Workbook
Name Arnarberg: Skóladeildarlisti!$B$19:$F$19
Name Álfaberg: Skóladeildarlisti!$B$18:$G$18
Name Álfakot: Skóladeildarlisti!$B$10:$P$10
Name Bjarkalundur: Skóladeildarlisti!$B$20:$C$20
Name Engidalsskóli: Skóladeildarlisti!$B$2:$P$2
Name Hlíðarberg: Skóladeildarlisti!$B$21:$E$21
Name Holtasel: Skóladeildarlisti!$B$12:$P$12
Name Hraunkot: Skóladeildarlisti!$B$17:$P$17
Name Hraunsel: Skóladeildarlisti!$B$11:$P$11
Name Hraunvallaskóli: Skóladeildarlisti!$B$3:$P$3
Name Hvaleyrarskóli: Skóladeildarlisti!$B$4:$P$4
Name Hörðuvellir: Skóladeildarlisti!$B$22:$E$22
Name Krakkaberg: Skóladeildarlisti!$B$15:$P$15
Name Leikskólinn_við_Hraunvallaskóla: Skóladeildarlisti!$B$23:$F$23
Name Leikskólinn_við_Skarðshlíðarskó: Skóladeildarlisti!$B$24:$F$24
Name Lækjarsel: Skóladeildarlisti!$B$13:$P$13
Name Lækjarskóli: Skóladeildarlisti!$B$5:$P$5
Name Selið: Skóladeildarlisti!$B$14:$P$14
Name Setbergsskóli: Skóladeildarlisti!$B$7:$P$7
Name Skarðshlíðarskóli: Skóladeildarlisti!$B$8:$P$8
Name Skarðssel: Skóladeildarlisti!$B$16:$P$16
Name Smáralundur: Skóladeildarlisti!$B$25:$E$25
Name Stekkjarás: Skóladeildarlisti!$B$26:$I$26
Name Tjarnarás: Skóladeildarlisti!$B$27:$F$27
Name Vesturkot: Skóladeildarlisti!$B$28:$F$28
Name Víðistaðaskóli: Skóladeildarlisti!$B$9:$P$9
Name Víðivellir: Skóladeildarlisti!$B$29:$D$29
Name Öldutúnsskóli: Skóladeildarlisti!$B$6:$P$6

Sheet Vöruskrá
A1: VÖRUSKRÁ – HRÁEFNI OG INNIHALDSEFNI
A2: Heiti vöru | B2: Leitarnafn (dropdown) | C2: Framleiðandi / Byrgi | D2: Vörúnúmer | E2: Vörúflokkur | F2: Innihaldslýsing | G2: Ofnæmisvaldar | H2: Fyrirvari | I2: Hlekkur á gagnablað | J2: Orka (kcal/100g) | K2: Fita (g/100g) | L2: Mettuð fita (g/100g) | M2: Kolvetni (g/100g) | N2: Sykur (g/100g) | O2: Prótein (g/100g) | P2: Salt (g/100g) | Q2: Trefjar (g/100g) | R2: Kostnaður (kr/kg) | S2: Athugasemdir
A3: Ömmu skonsur heilar | B3: Ömmu skonsur heilar | C3: Gæðabakstur | D3: 121 | E3: Bakkelsi | F3: Vatn, **hveiti**, **HAFRAMJÖL**, repjuolía, sykur, **HEILHVEITI**, **egg**, **MYSUDUFT**, pálmaolía, lyftiefni (E450, E500), salt, maltað **hveiti**, mjölmeðhöndlunarefni (E300), rotvarnarefni (E282), sykur, bindiefni (E322 úr sólblómum, E471), dextrósi, bragðefni, rotvarnarefni (E211), sýrustillir (E330), vanillubragðefni, kókosolía, litarefni (E150c, E150a), kekkjarvarnarefni (E535) | G3: Glúten (hveiti, haframjöl), egg, mjólk | H3: Gæti innihaldið snefil af sesam. | I3: https://gaedabakstur.is/vara/ommuskonsur-heilar-10stk-i-pakka/ | J3: 260 | K3: 12 | L3: 1.3 | M3: 31 | N3: 10 | O3: 5.3 | P3: 1 | Q3: 2.3 | R3: 160 g/stk.
A4: Bananaskonsur | B4: Bananaskonsur | C4: Gæðabakstur | D4: 122 | E4: Bakkelsi | F4: Hrísmjólk (vatn, hrísgrjón, sólblómaolía, kalsíum, maltextrakt, salt, bindiefni E418, vítamín B12, D2, sýrustillir E340), **hveiti**, vatn, sykur, banani, repjuolía, maltað **hveiti**, mjölmeðhöndlunarefni (E300), lyftiefni (E450, E500), salt, vanillubragðefni, litarefni (E150c), kekkjarvarnarefni (E535) | G4: Glúten (hveiti) | H4: Gæti innihaldið snefil af sesam, mjólk og eggjum. | I4: https://gaedabakstur.is/vara/bananaskonsur/ | J4: 237 | K4: 4.3 | L4: 0.3 | M4: 44 | N4: 16 | O4: 4.4 | P4: 0.4 | Q4: 1.5 | R4: 75 g/stk.
A5: Sólkjarnabrauð plötubrauð | B5: Sólkjarnabrauð plötubrauð | C5: Gæðabakstur | D5: 730 | E5: Brauð | F5: **Hveiti**, vatn, 12,3% - sólkjarnafræ, **rúgmjöl**, hörfræ, maltað **hveiti**, salt, maltað **bygg**, mjölmeðhöndlunarefni (E300), ger, malt extrakt (úr **byggi**), súrdeigsduft úr **hveiti** (**hveiti**, gerlar), dextrósi, **hveitiglúten**, bindiefni (E472e, E491), ensím, kekkjarvarnarefni (E535) | G5: Glúten | H5: Gæti innihaldið snefil af sesamfræjum | I5: https://gaedabakstur.is/vara/solkjarnabraud/ | J5: 311 | K5: 10.8 | L5: 1.3 | M5: 40.3 | N5: 1.7 | O5: 10.5 | P5: 1.1 | Q5: 4.7 | R5: 500 g.
A6: Beyglur fínar KS(48) | B6: Beyglur fínar KS(48) | C6: Myllan | D6: 3413 | E6: Brauð / Frystar | F6: **hveiti**, vatn, sykur, maltað mjöl (**bygg**, **hveiti**), salt, ger, óvirkt þurrger, ýruefni (E472e), repjuolía, mjölmeðhöndlunarefni (E300), ensím. | G6: Glúten (hveiti, bygg) | H6: Framleitt á svæði þar sem unnið er með sesamfræ, mjólk, egg, lúpínu, soja | I6: https://www.myllan.is/is/vorulinur/frosin-pokkud-vara/beyglur-finar | J6: 257 | K6: 0.9 | L6: 0.2 | M6: 51 | N6: 2.6 | O6: 9.4 | P6: 1.5 | Q6: 2.4 | R6: 95 g/stk, 48 stk.
A7: Heilkornasamlokubrauð stórt | B7: Heilkornasamlokubrauð stórt | C7: Myllan | D7: 1036 | E7: Brauð | F7: Vatn, heilkorna **HEILHVEITI** 17%, heilkorna **RÚGMJÖL** 17%, **hveiti**, **HVEITIGLÚTEN**, **HVEITIFLÖGUR**, **RÚGMJÖL**, þurrkað súrdeig (**RÚGUR**, súrdeigsgerlar), **HVEITIKURL**, ger, maltextrakt (**bygg**), repjuolía, salt, þykkingarefni (E415), sýrustillir (E262), ýruefni (E471, E472e), þurrkað súrdeig (**hveiti**, súrdeigsgerlar), mjölmeðhöndlunarefni (E300) | G7: Glúten (hveiti, rúgur, bygg) | H7: Framleitt á svæði þar sem unnið er með sesamfræ, egg, mjólk og lúpínu | I7: https://www.myllan.is/is/vorulinur/samlokubraud/heilkornasamlokubraud-stort | J7: 244 | K7: 2.9 | L7: 0.6 | M7: 37 | N7: 1.6 | O7: 14 | P7: 1 | Q7: 6.6 | R7: 1000 g.
A8: Heimilisbrauð 1/1 | B8: Heimilisbrauð 1/1 | C8: Myllan | D8: 1023 | E8: Brauð | F8: **Hveiti**, vatn, **HVEITIKURL**, repjuolía, ger, salt, **HVEITITREFJAR**, mjölmeðhöndlunarefni (E300), ýruefni (E481) | G8: Glúten (hveiti) | H8: Framleitt á svæði þar sem unnið er með sesamfræ, mjólk, egg og lúpínu | I8: https://www.myllan.is/is/vorulinur/samlokubraud/heimilisbraud-heilt | J8: 250 | K8: 2.7 | L8: 0.4 | M8: 45 | N8: 0.3 | O8: 9 | P8: 1.4 | Q8: 3.1 | R8: 770 g.
A9: Lífskornabrauð m/ tröllahöfrum og chia | B9: Lífskornabrauð m/ tröllahöfrum og chia | C9: Myllan | D9: 1063 | E9: Brauð | F9: Vatn, **TRÖLLAHAFRAR** 21%, heilkorna **HEILHVEITI** 16%, **hveiti**, **HVEITIGLÚTEN**, **RÚGMJÖL**, þurrkað súrdeig (**RÚGUR**, súrdeigsgerlar), **HVEITIKURL**, ger, chia fræ 1% (Salvia hispanica), maltextrakt (**bygg**), repjuolía, joðbætt salt, þykkingarefni (E415), sýrustillir (E262), ýruefni (E471, E472e), mjölmeðhöndlunarefni (E300) | G9: Glúten (tröllahafrar, heilhveiti, hveiti, rúgur, bygg) | H9: Framleitt á svæði þar sem unnið er með sesamfræ, egg, mjólk og lúpínu | I9: https://www.myllan.is/is/vorulinur/vegan-vorur/lifskorn-trollahafrar-chiafrae | J9: 241 | K9: 4.3 | L9: 0.8 | M9: 33 | N9: 1.2 | O9: 14 | P9: 0.9 | Q9: 6.8 | R9: 450 g. Vegan.
A10: Hvítlauksbrauð / baguette | B10: Hvítlauksbrauð / baguette | C10: Myllan | D10: 4280 | E10: Brauð / Frystar | F10: Mjöl (**hveiti**, maltað **hveiti**), vatn, smjör (**mjólk**), jurtafita (pálma), jurtaolía (repju), joðbætt salt, ger, hvítlaukur 0,6%, laukduft, ýruefni (E472e, E471, sólblómalesitín), sýrustillir (E341, E450, E330), óvirkt ger, steinselja, salt, þykkingarefni (E412), bragðefni, þráavarnarefni (E300), ensím | G10: Glúten (hveiti), mjólk | H10: Getur innihaldið snefil af eggjum, soja, sinnepi og sesamfræjum. | I10: https://drive.google.com/file/d/1ISY9dqVNVBuKMul2k8e0kwwb7vSrJhlW/view | J10: 305 | K10: 14 | L10: 6.4 | M10: 37 | N10: 0.8 | O10: 6.6 | P10: 1.5 | Q10: 1.9 | R10: 175 g/stk.
A11: Dökkt súrdeigsbrauð (Skanörgrova) | B11: Dökkt súrdeigsbrauð (Skanörgrova) | C11: Pågen | D11: 1003 | E11: Brauð | F11: Vatn, **hveiti**mjöl, súrdeig úr **hveiti**korni (13%), heilkorna**hveiti**mjöl, dinkel**hveiti**mjöl, muldir heilkornakjarnar úr dinkel**hveiti**, **hafra**grjón, skolað heilkorna**hafra**mjöl, **hveiti**glúten, heilkorna**rúg**mjöl, **hafra**trefjar, kaldpressuð repjuolía (1%), gul hörfræ, sykur, ger, malt úr **byggi** og **hveiti**, salt. | G11: Glúten (hveiti, rúg, hafrar, bygg) | I11: https://drive.google.com/file/d/1_xC3btJzq-zmdaQHqlJ0_0EY7KwFaCqs/view | J11: 308 | K11: 7.8 | L11: 0.8 | M11: 48 | N11: 9.1 | O11: 10 | P11: 1.4 | Q11: 6
A12: Ljóst súrdeigsbrauð (LantGoda) | B12: Ljóst súrdeigsbrauð (LantGoda) | C12: Pågen | D12: 1004 | E12: Brauð | F12: Vatn, **hveiti**mjöl, súrdeig úr **hveiti** (13%), heilkorna**hveiti**mjöl, dinkel**hveiti**mjöl, muldir heilkornakjarnar úr dinkel**hveiti**, **hafra**grjón, skolað heilkorna**hafra**mjöl, **hveiti**glúten, heilkorna**rúg**mjöl, **hafra**trefjar, kaldpressuð repjuolía (1%), gul hörfræ, sykur, ger, malt úr **byggi** og **hveiti**, salt. | G12: Glúten (hveiti, rúg, hafrar, bygg) | I12: https://drive.google.com/file/d/1aObopp1C2qlx3QieZ3phPb3MzLNGDVZz/view | J12: 262 | K12: 3 | L12: 0.4 | M12: 45 | N12: 4.1 | O12: 11 | P12: 0.9 | Q12: 5 | R12: 650 g.
A13: Hrökkbrauð – Spelt | B13: Hrökkbrauð – Spelt | C13: Burger Knäcke | E13: Hrökkbrauð | F13: Heilkorna**rúg**mjöl, **spelt**flögur (**hveiti**), heilkorna**spelt**mjöl (**hveiti**), salt. | G13: Glúten (rúg, spelt (hveiti)) | H13: Getur innihaldið snefil af sesam, mjólk og öðrum glútentegundum | I13: https://drive.google.com/file/d/1z4yQiAT8epMbEaAPA9lsAZjC7K1VKYth/view | J13: 324 | K13: 1.6 | L13: 0.3 | M13: 59 | N13: 1.8 | O13: 8.6 | P13: 1.3 | Q13: 21 | R13: 250 g.
A14: Heilhveitikex (HAUST Graham) | B14: Heilhveitikex (HAUST Graham) | C14: Continental Bakeries | D14: 307242 | E14: Kex | F14: **Hveiti**mjöl, heilkorna **hveiti**mjöl 30%, sykur, jurtafita (pálma), lyftiefni (ammoníumkarbónöt, natríumkarbónöt), salt, bragðefni. | G14: Glúten (hveiti) | H14: Getur innihaldið snefil af hnetum og sesam | I14: https://docs.google.com/document/d/1hSm-4pt3r15YYOeuqlWMbkkVgdKc8cwt0qPlCRs1ssM/edit | J14: 478 | K14: 20.8 | L14: 10.5 | M14: 62.4 | N14: 22.7 | O14: 8 | P14: 1.1 | R14: 225 g.
A15: Horn / Mini croissant 25g | B15: Horn / Mini croissant 25g | C15: Neuhauser | D15: 401262 | E15: Bakkelsi / Frystar | F15: **Hveiti**mjöl, vatn, **smjör** 18%, ger, sykur, **egg**, salt, **hveiti**glúten, maltað **hveiti**mjöl, óvirkt ger, mjölmeðhöndlunarefni (askorbínsýra E300), ensím. | G15: Glúten (hveiti), mjólk (smjör), egg | I15: https://drive.google.com/file/d/1DNHhTRSDQjq03Ewnj0fn_Ex30mAnbK52/view | J15: 308 | K15: 15 | L15: 9.2 | M15: 36 | N15: 5.4 | O15: 6.8 | P15: 1 | Q15: 1.4 | R15: 25 g/stk.
A16: Skólabollur | B16: Skólabollur | C16: Myllan | D16: 3651 | E16: Brauð / Frystar | F16: Vatn, heilkorna **rúg**mjöl 20%, heilkorna **hveiti**mjöl 17%, **hveiti**mjöl, **hveiti**glúten, **rúg**mjöl, þurrkað súrdeig (**rúg**, súrdeigsgerlar), **hveiti**kurl, ger, maltextrakt (**bygg**), repjuolía, joðbætt salt, þykkingarefni (E415), sýrustillir (E262), ýruefni (E471, E472e), mjölmeðhöndlunarefni (E300), maltað **hveiti**. | G16: Glúten (rúgur, hveiti, bygg) | H16: Framleitt á svæði þar sem unnið er með sesamfræ, egg, mjólk og lúpínu | I16: https://drive.google.com/file/d/14DAgTI18dATCiMOlGqGBlT2S4QVgoDrD/view | J16: 221 | K16: 2.8 | L16: 0.5 | M16: 34 | N16: 1.4 | O16: 11 | P16: 1.1 | Q16: 6.4
A17: Organic Crystal Sourdough Bun | B17: Organic Crystal Sourdough Bun | C17: Europastry | D17: 69393 | E17: Brauð / Frystar | F17: **Hveiti**mjöl*, vatn, heilkorna **hveiti**súrdeig 4%, ger*, extra virgin ólífuolía 1,3%*, salt, **bygg**maltmjöl*, **hveiti**glúten*. | G17: Glúten (hveiti, bygg) | H17: Getur innihaldið snefil af soja, egg, mjólk, sesam, sinnep | I17: https://drive.google.com/file/d/1_7-lapfB0IXWi_NgfdgjTejZibfQdUt4/view | J17: 242 | K17: 2.5 | L17: 0.4 | M17: 44 | N17: 0.6 | O17: 9.4 | P17: 1.3 | Q17: 1.8
A18: Rúnstykki Kaiserbrauð 60g | B18: Rúnstykki Kaiserbrauð 60g | C18: Diversi Foods | D18: 65 | E18: Brauð / Frystar | F18: Hveitimjöl, vatn, ger, salt, repjuolía, glúkósi. | G18: Glúten (hveiti) | H18: Getur innihaldið snefil af mjólk, eggjum, soja, hnetum og sesam. | I18: https://drive.google.com/file/d/1tiAWMsBCjkJpvqLl-JZapnAJqJ3ldR3x/view | J18: 267 | K18: 2.4 | L18: 0.4 | M18: 51.1 | N18: 0.5 | O18: 8.9 | P18: 1.625 | Q18: 2.3
A19: Heilkornastykki | B19: Heilkornastykki | C19: OJK | D19: PAG-13103 | E19: Brauð / Frystar | F19: Vatn, heil**hveiti**, **hveitimjöl**, brotin **rúgur**, súrdeig úr **hveiti**, **hveitiglúten**, **heilhveiti**, **durumhveiti**, ger, sólblómafræ, epli, kaldpressuð repjuolía, hörfræ, **bygg**malt, sykur, sýrustillir (sítrónusýra), salt. | G19: Glúten (hveiti, rúgur) | I19: https://verslun.ojk-isam.is/vara/PAG-13103 | J19: 270 | K19: 5.2 | L19: 0.7 | M19: 40 | N19: 2.6 | O19: 12 | P19: 0.99 | Q19: 6
A20: Hönö Skärgårdskaka | B20: Pólarbrauð | C20: Pågen | D20: 1186 | E20: Brauð / Frystar | F20: **Hveiti**mjöl, vatn, sykur, sigtað **rúg**mjöl, repjuolía, heilkorna **rúg**mjöl, **hveiti**glúten, heilkorna **hveiti**mjöl, ger, jurtaýruefni, lyftiefni (hjartarsalt), malt úr **byggi**, salt. | G20: Glúten (hveiti, rúgur, bygg) | I20: https://drive.google.com/file/d/1wQ6Aj25cbHnFwYYRVBbBoa0ceJotW3tK/view | J20: 296 | K20: 4.5 | L20: 0.5 | M20: 52 | N20: 9.7 | O20: 9.1 | P20: 0.8 | Q20: 3.3
A21: Arna skyr vanillu | B21: Arna skyr vanillu | C21: Arna / MS | E21: Mjólkurvörur | F21: **Mjólk**, sykur (5.0%), maíssterkja, vanilluþykkni (0,1%), vanillukorn, sítrónusafi, skyrgerlar, laktasi. | G21: Mjólk | I21: https://drive.google.com/file/d/1yzNdxeJqQSbLVXSF15Oeij4m2PUBv2GA/view | J21: 78 | K21: 0.3 | L21: 0.2 | M21: 7.9 | N21: 7.9 | O21: 11 | P21: 0.1 | R21: 1 kg.
A22: Heimilis grjónagrautur | B22: Heimilis grjónagrautur | C22: Matarstræti | D22: 400208 | E22: Grautar | F22: **Mjólk**, hrísgrjón(12%), sykur, salt. | G22: Mjólk | I22: https://drive.google.com/file/d/1Q4ZfVecv6vttdWG8fU0WA-1aeEo59cEB/view | J22: 91 | K22: 3 | L22: 1.6 | M22: 14 | N22: 4.6 | O22: 3 | P22: 0.5 | R22: 2 kg.
A23: Oatly iMat Fraiche | B23: Oatly iMat Fraiche | C23: Oatly | D23: 61529 | E23: Rjómi | F23: Gerjaður hafragrunnur (vatn, hafrar 10%), repjuolía, fullhertar jurtaolíur (kókos, repju), kartöflusterkja, ýruefni (E472e), bindiefni (E407), sýrur (eplasýra, mjólkursýra), kalsíumkarbónat, kalsíumfosföt. | I23: https://docs.google.com/document/d/1vtp7UoMhU2kAQ80lddgVvUUhOoVTIYypmLZ4XRd5l3E/edit | J23: 177 | K23: 15 | L23: 6.4 | M23: 9.1 | N23: 4.1 | O23: 1 | P23: 0 | Q23: 1 | R23: 200 ml.
A24: Debic Vegan Top | B24: Debic Vegan Top | C24: FrieslandCampina | D24: 1180281 | E24: Rjómi | F24: Vatn (64%), jurtaolía (29%) (pálmakjarni, pálmi), þurrkað glúkósasíróp (5%), umbreytt sterkja, salt, bindiefni (E339, gellangúmmí), ýruefni (lesitín, E435, E472b), litarefni (karótín), náttúruleg bragðefni. | G24: Engir skráðir | I24: https://drive.google.com/file/d/1VkCiTqPDw5l0voO-OiMPXkFvU-St0eZv/view | J24: 295 | K24: 30 | L24: 25 | M24: 6.2 | O24: 0 | P24: 0.1 | Q24: 0 | R24: 5 L Bag-in-Box.
A25: Ali brauðskinka 62% | B25: Ali brauðskinka 62% | C25: Síldar og Fiskur | E25: Kjöt | F25: Grísakjöt (62%), vatn, kartöflumjöl, **sojaprótein**, salt, þrúgusykur, bindiefni (E451), þráavarnarefni (E301, E330), gerextrakt, þykkingarefni (E410, E407), bragðefni, rotvarnarefni (E270, E250) | G25: Soja | I25: https://docs.google.com/document/d/1tYCZIN-9wdHVdNDDkGYzBt6KHJktVy-txKVoBoCKeKQ/edit | J25: 122 | K25: 5.9 | L25: 2.4 | M25: 3.6 | N25: 1.6 | O25: 13.4 | P25: 2.7
A26: Ali kjúklingapylsur | B26: Ali kjúklingapylsur | C26: Síldar og Fiskur | E26: Kjöt | F26: Kjúklingakjöt 58%, kjúklingaskinn 24%, vatn, salt, krydd (**sinnep**, hvítlaukur), gerextrakt, bragðefni, rotvarnarefni (E250) | G26: Sinnep | I26: https://drive.google.com/file/d/1YjhRYrqRfXtv7LqVwi1Ut5s0ZlUPbbqk/view | J26: 173 | K26: 13.4 | L26: 4.8 | M26: 0.3 | N26: 0.3 | O26: 13.7 | P26: 2.8
A27: Kjúklingabollur 5 kg | B27: Kjúklingabollur 5 kg | C27: Matfugl | D27: 174170 | E27: Kjöt / Frystar | F27: Kjúklingaleggjakjöt, kartöflusterkja, vatn, **soja**prótein, salt, þurrkað grænmeti (laukur, hvítlaukur, paprika), bragðefni (**soja**), krydd (**sinnep**), þrúgusykur, **hveiti**prótein, gerextrakt, litarefni (E160c), krydd, ger, repjuolía, fosfat (E450) | G27: Hveiti, soja, sinnep | I27: https://drive.google.com/file/d/1YThV-MnjJNGCpLCeYQojXy09zGYF6MrY/view | J27: 177 | K27: 9 | L27: 1.8 | M27: 7 | N27: 0.9 | O27: 17 | P27: 1.8
A28: Kjúklingaborgarar í cornflakes | B28: Kjúklingaborgarar í cornflakes | C28: Matfugl | D28: 174311 | E28: Kjöt / Frystar | F28: Kjötfylling (79%) (Kjúklingakjöt, vatn, **soja**prótein, salt, krydd, gerþykkni, laukur), Brauðhjúpur (**hveiti**, maís, vatn, sykur, salt, maltað **bygg** extrakt), repjuolía. | G28: Hveiti, soja, bygg | I28: https://drive.google.com/file/d/1eikdCgUrXnNjx_B4w2fUH_3E5nIrr0Kz/view | J28: 237 | K28: 13 | L28: 4.7 | M28: 14 | N28: 1.1 | O28: 16 | P28: 1.5
A29: kjúklinga Lærakjöt Rodizio | B29: kjúklinga Lærakjöt Rodizio | C29: Matfugl | D29: 171481 | E29: Kjöt | F29: Úrbeinuð skinnlaus kjúklingalæri (83%), vatn, salt, jurtaolía, sykur, mango chutney, ávaxtaþykkni, sýrustillir (E500), krydd reykbragðefni, rotvarnarefni (E262), þráavarnarefni (E320) | I29: https://drive.google.com/file/d/111MXMHumSNCo1SX0OgN5_iw4ol6nI6Y0/view | J29: 206 | K29: 10 | L29: 1.8 | M29: 4 | N29: 3.3 | O29: 25 | P29: 3.2
A30: Kjúklingalæri úrbeinuð | B30: Kjúklingalæri úrbeinuð | C30: Danpo | D30: 844014 | E30: Kjöt / Frystar | F30: Úrbeinað og skinnlaust kjúklingalæri 80%, vatn 19%, salt, sykur, þráavarnarefni (E331, E301), sýrustillir (E262). | I30: https://drive.google.com/file/d/1GO4O3alIJnHNWfA6fdAD_SVmAdbBm5wZ/view | J30: 137 | K30: 9 | L30: 2.3 | O30: 14 | P30: 0.8
A31: NOL Kindakæfa 200g | B31: NOL Kindakæfa 200g | C31: Kjarnafæði | D31: 70519 | E31: Kjöt | F31: Lambakjöt 80%, kjötsoð, laukduft, salt, pipar. | I31: https://docs.google.com/document/d/1LXzsuB69-IC_oRxF1lHfWTuKdnHk4OhCG33dUGHUGSs/edit | J31: 264 | K31: 24 | L31: 12 | M31: 1 | N31: 0 | O31: 11 | P31: 2.1 | Q31: 0
A32: Lifrarpylsa án mjólkur, soðin | B32: Lifrarpylsa án mjólkur, soðin | C32: Kjarnafæði | D32: 59804 | E32: Kjöt | F32: Lambalifur 32%, lambamör, **RÚGMJÖL**, **HAFRAMJÖL**, vatn, salt. | G32: Glúten (RÚGMJÖL, HAFRAMJÖL) | I32: https://docs.google.com/document/d/1dqgFZjSbMdctBpuTsZ86-uVkLNdvEtPTC6Kh8455--Y/edit | J32: 401 | K32: 32.7 | L32: 16.6 | M32: 15.7 | N32: 0.3 | O32: 10.3 | P32: 1 | Q32: 3.8
A33: Dönsk lifrarkæfa | B33: Dönsk lifrarkæfa | C33: Kjarnafæði | E33: Kjöt | F33: Grísalifur og kjöt 80%, vatn, laukur, salt, kartöflumjöl, **soja**prótein, krydd, vatnsrofið jurtaprótein, repjuolía, maísprótein, jurtafita (pálma), þrúgusykur, rotvarnarefni (E250), þráavarnarefni (E315, E316, E330), bindiefni (E450, E451) | G33: Soja | I33: https://docs.google.com/document/d/1iXvC7kN0wGPam-zMk0XlcLESdw9tCpSF14EDgGArP38/edit | J33: 384 | K33: 29.3 | L33: 14.7 | M33: 2.4 | N33: 0.2 | O33: 12.8 | P33: 1.7 | Q33: 0.2
A34: Ýsa í raspi | B34: Ýsa í raspi | C34: Hafið | D34: 1164 | E34: Fiskur | F34: Ýsa, raspur (**hveiti**, vatn, ger, salt, litarefni (E100, E160b)), hjúpur (**hveiti**, **glúten**, salt, umbreytt **hveiti**sterkja). | G34: Fiskur, hveiti, glúten | I34: https://docs.google.com/document/d/1mrPTXRk_Pt2msU-ckh0eoh4oUCEKrI5g/edit | J34: 125 | K34: 1 | L34: 0.3 | M34: 11 | N34: 0.2 | O34: 18 | P34: 0.7
A35: Ýsa í tandoori | B35: Ýsa í tandoori | C35: Hafið | D35: 0 | E35: Fiskur | F35: Ýsa, marinering (vatn, repjuolía, pipar, engifer, kóríander, kúmen, chili, salt, sítrónusafi, sykur, rauðrófuduft, náttúruleg bragðefni, þykkingarefni xantangúmmí E415, þurrkaður hvítlaukur, rotvarnarefni kalíumsorbat E202). | G35: Fiskur (ýsa) | I35: https://drive.google.com/file/d/13AmWc24B7lw4yM7QnWS-el6FVT-PU7Ty/view | J35: 114 | K35: 5.9 | L35: 0.5 | M35: 1.8 | N35: 1.2 | O35: 13 | P35: 0.8 | Q35: 0.6
A36: Ýsa nætursöltuð | B36: Ýsa nætursöltuð | C36: Hafið | E36: Fiskur | F36: Ýsa, salt. | G36: Fiskur | I36: https://docs.google.com/document/d/16XSSnVUJ3h_-jINvQvjLPJxqQDm3-XJQ/edit | J36: 61 | K36: 1 | L36: 0 | M36: 0 | N36: 0 | O36: 14 | P36: 3
A37: Fiskibollur án glúten | B37: Fiskibollur án glúten | C37: Norðanfiskur | D37: 9060 | E37: Fiskur / Frystar | F37: **Þorskur**, laukur, kartöflumjöl, umbreytt sterkja, jurtatrefjar, **soja**prótein, laukduft, salt, bindiefni (E451), hvítur pipar repjuolía. | G37: Fiskur, soja | I37: https://drive.google.com/file/d/1su1X4NqQ06JKbPrLHqbYVzuDSI9b-_ZY/view | J37: 125 | K37: 1.3 | L37: 0.1 | M37: 14.2 | N37: 0.7 | O37: 14.1 | P37: 1.4
A38: Kentuckyhjúpaðir ýsubitar | B38: Kentuckyhjúpaðir ýsubitar | C38: Norðanfiskur | D38: 9174 | E38: Fiskur / Frystar | F38: Ýsa (70%), vítamínbætt **hveiti**, vatn, **hveitisterkja**, gerþykkni, salt, hvítlauksduft, laukduft, lyftiefni (E503(II)), **hveitiglúten**, hrísgrjónamjöl, pipar, þrúgusykur, sýra (E330), **sellerí**fræ, sykur, krydd, repjuolía. | G38: Fiskur (ýsa), Glúten (hveiti), Sellerí | I38: https://docs.google.com/document/d/1nPfU8Vp8xiyfhIt3illeInciLtmTNm2bGwro_9ZVWlk/edit | J38: 122 | K38: 1.5 | L38: 0.2 | M38: 12.4 | N38: 0.7 | O38: 14.7 | P38: 0.6
A39: Anamma Vegan Nuggets Pea | B39: Anamma Vegan Nuggets Pea | C39: Anamma | D39: 454071477 | E39: Plantabasað / Frystar | F39: Vatn, baunaprótein(17%), repjuolía, glútenlaus raspur (hrísgrjónamjöl, kjúklingabaunamjöl, maíssterkja, salt, dextrósi), hrísgrjónamjöl, maíssterkja, laukur, salt, náttúruleg bragðefni (paprika, kóríander, múskat), bindiefni (metýlsellulósi) | H39: Getur innihaldið snefil af soja | I39: https://docs.google.com/document/d/1hD7vfcvl0f75johYoY3PnnS548AlpCDkNKyTSEnJezk/edit | J39: 256 | K39: 17 | L39: 1.2 | M39: 14 | N39: 0 | O39: 12 | P39: 1.2 | R39: 3 kg. Vegan.
A40: BBQ Oumph! (Pulled) | B40: BBQ Oumph! (Pulled) | C40: LiveKindly | D40: 1407 | E40: Plantabasað / Frystar | F40: Sojaprótein 54,3% (vatn, sojapróteinþykkni), grillsósa 45,7%. | G40: Soja (sojabaunir) | I40: https://drive.google.com/file/d/1ny7Hc5Bb9td7Jjuz8iDeeFNvGw0ASEur/view | J40: 115 | K40: 0.7 | L40: 0.1 | M40: 11 | N40: 9.4 | O40: 14 | P40: 1.5 | Q40: 4.7 | R40: 2 kg.
...

Sheet Réttabanki
A1: RÉTTABANKI – UPPSKRIFTIR
A2: Heiti réttar | B2: Vara (leitarnafn) | C2: Magn (g/100kg) | D2: Innihaldslýsing (sjálfvirkt) | E2: Ofnæmisvaldar (sjálfvirkt) | F2: Fyrirvari (sjálfvirkt) | G2: Orka (kcal/100g) | H2: Fita (g/100g) | I2: Mettuð fita (g/100g) | J2: Kolvetni (g/100g) | K2: Sykur (g/100g) | L2: Prótein (g/100g) | M2: Salt (g/100g) | N2: Trefjar (g/100g) | O2: Foodcost (kr/100kg) | P2: Athugasemd | Q2: Eldunarleiðbeiningar | R2: Eldunarleiðbeiningar (template)
A3: Pasta með kjötbollum í mildri tómatsósu | D3: Kinda- og nautgripakjöt 50%, grænmeti 41% (kartöflur, brokkólí, laukur, gulrætur), kartöflusterkja, salt, krydd (pipar, oregano, basil, paprika). | Tómatar | Laukur | Gulrætur | Vatn | Súkrósi | Oregano 100%. | Svartur pipar 100%. | Salt (salt, kekkjavarnarefni E535, lyftiefni E500). | Maíssterkja. | E3: Engir skráðir | G3: 99.39 | H3: 5.4 | I3: 2.62 | J3: 14.95 | L3: 7.28 | M3: 2.13 | N3: 0.32 | O3: =IF(OR(B3="",C3=""),"",IFERROR(C3/1000*IFERROR(INDEX(Vöruskrá!R:R,MATCH(B3,Vöruskrá!B:B,0)),0)/1000,"")) | P3: Í-Mat / Matarstund | Pastahlutfall 40%, sósa og kjötbollur 60% | Q3: 1. Hitið sósu í potti við meðalhita í 15-20 mín, hrærið reglulega. 2. Hitið kjötbollur í ofni 180°C í 10-12 mín. 3. Eldið pasta skv. leiðbeiningum á pakka. 4. Berið fram með pasta og kjötbollum í sósu. | R3: Hitið sósu í potti við meðalhita í 15-20 mín. Hitið kjötbollur í ofni 180°C í 10-12 mín. Eldið pasta skv. leiðbeiningum. Berið fram saman.
B4: Skólabollur, Kjöt og grænmeti | C4: 25000 | D4: Kinda- og nautgripakjöt 50%, grænmeti 41% (kartöflur, brokkólí, laukur, gulrætur), kartöflusterkja, salt, krydd (pipar, oregano, basil, paprika). | G4: 110 | H4: 12 | I4: 6 | J4: 12 | K4: 0.6 | L4: 12 | M4: 1.6 | O4: =IF(OR(B4="",C4=""),"",IFERROR(C4/1000*IFERROR(INDEX(Vöruskrá!R:R,MATCH(B4,Vöruskrá!B:B,0)),0)/1000,"")) -> 0
B5: Tómatpuré Doppio Concentrato 800 g (Menu) | C5: 18000 | D5: Tómatar | G5: 113 | H5: 0.4 | I5: 0 | J5: 19 | K5: 14 | L5: 6 | M5: 0.1 | O5: =IF(OR(B5="",C5=""),"",IFERROR(C5/1000*IFERROR(INDEX(Vöruskrá!R:R,MATCH(B5,Vöruskrá!B:B,0)),0)/1000,"")) -> 0
B6: Laukur (ferskur) | C6: 5000 | D6: Laukur | E6: Engir skráðir | G6: 40 | H6: 0.1 | I6: 0 | J6: 9.3 | K6: 4.2 | L6: 1.1 | M6: 0.004 | N6: 1.7 | O6: =IF(OR(B6="",C6=""),"",IFERROR(C6/1000*IFERROR(INDEX(Vöruskrá!R:R,MATCH(B6,Vöruskrá!B:B,0)),0)/1000,"")) -> 0
B7: Gulrætur (ferskar) | C7: 3000 | D7: Gulrætur | E7: Engir skráðir | G7: 41 | H7: 0.2 | I7: 0 | J7: 9.6 | K7: 4.7 | L7: 0.9 | M7: 0.07 | N7: 2.8 | O7: =IF(OR(B7="",C7=""),"",IFERROR(C7/1000*IFERROR(INDEX(Vöruskrá!R:R,MATCH(B7,Vöruskrá!B:B,0)),0)/1000,"")) -> 0
B8: Vatn | C8: 4000 | D8: Vatn | E8: Engir skráðir | G8: 0 | H8: 0 | I8: 0 | J8: 0 | K8: 0 | L8: 0 | M8: 0 | N8: 0 | O8: =IF(OR(B8="",C8=""),"",IFERROR(C8/1000*IFERROR(INDEX(Vöruskrá!R:R,MATCH(B8,Vöruskrá!B:B,0)),0)/1000,"")) -> 0
B9: Crystal Sugar (Sykur) | C9: 300 | D9: Súkrósi | G9: 400 | H9: 0 | I9: 0 | J9: 100 | K9: 100 | L9: 0 | M9: 0 | N9: 0 | O9: =IF(OR(B9="",C9=""),"",IFERROR(C9/1000*IFERROR(INDEX(Vöruskrá!R:R,MATCH(B9,Vöruskrá!B:B,0)),0)/1000,"")) -> 0
B10: Oregano | C10: 80 | D10: Oregano 100%. | F10: Framleitt á svæði þar sem unnið er með glúten, fisk, krabbadýr, lindýr, mjólk, soja, sellerí, sinnep og sesam. | G10: 480 | H10: 10 | I10: 2.7 | J10: 64 | K10: 4.1 | L10: 11 | M10: 0 | O10: =IF(OR(B10="",C10=""),"",IFERROR(C10/1000*IFERROR(INDEX(Vöruskrá!R:R,MATCH(B10,Vöruskrá!B:B,0)),0)/1000,"")) -> 0
B11: Svartur pipar, malaður | C11: 40 | D11: Svartur pipar 100%. | F11: Framleitt á svæði þar sem unnið er með glúten, fisk, krabbadýr, lindýr, mjólk, soja, sellerí, sinnep og sesam. | G11: 386 | H11: 3.3 | I11: 1 | J11: 65 | K11: 0.6 | L11: 11 | M11: 0.1 | O11: =IF(OR(B11="",C11=""),"",IFERROR(C11/1000*IFERROR(INDEX(Vöruskrá!R:R,MATCH(B11,Vöruskrá!B:B,0)),0)/1000,"")) -> 0
B12: Borðsalt | C12: 800 | D12: Salt (salt, kekkjavarnarefni E535, lyftiefni E500). | F12: Framleitt á svæði þar sem unnið er með mjólk, glúten, egg, sesam, sellerí, soja og sinnep. | G12: 0 | H12: 0 | I12: 0 | J12: 0 | K12: 0 | L12: 0 | M12: 100 | O12: =IF(OR(B12="",C12=""),"",IFERROR(C12/1000*IFERROR(INDEX(Vöruskrá!R:R,MATCH(B12,Vöruskrá!B:B,0)),0)/1000,"")) -> 0
B13: Maizenamjöl (majssterkja) | C13: 1200 | D13: Maíssterkja. | O13: =IF(OR(B13="",C13=""),"",IFERROR(C13/1000*IFERROR(INDEX(Vöruskrá!R:R,MATCH(B13,Vöruskrá!B:B,0)),0)/1000,"")) -> 0
A14: Lambakjötspottréttur með kartöflum | D14: Kartöflur | Gulrætur | Laukur | Tómatar | Salt (salt, kekkjavarnarefni E535, lyftiefni E500). | Svartur pipar 100%. | Vatn | Maíssterkja. | E14: Engir skráðir | G14: 63.27 | H14: 0.13 | I14: 0 | J14: 14 | L14: 1.58 | M14: 1.02 | N14: 1.82 | O14: =IF(OR(B14="",C14=""),"",IFERROR(C14/1000*IFERROR(INDEX(Vöruskrá!R:R,MATCH(B14,Vöruskrá!B:B,0)),0)/1000,"")) | P14: Matarstund | LP-100KG-20260529 | Q14: 1. Hitið pottrétt í ofni 160°C í 45-60 mín. 2. Potturinn er tilbúinn þegar kjötið er mjúkt. 3. Berið fram heitt. | R14: Hitið pottrétt í ofni 160°C í 45-60 mín. Tilbúinn þegar kjötið er mjúkt. Berið fram heitt.
B15: Kartöflur (ferskar) | C15: 30000 | D15: Kartöflur | E15: Engir skráðir | G15: 77 | H15: 0.1 | I15: 0 | J15: 17 | K15: 0.8 | L15: 2 | M15: 0.006 | N15: 2.2 | O15: =IF(OR(B15="",C15=""),"",IFERROR(C15/1000*IFERROR(INDEX(Vöruskrá!R:R,MATCH(B15,Vöruskrá!B:B,0)),0)/1000,"")) -> 0
B16: Gulrætur (ferskar) | C16: 10000 | D16: Gulrætur | E16: Engir skráðir | G16: 41 | H16: 0.2 | I16: 0 | J16: 9.6 | K16: 4.7 | L16: 0.9 | M16: 0.07 | N16: 2.8 | O16: =IF(OR(B16="",C16=""),"",IFERROR(C16/1000*IFERROR(INDEX(Vöruskrá!R:R,MATCH(B16,Vöruskrá!B:B,0)),0)/1000,"")) -> 0
B17: Laukur (ferskur) | C17: 8000 | D17: Laukur | E17: Engir skráðir | G17: 40 | H17: 0.1 | I17: 0 | J17: 9.3 | K17: 4.2 | L17: 1.1 | M17: 0.004 | N17: 1.7 | O17: =IF(OR(B17="",C17=""),"",IFERROR(C17/1000*IFERROR(INDEX(Vöruskrá!R:R,MATCH(B17,Vöruskrá!B:B,0)),0)/1000,"")) -> 0
B18: Tómatpuré Doppio Concentrato 800 g (Menu) | C18: 2500 | D18: Tómatar | G18: 113 | H18: 0.4 | I18: 0 | J18: 19 | K18: 14 | L18: 6 | M18: 0.1 | O18: =IF(OR(B18="",C18=""),"",IFERROR(C18/1000*IFERROR(INDEX(Vöruskrá!R:R,MATCH(B18,Vöruskrá!B:B,0)),0)/1000,"")) -> 0
B19: Borðsalt | C19: 600 | D19: Salt (salt, kekkjavarnarefni E535, lyftiefni E500). | F19: Framleitt á svæði þar sem unnið er með mjólk, glúten, egg, sesam, sellerí, soja og sinnep. | G19: 0 | H19: 0 | I19: 0 | J19: 0 | K19: 0 | L19: 0 | M19: 100 | O19: =IF(OR(B19="",C19=""),"",IFERROR(C19/1000*IFERROR(INDEX(Vöruskrá!R:R,MATCH(B19,Vöruskrá!B:B,0)),0)/1000,"")) -> 0
B20: Svartur pipar, malaður | C20: 80 | D20: Svartur pipar 100%. | F20: Framleitt á svæði þar sem unnið er með glúten, fisk, krabbadýr, lindýr, mjólk, soja, sellerí, sinnep og sesam. | G20: 386 | H20: 3.3 | I20: 1 | J20: 65 | K20: 0.6 | L20: 11 | M20: 0.1 | O20: =IF(OR(B20="",C20=""),"",IFERROR(C20/1000*IFERROR(INDEX(Vöruskrá!R:R,MATCH(B20,Vöruskrá!B:B,0)),0)/1000,"")) -> 0
B21: Vatn | C21: 7350 | D21: Vatn | E21: Engir skráðir | G21: 0 | H21: 0 | I21: 0 | J21: 0 | K21: 0 | L21: 0 | M21: 0 | N21: 0 | O21: =IF(OR(B21="",C21=""),"",IFERROR(C21/1000*IFERROR(INDEX(Vöruskrá!R:R,MATCH(B21,Vöruskrá!B:B,0)),0)/1000,"")) -> 0
B22: Maizenamjöl (majssterkja) | C22: 1200 | D22: Maíssterkja. | O22: =IF(OR(B22="",C22=""),"",IFERROR(C22/1000*IFERROR(INDEX(Vöruskrá!R:R,MATCH(B22,Vöruskrá!B:B,0)),0)/1000,"")) -> 0
A23: Mildur kjúklingakarrýréttur | D23: Úrbeinað og skinnlaust kjúklingalæri 80%, vatn 19%, salt, sykur, þráavarnarefni (E331, E301), sýrustillir (E262). | Hrísgrjón 100% | Laukur (90%), repjuolía (10%). | Gulrætur | Kókosmjólk, vatn, gúargúmmí. | Hvítlauksduft 100% | Maíssterkja. | Salt (salt, kekkjavarnarefni E535, lyftiefni E500). | Svartur pipar 100%. | Vatn | E23: kókos | G23: 169.2 | H23: 6.78 | I23: 3.05 | J23: 19.1 | L23: 7.34 | M23: 0.98 | N23: 0.68 | O23: =IF(OR(B23="",C23=""),"",IFERROR(C23/1000*IFERROR(INDEX(Vöruskrá!R:R,MATCH(B23,Vöruskrá!B:B,0)),0)/1000,"")) | P23: Matarstund | MK-100KG-20260529 | Q23: 1. Hitið karrýsósu í potti við meðalhita í 20-25 mín, hrærið reglulega. 2. Eldið hrísgrjón skv. leiðbeiningum. 3. Berið fram karrý yfir hrísgrjónum. | R23: Hitið karrýsósu í potti við meðalhita í 20-25 mín, hrærið reglulega. Eldið hrísgrjón skv. leiðbeiningum. Berið fram.
B24: Kjúklingalæri úrbeinuð | C24: 35000 | D24: Úrbeinað og skinnlaust kjúklingalæri 80%, vatn 19%, salt, sykur, þráavarnarefni (E331, E301), sýrustillir (E262). | G24: 137 | H24: 9 | I24: 2.3 | L24: 14 | M24: 0.8 | O24: =IF(OR(B24="",C24=""),"",IFERROR(C24/1000*IFERROR(INDEX(Vöruskrá!R:R,MATCH(B24,Vöruskrá!B:B,0)),0)/1000,"")) -> 0
B25: Hrísgrjón Thai Hom Mali (Royal Umbrella) | C25: 18000 | D25: Hrísgrjón 100% | O25: =IF(OR(B25="",C25=""),"",IFERROR(C25/1000*IFERROR(INDEX(Vöruskrá!R:R,MATCH(B25,Vöruskrá!B:B,0)),0)/1000,"")) -> 0 | R25: GUFA 98°C, lok á, kjarnhiti 75°C. Hrá: 3,3 kg hrísgrjón + 5 kg sjóðandi vatn, 55 mín. Endurhituð: 25 mín.
B26: Forsteiktur laukur | C26: 8000 | D26: Laukur (90%), repjuolía (10%). | G26: 114 | H26: 8.6 | I26: 1.1 | J26: 6.9 | K26: 3.9 | L26: 1.2 | M26: 0 | N26: 1.9 | O26: =IF(OR(B26="",C26=""),"",IFERROR(C26/1000*IFERROR(INDEX(Vöruskrá!R:R,MATCH(B26,Vöruskrá!B:B,0)),0)/1000,"")) -> 0
B27: Gulrætur (ferskar) | C27: 8000 | D27: Gulrætur | E27: Engir skráðir | G27: 41 | H27: 0.2 | I27: 0 | J27: 9.6 | K27: 4.7 | L27: 0.9 | M27: 0.07 | N27: 2.8 | O27: =IF(OR(B27="",C27=""),"",IFERROR(C27/1000*IFERROR(INDEX(Vöruskrá!R:R,MATCH(B27,Vöruskrá!B:B,0)),0)/1000,"")) -> 0
B28: Kókosmjólk Roland Coconut Milk | C28: 12000 | D28: Kókosmjólk, vatn, gúargúmmí. | E28: kókos | G28: 181 | H28: 18 | I28: 15.3 | J28: 2.8 | K28: 1 | L28: 2 | M28: 0 | N28: 0 | O28: =IF(OR(B28="",C28=""),"",IFERROR(C28/1000*IFERROR(INDEX(Vöruskrá!R:R,MATCH(B28,Vöruskrá!B:B,0)),0)/1000,"")) -> 0
B29: Hvítlauksduft (Vitlökspulver) | C29: 500 | D29: Hvítlauksduft 100% | F29: Framleitt á svæði þar sem unnið er með glúten, fisk, krabbadýr, lindýr, mjólk, soja, sellerí, sinnep og sesam. | G29: 385 | H29: 0.8 | I29: 0.1 | J29: 73 | K29: 24 | L29: 17 | M29: 0.1 | O29: =IF(OR(B29="",C29=""),"",IFERROR(C29/1000*IFERROR(INDEX(Vöruskrá!R:R,MATCH(B29,Vöruskrá!B:B,0)),0)/1000,"")) -> 0
B30: Maizenamjöl (majssterkja) | C30: 1000 | D30: Maíssterkja. | O30: =IF(OR(B30="",C30=""),"",IFERROR(C30/1000*IFERROR(INDEX(Vöruskrá!R:R,MATCH(B30,Vöruskrá!B:B,0)),0)/1000,"")) -> 0
B31: Borðsalt | C31: 600 | D31: Salt (salt, kekkjavarnarefni E535, lyftiefni E500). | F31: Framleitt á svæði þar sem unnið er með mjólk, glúten, egg, sesam, sellerí, soja og sinnep. | G31: 0 | H31: 0 | I31: 0 | J31: 0 | K31: 0 | L31: 0 | M31: 100 | O31: =IF(OR(B31="",C31=""),"",IFERROR(C31/1000*IFERROR(INDEX(Vöruskrá!R:R,MATCH(B31,Vöruskrá!B:B,0)),0)/1000,"")) -> 0
B32: Svartur pipar, malaður | C32: 100 | D32: Svartur pipar 100%. | F32: Framleitt á svæði þar sem unnið er með glúten, fisk, krabbadýr, lindýr, mjólk, soja, sellerí, sinnep og sesam. | G32: 386 | H32: 3.3 | I32: 1 | J32: 65 | K32: 0.6 | L32: 11 | M32: 0.1 | O32: =IF(OR(B32="",C32=""),"",IFERROR(C32/1000*IFERROR(INDEX(Vöruskrá!R:R,MATCH(B32,Vöruskrá!B:B,0)),0)/1000,"")) -> 0
B33: Vatn | C33: 7600 | D33: Vatn | E33: Engir skráðir | G33: 0 | H33: 0 | I33: 0 | J33: 0 | K33: 0 | L33: 0 | M33: 0 | N33: 0 | O33: =IF(OR(B33="",C33=""),"",IFERROR(C33/1000*IFERROR(INDEX(Vöruskrá!R:R,MATCH(B33,Vöruskrá!B:B,0)),0)/1000,"")) -> 0
A34: Mild tikka masala með kjúklingi | D34: Úrbeinað og skinnlaust kjúklingalæri 80%, vatn 19%, salt, sykur, þráavarnarefni (E331, E301), sýrustillir (E262). | Vatn, sykur, laukur, tómatmauk, sólblómaolía, salt, kóríanderduft, engifer, hvítlaukur, **sinnep**duft, sýrustillir (sítrónusýra E330), chili, kúmenduft, fenugreeklauf, svartur piparduft, kóríander, þráavarnarefni (E306). | Kókosmjólk, vatn, gúargúmmí. | Sellerírót (33%), gulrætur (32%), blaðlaukur (15%), **sellerí** (10%), laukur (10%) | Tómatar | Hvítlauksduft 100% | Salt (salt, kekkjavarnarefni E535, lyftiefni E500). | Súkrósi | Vatn | E34: Sinnep, kókos, Sellerí | G34: 139.84 | H34: 8.55 | I34: 2.67 | J34: 5 | L34: 10.48 | M34: 1.57 | N34: 0.34 | O34: =IF(OR(B34="",C34=""),"",IFERROR(C34/1000*IFERROR(INDEX(Vöruskrá!R:R,MATCH(B34,Vöruskrá!B:B,0)),0)/1000,"")) | P34: Matarstund | TMK-100KG-20260529 | Q34: 1. Hitið tikka masala í potti við meðalhita í 20-25 mín. 2. Eldið hrísgrjón eða naan. 3. Berið fram heitt. | R34: Hitið tikka masala í potti við meðalhita í 20-25 mín. Eldið hrísgrjón. Berið fram heitt.
B35: Kjúklingalæri úrbeinuð | C35: 70000 | D35: Úrbeinað og skinnlaust kjúklingalæri 80%, vatn 19%, salt, sykur, þráavarnarefni (E331, E301), sýrustillir (E262). | G35: 137 | H35: 9 | I35: 2.3 | L35: 14 | M35: 0.8 | O35: =IF(OR(B35="",C35=""),"",IFERROR(C35/1000*IFERROR(INDEX(Vöruskrá!R:R,MATCH(B35,Vöruskrá!B:B,0)),0)/1000,"")) -> 0
B36: Sauce tikka masala GT-CHEF | C36: 18000 | D36: Vatn, sykur, laukur, tómatmauk, sólblómaolía, salt, kóríanderduft, engifer, hvítlaukur, **sinnep**duft, sýrustillir (sítrónusýra E330), chili, kúmenduft, fenugreeklauf, svartur piparduft, kóríander, þráavarnarefni (E306). | E36: Sinnep | G36: 150 | H36: 5.9 | I36: 0.6 | J36: 22 | K36: 18 | L36: 1.4 | M36: 4.4 | N36: 1.6 | O36: =IF(OR(B36="",C36=""),"",IFERROR(C36/1000*IFERROR(INDEX(Vöruskrá!R:R,MATCH(B36,Vöruskrá!B:B,0)),0)/1000,"")) -> 0
B37: Kókosmjólk Roland Coconut Milk | C37: 6000 | D37: Kókosmjólk, vatn, gúargúmmí. | E37: kókos | G37: 181 | H37: 18 | I37: 15.3 | J37: 2.8 | K37: 1 | L37: 2 | M37: 0 | N37: 0 | O37: =IF(OR(B37="",C37=""),"",IFERROR(C37/1000*IFERROR(INDEX(Vöruskrá!R:R,MATCH(B37,Vöruskrá!B:B,0)),0)/1000,"")) -> 0
B38: Brunoise grænmetisblanda | C38: 2000 | D38: Sellerírót (33%), gulrætur (32%), blaðlaukur (15%), **sellerí** (10%), laukur (10%) | E38: Sellerí | G38: 26 | H38: 0.4 | I38: 0.1 | J38: 3.4 | K38: 2.9 | L38: 1 | M38: 0.1 | N38: 2.5 | O38: =IF(OR(B38="",C38=""),"",IFERROR(C38/1000*IFERROR(INDEX(Vöruskrá!R:R,MATCH(B38,Vöruskrá!B:B,0)),0)/1000,"")) -> 0
B39: Tómatpuré Doppio Concentrato 800 g (Menu) | C39: 1500 | D39: Tómatar | G39: 113 | H39: 0.4 | I39: 0 | J39: 19 | K39: 14 | L39: 6 | M39: 0.1 | O39: =IF(OR(B39="",C39=""),"",IFERROR(C39/1000*IFERROR(INDEX(Vöruskrá!R:R,MATCH(B39,Vöruskrá!B:B,0)),0)/1000,"")) -> 0
B40: Hvítlauksduft (Vitlökspulver) | C40: 500 | D40: Hvítlauksduft 100% | F40: Framleitt á svæði þar sem unnið er með glúten, fisk, krabbadýr, lindýr, mjólk, soja, sellerí, sinnep og sesam. | G40: 385 | H40: 0.8 | I40: 0.1 | J40: 73 | K40: 24 | L40: 17 | M40: 0.1 | O40: =IF(OR(B40="",C40=""),"",IFERROR(C40/1000*IFERROR(INDEX(Vöruskrá!R:R,MATCH(B40,Vöruskrá!B:B,0)),0)/1000,"")) -> 0
...

Sheet Grunnmatseðill
A1: GRUNNMATSEÐILL | T1: Eldunarleiðbeiningar | AB1: Gildir-listi (sjálfvirkt) ↓ | AC1: Bæði
A2: Dagsetning | B2: Dagur (sjálfvirkt) | C2: Vika (sjálfvirkt) | D2: Gildir fyrir | E2: Máltíðartegund | F2: Vara / Réttur (leitarnafn) | G2: Birtingarnafn (vefur) | H2: Skammtur Leikskóli (g) | I2: Skammtur Grunnskóli (g) | J2: Foodcost (kr/skammt) | K2: Innihaldslýsing (sjálfvirkt) | L2: Ofnæmisvaldar (sjálfvirkt) | M2: Fyrirvari (sjálfvirkt) | N2: Orka (kcal) | O2: Fita (g) | P2: Mettuð fita (g) | Q2: Kolvetni (g) | R2: Prótein (g) | S2: Salt (g) | T2: Eldunarpöntun (1, 2, 3...) | U2: Upphafsástand | V2: Eldunaraðferð | W2: Ofnhiti (°C) | X2: Eldunartími (mín) | Y2: Kjarnhiti (°C) | Z2: Hræra / snúa | AA2: Hvíld eftir eldun (mín) | AC2: Leikskóli
A3: 46195 | B3: Mánudagur | C3: 26 | D3: Leikskóli | E3: Aðalréttur | G3: Mildur kjúklinga-karríréttur, hrísgrjón | K3: Hrísgrjón 100% | Úrbeinað og skinnlaust kjúklingalæri 80%, vatn 19%, salt, sykur, þráavarnarefni (E331, E301), sýrustillir (E262). | Hrísgrjón 100% | Laukur (90%), repjuolía (10%). | Gulrætur | Kókosmjólk, vatn, gúargúmmí. | Hvítlauksduft 100% | Maíssterkja. | Salt (salt, kekkjavarnarefni E535, lyftiefni E500). | Svartur pipar 100%. | Vatn | L3: kókos | AC3: Grunnskóli
B4: Mánudagur | C4: 26 | D4: Leikskóli | E4: Aðalréttur | F4: Hrísgrjón Thai Hom Mali (Royal Umbrella) | G4: Hrísgrjón | H4: 80 | K4: Hrísgrjón 100% | N4: 292 | O4: 0.6 | P4: 0.2 | Q4: 64 | R4: 5.6 | S4: 0 | T4: 1 | U4: Kælt | V4: Ofn | W4: 150 | X4: 15 | Y4: 75 | Z4: Hylja, hræra einu sinni | AC4: Engidalsskóli
B5: Mánudagur | C5: 26 | D5: Leikskóli | E5: Aðalréttur | F5: Mildur kjúklingakarrýréttur | G5: Kjúklingakarrý | H5: 250 | K5: Úrbeinað og skinnlaust kjúklingalæri 80%, vatn 19%, salt, sykur, þráavarnarefni (E331, E301), sýrustillir (E262). | Hrísgrjón 100% | Laukur (90%), repjuolía (10%). | Gulrætur | Kókosmjólk, vatn, gúargúmmí. | Hvítlauksduft 100% | Maíssterkja. | Salt (salt, kekkjavarnarefni E535, lyftiefni E500). | Svartur pipar 100%. | Vatn | L5: kókos | N5: 423 | O5: 17 | P5: 7.6 | Q5: 47.8 | R5: 18.4 | S5: 2.5 | T5: 2 | U5: Kælt | V5: Pottur | X5: 20 | Y5: 75 | Z5: Hræra á 5 mín fresti | AC5: Hraunvallaskóli
B6: Mánudagur | C6: 26 | D6: Leikskóli | E6: Sérfæði | G6: Marrakesh pottréttur (mjólkur-/kjötlaus) | K6: Tómatar, kjúklingabaunir, laukur, gulrætur, sætar kartöflur, eplasafi, blómkál, repjuolía, döðlur, limesafi (inniheldur **SÚLFÍÐ**), paprikamauk, hvítlaukur, salt, kóríander, chilimauk, grænmetiskraftur, kúmen, engifer, túrmerik, svartur pipar, kanill. | L6: Súlfít, sellerí. | AC6: Hvaleyrarskóli
B7: Mánudagur | C7: 26 | D7: Leikskóli | E7: Sérfæði | F7: Marrakesh pottréttur | G7: Marrakesh pottréttur | H7: 250 | K7: Tómatar, kjúklingabaunir, laukur, gulrætur, sætar kartöflur, eplasafi, blómkál, repjuolía, döðlur, limesafi (inniheldur **SÚLFÍÐ**), paprikamauk, hvítlaukur, salt, kóríander, chilimauk, grænmetiskraftur, kúmen, engifer, túrmerik, svartur pipar, kanill. | L7: Súlfít, sellerí. | M7: Framleitt á svæði þar sem unnið er með hnetur | N7: 295 | O7: 11.3 | P7: 1 | Q7: 33.8 | R7: 9.5 | S7: 2.3 | T7: 1 | U7: Frosið | V7: Ofn | W7: 180 | X7: 22 | Y7: 75 | Z7: Hræra einu sinni | AA7: 2 | AC7: Lækjarskóli
B8: Mánudagur | C8: 26 | D8: Leikskóli | E8: Hliðarréttur | G8: Mildur grænmetis-karríréttur, hrísgrjón | K8: Hrísgrjón 100% | BYGG, kartöflur, kjúklingabaunir, grænar baunir, chilimauk, tómatpúrra, kartöflumjöl, salt, engifer, kóríander, hvítlaukur. | Hrísgrjón 100% | Laukur (90%), repjuolía (10%). | Gulrætur | Kókosmjólk, vatn, gúargúmmí. | Hvítlauksduft 100% | Maíssterkja. | Salt (salt, kekkjavarnarefni E535, lyftiefni E500). | Vatn | L8: Glúten (bygg), kókos | AC8: Öldutúnsskóli
B9: Mánudagur | C9: 26 | D9: Leikskóli | E9: Hliðarréttur | F9: Hrísgrjón Thai Hom Mali (Royal Umbrella) | G9: Hrísgrjón | H9: 80 | K9: Hrísgrjón 100% | N9: 292 | O9: 0.6 | P9: 0.2 | Q9: 64 | R9: 5.6 | S9: 0 | T9: 1 | U9: Kælt | V9: Ofn | W9: 150 | X9: 15 | Y9: 75 | Z9: Hylja, hræra einu sinni | AC9: Setbergsskóli
B10: Mánudagur | C10: 26 | D10: Leikskóli | E10: Hliðarréttur | F10: Mildur grænmetiskarrýréttur | G10: Grænmetiskarrý | H10: 250 | K10: BYGG, kartöflur, kjúklingabaunir, grænar baunir, chilimauk, tómatpúrra, kartöflumjöl, salt, engifer, kóríander, hvítlaukur. | Hrísgrjón 100% | Laukur (90%), repjuolía (10%). | Gulrætur | Kókosmjólk, vatn, gúargúmmí. | Hvítlauksduft 100% | Maíssterkja. | Salt (salt, kekkjavarnarefni E535, lyftiefni E500). | Vatn | L10: Glúten (bygg), kókos | N10: 492.7 | O10: 10.9 | P10: 6.3 | Q10: 82.1 | R10: 12 | S10: 2.6 | T10: 2 | U10: Kælt | V10: Pottur | X10: 20 | Y10: 75 | Z10: Hræra á 5 mín fresti | AC10: Skarðshlíðarskóli
B11: Mánudagur | C11: 26 | D11: Leikskóli | E11: Meðlætisbar | G11: Gúrka, ávextir | L11: Engir skráðir | V11: Engin (kalt) | AC11: Víðistaðaskóli
B12: Mánudagur | C12: 26 | D12: Leikskóli | E12: Síðdegishressing | G12: Skólabollur með osti og gúrku | K12: Vatn, heilkorna **rúg**mjöl 20%, heilkorna **hveiti**mjöl 17%, **hveiti**mjöl, **hveiti**glúten, **rúg**mjöl, þurrkað súrdeig (**rúg**, súrdeigsgerlar), **hveiti**kurl, ger, maltextrakt (**bygg**), repjuolía, joðbætt salt, þykkingarefni (E415), sýrustillir (E262), ýruefni (E471, E472e), mjölmeðhöndlunarefni (E300), maltað **hveiti**. | Mjólk, undanrenna, salt, ostahleypir. | L12: Glúten (rúgur, hveiti, bygg), Mjólk | AC12: Álfaberg
B13: Mánudagur | C13: 26 | D13: Leikskóli | E13: Síðdegishressing | F13: Skólabollur | G13: Skólabollur | H13: 45 | K13: Vatn, heilkorna **rúg**mjöl 20%, heilkorna **hveiti**mjöl 17%, **hveiti**mjöl, **hveiti**glúten, **rúg**mjöl, þurrkað súrdeig (**rúg**, súrdeigsgerlar), **hveiti**kurl, ger, maltextrakt (**bygg**), repjuolía, joðbætt salt, þykkingarefni (E415), sýrustillir (E262), ýruefni (E471, E472e), mjölmeðhöndlunarefni (E300), maltað **hveiti**. | L13: Glúten (rúgur, hveiti, bygg) | M13: Framleitt á svæði þar sem unnið er með sesamfræ, egg, mjólk og lúpínu | N13: 99.5 | O13: 1.3 | P13: 0.2 | Q13: 15.3 | R13: 5 | S13: 0.5 | T13: 1 | U13: Frosið | V13: Ofn | W13: 180 | X13: 7 | Z13: Snúa einu sinni | AA13: 2 | AC13: Arnarberg
B14: Mánudagur | C14: 26 | D14: Leikskóli | E14: Síðdegishressing | F14: Góðostur 26% sneiðar | G14: Ostur | H14: 15 | K14: Mjólk, undanrenna, salt, ostahleypir. | L14: Mjólk | N14: 49.5 | O14: 3.9 | P14: 2.1 | Q14: 0 | R14: 3.8 | S14: 0.2 | T14: 2 | U14: Kælt | V14: Engin (kalt) | AC14: Bjarkalundur
A15: 46196 | B15: Þriðjudagur | C15: 26 | D15: Leikskóli | E15: Aðalréttur | G15: Ofnbökuð ýsa, smælki, brætt smjör | K15: Kartöflur | Ýsa, raspur (**hveiti**, vatn, ger, salt, litarefni (E100, E160b)), hjúpur (**hveiti**, **glúten**, salt, umbreytt **hveiti**sterkja). | L15: Fiskur, hveiti, glúten | AC15: Hlíðarberg
B16: Þriðjudagur | C16: 26 | D16: Leikskóli | E16: Aðalréttur | F16: Forsoðnar kartöflur | G16: Kartöflusmælki | H16: 100 | K16: Kartöflur | L16: Engir skráðir | N16: 77 | O16: 0.1 | P16: 0 | Q16: 16.3 | R16: 1.8 | S16: 0 | T16: 1 | U16: Kælt | V16: Ofn | W16: 200 | X16: 15 | Y16: 75 | Z16: Hræra einu sinni | AC16: Hörðuvellir
B17: Þriðjudagur | C17: 26 | D17: Leikskóli | E17: Aðalréttur | F17: Ýsa í raspi | G17: Ýsa í raspi | H17: 130 | K17: Ýsa, raspur (**hveiti**, vatn, ger, salt, litarefni (E100, E160b)), hjúpur (**hveiti**, **glúten**, salt, umbreytt **hveiti**sterkja). | L17: Fiskur, hveiti, glúten | N17: 162.5 | O17: 1.3 | P17: 0.4 | Q17: 14.3 | R17: 23.4 | S17: 0.9 | T17: 2 | U17: Frosið | V17: Ofn | W17: 200 | X17: 18 | Y17: 75 | Z17: Snúa einu sinni | AA17: 3 | AC17: Leikskólinn við Hraunvallaskóla
B18: Þriðjudagur | C18: 26 | D18: Leikskóli | E18: Sérfæði | G18: Kjúklingabollur (fisklaust) | K18: Kjúklingaleggjakjöt, kartöflusterkja, vatn, **soja**prótein, salt, þurrkað grænmeti (laukur, hvítlaukur, paprika), bragðefni (**soja**), krydd (**sinnep**), þrúgusykur, **hveiti**prótein, gerextrakt, litarefni (E160c), krydd, ger, repjuolía, fosfat (E450) | Rjómi, salt. | L18: Hveiti, soja, sinnep, Mjólk | AC18: Leikskólinn við Skarðshlíðarskóla
B19: Þriðjudagur | C19: 26 | D19: Leikskóli | E19: Sérfæði | F19: Kjúklingabollur 5 kg | G19: Kjúklingabollur | H19: 130 | K19: Kjúklingaleggjakjöt, kartöflusterkja, vatn, **soja**prótein, salt, þurrkað grænmeti (laukur, hvítlaukur, paprika), bragðefni (**soja**), krydd (**sinnep**), þrúgusykur, **hveiti**prótein, gerextrakt, litarefni (E160c), krydd, ger, repjuolía, fosfat (E450) | L19: Hveiti, soja, sinnep | N19: 230.1 | O19: 11.7 | P19: 2.3 | Q19: 9.1 | R19: 22.1 | S19: 2.3 | T19: 1 | U19: Frosið | V19: Ofn | W19: 200 | X19: 14 | Y19: 75 | Z19: Snúa einu sinni | AA19: 2 | AC19: Smáralundur
B20: Þriðjudagur | C20: 26 | D20: Leikskóli | E20: Meðlæti | F20: Smjör 500 g | G20: Brætt smjör | H20: 10 | K20: Rjómi, salt. | L20: Mjólk | N20: 73.8 | O20: 8.2 | P20: 4.9 | Q20: 0 | R20: 0.1 | S20: 0.1 | T20: 3 | U20: Kælt | V20: Pottur | X20: 3 | Z20: Bræða við vægan hita | AC20: Stekkjarás
B21: Þriðjudagur | C21: 26 | D21: Leikskóli | E21: Hliðarréttur | G21: Grænmetisbuff, smælki, hvítlauksmæjó | K21: Kartöflur | Grænkál 17%, raspur 15% (**spelt**mjöl, poppað kínóa, sólblómaolía, salt, ger), forsoðið kínóa 13%, vatn, jurtaolía, kartöflur, gulrætur, ristaður laukur, **sojabaunir**, kartöfluflögur, **hveiti**mjöl, kryddblanda, sojasósa (vatn, salt, **sojabaunir**, **hveiti**), joðbætt salt, karríduft, hvítlauksduft, malað engifer, svartur pipar. | Repjuolía, vatn, hvítlaukur, **sinnep**, kryddblanda, sykur, umbreytt kartöflusterkja, salt, edik, rotvarnarefni (E260, E211, E202), **sinnep**sduft, sýra (E330), bindiefni (E415) | L21: Glúten (spelt, hveiti), soja., Sinnep | AC21: Tjarnarás
B22: Þriðjudagur | C22: 26 | D22: Leikskóli | E22: Hliðarréttur | F22: Forsoðnar kartöflur | G22: Kartöflusmælki | H22: 100 | K22: Kartöflur | L22: Engir skráðir | N22: 77 | O22: 0.1 | P22: 0 | Q22: 16.3 | R22: 1.8 | S22: 0 | T22: 1 | U22: Kælt | V22: Ofn | W22: 200 | X22: 15 | Y22: 75 | AC22: Vesturkot
B23: Þriðjudagur | C23: 26 | D23: Leikskóli | E23: Hliðarréttur | F23: Quinoa Grænkálsbuff | G23: Grænmetisbuff | H23: 140 | K23: Grænkál 17%, raspur 15% (**spelt**mjöl, poppað kínóa, sólblómaolía, salt, ger), forsoðið kínóa 13%, vatn, jurtaolía, kartöflur, gulrætur, ristaður laukur, **sojabaunir**, kartöfluflögur, **hveiti**mjöl, kryddblanda, sojasósa (vatn, salt, **sojabaunir**, **hveiti**), joðbætt salt, karríduft, hvítlauksduft, malað engifer, svartur pipar. | L23: Glúten (spelt, hveiti), soja. | N23: 296.8 | O23: 16 | P23: 1.8 | Q23: 30.4 | R23: 6.3 | S23: 1.4 | T23: 2 | U23: Frosið | V23: Ofn | W23: 200 | X23: 14 | Y23: 75 | Z23: Snúa einu sinni | AA23: 2 | AC23: Víðivellir
B24: Þriðjudagur | C24: 26 | D24: Leikskóli | E24: Meðlæti | F24: Hvítlauks aioli GARRI vegan 725 ml | G24: Hvítlauksmæjó | H24: 20 | K24: Repjuolía, vatn, hvítlaukur, **sinnep**, kryddblanda, sykur, umbreytt kartöflusterkja, salt, edik, rotvarnarefni (E260, E211, E202), **sinnep**sduft, sýra (E330), bindiefni (E415) | L24: Sinnep | N24: 103.8 | O24: 11.2 | P24: 0.7 | Q24: 1.2 | S24: 0.2 | T24: 3 | U24: Kælt | V24: Engin (kalt) | AC24: Álfakot
B25: Þriðjudagur | C25: 26 | D25: Leikskóli | E25: Meðlætisbar | G25: Byggsalat, ávextir | K25: Bygg, vatn, krydd (hvítur pipar, salt), sítrónusafi, olífu olía. | L25: Glúten (bygg) | V25: Engin (kalt) | AC25: Hraunsel
B26: Þriðjudagur | C26: 26 | D26: Leikskóli | E26: Meðlætisbar | F26: Byggsalat | G26: Byggsalat | H26: 20 | K26: Bygg, vatn, krydd (hvítur pipar, salt), sítrónusafi, olífu olía. | L26: Glúten (bygg) | N26: 24.2 | O26: 0.1 | P26: 0 | Q26: 5.6 | R26: 0.5 | S26: 0 | U26: Kælt | V26: Engin (kalt) | AC26: Holtasel
B27: Þriðjudagur | C27: 26 | D27: Leikskóli | E27: Síðdegishressing | G27: Maltað kornbrauð með kjúklingaáleggi | K27: Vatn, heil**hveiti**, **hveitimjöl**, brotin **rúgur**, súrdeig úr **hveiti**, **hveitiglúten**, **heilhveiti**, **durumhveiti**, ger, sólblómafræ, epli, kaldpressuð repjuolía, hörfræ, **bygg**malt, sykur, sýrustillir (sítrónusýra), salt. | Úrbeinuð skinnlaus kjúklingalæri (83%), vatn, salt, jurtaolía, sykur, mango chutney, ávaxtaþykkni, sýrustillir (E500), krydd reykbragðefni, rotvarnarefni (E262), þráavarnarefni (E320) | L27: Glúten (hveiti, rúgur) | AC27: Lækjarsel
B28: Þriðjudagur | C28: 26 | D28: Leikskóli | E28: Síðdegishressing | F28: Heilkornastykki | G28: Kornbrauð | H28: 60 | K28: Vatn, heil**hveiti**, **hveitimjöl**, brotin **rúgur**, súrdeig úr **hveiti**, **hveitiglúten**, **heilhveiti**, **durumhveiti**, ger, sólblómafræ, epli, kaldpressuð repjuolía, hörfræ, **bygg**malt, sykur, sýrustillir (sítrónusýra), salt. | L28: Glúten (hveiti, rúgur) | N28: 162 | O28: 3.1 | P28: 0.4 | Q28: 24 | R28: 7.2 | S28: 0.6 | T28: 1 | U28: Ferskt | V28: Engin (kalt) | AC28: Selið
B29: Þriðjudagur | C29: 26 | D29: Leikskóli | E29: Síðdegishressing | F29: kjúklinga Lærakjöt Rodizio | G29: Kjúklingaálegg | H29: 20 | K29: Úrbeinuð skinnlaus kjúklingalæri (83%), vatn, salt, jurtaolía, sykur, mango chutney, ávaxtaþykkni, sýrustillir (E500), krydd reykbragðefni, rotvarnarefni (E262), þráavarnarefni (E320) | N29: 41.2 | O29: 2 | P29: 0.4 | Q29: 0.8 | R29: 5 | S29: 0.6 | T29: 2 | U29: Kælt | V29: Engin (kalt) | AC29: Krakkaberg
A30: 46197 | B30: Miðvikudagur | C30: 26 | D30: Leikskóli | E30: Aðalréttur | G30: Grjónagrautur, lifrarpylsa | K30: **Mjólk**, hrísgrjón(12%), sykur, salt. | Lambalifur 32%, lambamör, **RÚGMJÖL**, **HAFRAMJÖL**, vatn, salt. | L30: Mjólk, Glúten (RÚGMJÖL, HAFRAMJÖL) | AC30: Skarðssel
B31: Miðvikudagur | C31: 26 | D31: Leikskóli | E31: Aðalréttur | F31: Heimilis grjónagrautur | G31: Grjónagrautur | H31: 250 | K31: **Mjólk**, hrísgrjón(12%), sykur, salt. | L31: Mjólk | N31: 227.5 | O31: 7.5 | P31: 4 | Q31: 35 | R31: 7.5 | S31: 1.3 | T31: 1 | U31: Kælt | V31: Pottur | X31: 15 | Y31: 75 | Z31: Hræra á 5 mín fresti svo hann brenni ekki við | AC31: Hraunkot
B32: Miðvikudagur | C32: 26 | D32: Leikskóli | E32: Aðalréttur | F32: Lifrarpylsa án mjólkur, soðin | G32: Lifrarpylsa | H32: 25 | K32: Lambalifur 32%, lambamör, **RÚGMJÖL**, **HAFRAMJÖL**, vatn, salt. | L32: Glúten (RÚGMJÖL, HAFRAMJÖL) | N32: 100.3 | O32: 8.2 | P32: 4.2 | Q32: 3.9 | R32: 2.6 | S32: 0.3 | T32: 2 | U32: Kælt | V32: Vatnsbað | X32: 20 | Y32: 75
B33: Miðvikudagur | C33: 26 | D33: Leikskóli | E33: Sérfæði | G33: Vegan grjónagrautur (mjólkurlaus) | K33: Vegan rjómi (vatn, kókoskjarnaolía, pálmaolía, þurrkað glúkósasíróp, umbreytt sterkja, salt, stöðugleikaefni fosfat E339, gellangúmmí, ýruefni lesitín, E435, E472b, litarefni karótín, náttúrulegt bragðefni), vatn, hrísgrjón, sykur, salt. | L33: Engir skráðir
B34: Miðvikudagur | C34: 26 | D34: Leikskóli | E34: Sérfæði | F34: Vegan grjónagrautur | G34: Vegan grjónagrautur | H34: 250 | K34: Vegan rjómi (vatn, kókoskjarnaolía, pálmaolía, þurrkað glúkósasíróp, umbreytt sterkja, salt, stöðugleikaefni fosfat E339, gellangúmmí, ýruefni lesitín, E435, E472b, litarefni karótín, náttúrulegt bragðefni), vatn, hrísgrjón, sykur, salt. | L34: Engir skráðir | N34: 185 | O34: 4 | P34: 0.8 | Q34: 32.5 | R34: 4.5 | S34: 1 | T34: 1 | U34: Kælt | V34: Pottur | X34: 15 | Y34: 75 | Z34: Hræra á 5 mín fresti
B35: Miðvikudagur | C35: 26 | D35: Leikskóli | E35: Hliðarréttur | G35: Vegan grjónagrautur, kanill | K35: Vegan rjómi (vatn, kókoskjarnaolía, pálmaolía, þurrkað glúkósasíróp, umbreytt sterkja, salt, stöðugleikaefni fosfat E339, gellangúmmí, ýruefni lesitín, E435, E472b, litarefni karótín, náttúrulegt bragðefni), vatn, hrísgrjón, sykur, salt. | L35: Engir skráðir
B36: Miðvikudagur | C36: 26 | D36: Leikskóli | E36: Hliðarréttur | F36: Vegan grjónagrautur | G36: Vegan grjónagrautur | H36: 250 | K36: Vegan rjómi (vatn, kókoskjarnaolía, pálmaolía, þurrkað glúkósasíróp, umbreytt sterkja, salt, stöðugleikaefni fosfat E339, gellangúmmí, ýruefni lesitín, E435, E472b, litarefni karótín, náttúrulegt bragðefni), vatn, hrísgrjón, sykur, salt. | L36: Engir skráðir | N36: 185 | O36: 4 | P36: 0.8 | Q36: 32.5 | R36: 4.5 | S36: 1 | T36: 1 | U36: Kælt | V36: Pottur | X36: 15 | Y36: 75 | Z36: Hræra á 5 mín fresti
B37: Miðvikudagur | C37: 26 | D37: Leikskóli | E37: Meðlætisbar | G37: Sólkjarnabrauð, smjör, ostur | K37: **Hveiti**, vatn, 12,3% - sólkjarnafræ, **rúgmjöl**, hörfræ, maltað **hveiti**, salt, maltað **bygg**, mjölmeðhöndlunarefni (E300), ger, malt extrakt (úr **byggi**), súrdeigsduft úr **hveiti** (**hveiti**, gerlar), dextrósi, **hveitiglúten**, bindiefni (E472e, E491), ensím, kekkjarvarnarefni (E535) | Rjómi, repjuolía, salt, A-vítamín og D-vítamín. | Mjólk, undanrenna, salt, ostahleypir. | L37: Glúten, Mjólk | V37: Engin (kalt)
B38: Miðvikudagur | C38: 26 | D38: Leikskóli | E38: Meðlætisbar | F38: Sólkjarnabrauð plötubrauð | G38: Sólkjarnabrauð | H38: 30 | K38: **Hveiti**, vatn, 12,3% - sólkjarnafræ, **rúgmjöl**, hörfræ, maltað **hveiti**, salt, maltað **bygg**, mjölmeðhöndlunarefni (E300), ger, malt extrakt (úr **byggi**), súrdeigsduft úr **hveiti** (**hveiti**, gerlar), dextrósi, **hveitiglúten**, bindiefni (E472e, E491), ensím, kekkjarvarnarefni (E535) | L38: Glúten | M38: Gæti innihaldið snefil af sesamfræjum | N38: 93.3 | O38: 3.2 | P38: 0.4 | Q38: 12.1 | R38: 3.2 | S38: 0.3 | U38: Ferskt | V38: Engin (kalt)
B39: Miðvikudagur | C39: 26 | D39: Leikskóli | E39: Meðlætisbar | F39: Smjörvi 400 g | G39: Smjörvi | H39: 5 | K39: Rjómi, repjuolía, salt, A-vítamín og D-vítamín. | L39: Mjólk | N39: 35.1 | O39: 3.9 | P39: 1.9 | Q39: 0 | R39: 0 | S39: 0.1 | U39: Kælt | V39: Engin (kalt)
B40: Miðvikudagur | C40: 26 | D40: Leikskóli | E40: Meðlætisbar | F40: Góðostur 26% sneiðar | G40: Ostur | H40: 15 | K40: Mjólk, undanrenna, salt, ostahleypir. | L40: Mjólk | N40: 49.5 | O40: 3.9 | P40: 2.1 | Q40: 0 | R40: 3.8 | S40: 0.2 | U40: Kælt | V40: Engin (kalt)
...

Sheet Ofnæmismatseðill
A1: OFNÆMISMATSEÐILL — SJÁLFVIRK TENGING NEMENDA VIÐ RÉTTI
A2: 💡 Þessi listi sýnir alla sem fá EKKI aðalréttinn þennan dag. 🔴 RAUTT = enginn réttur hentar, krefst sérréttar. 🟡 Gult = fær hliðarrétt eða ofnæmisrétt.
A3: Dagsetning | B3: Skóli | C3: Nafn | D3: Deild | E3: Ofnæmi / Óþol | F3: Athugasemd | G3: Fær rétt | H3: Ástæða | I3: Flokkun
A4: 46195 | B4: 📍 Álfaberg
A5: 46195 | B5: Álfaberg | C5: Flosi | D5: Keili | E5: Pescaterian | F5: Má fá fisk og mjólkurvörur | G5: Aðalréttur → Marrakesh pottréttur (mjólkur-/kjötlaus) | H5: Pescaterian (kjöt) | I5: en-2
A6: 46195 | B6: Álfaberg | C6: Freyr Sindrason | D6: Helgafell | E6: Pescaterian | G6: Aðalréttur → Marrakesh pottréttur (mjólkur-/kjötlaus) | H6: Pescaterian (kjöt) | I6: en-2
A7: 46195 | B7: Álfaberg | C7: Saga Sindrason | D7: Helgafell | E7: Pescaterian | G7: Aðalréttur → Marrakesh pottréttur (mjólkur-/kjötlaus) | H7: Pescaterian (kjöt) | I7: en-2
A8: 46195 | B8: Álfaberg | C8: Sif | D8: Öskju | E8: Pescaterian | G8: Aðalréttur → Marrakesh pottréttur (mjólkur-/kjötlaus) | H8: Pescaterian (kjöt) | I8: en-2
A9: 46195 | B9: 📍 Arnarberg
A10: 46195 | B10: Arnarberg | C10: Ewa | E10: vegan | F10: Má fá mjólkurvörur | G10: Aðalréttur → Marrakesh pottréttur (mjólkur-/kjötlaus) | H10: vegan (kjöt) | I10: ar-2
A11: 46195 | B11: 📍 Hörðuvellir
A12: 46195 | B12: Hörðuvellir | C12: Hrói Svöluson Nökkvason | D12: Hamar | E12: vegan, Jarðhnetur | G12: Aðalréttur → Marrakesh pottréttur (mjólkur-/kjötlaus) | H12: vegan (kjöt) | I12: ho-2
A13: 46195 | B13: Hörðuvellir | C13: Kai Zawada | D13: Hamar | E13: vegan | G13: Aðalréttur → Marrakesh pottréttur (mjólkur-/kjötlaus) | H13: vegan (kjöt) | I13: ho-2
A14: 46195 | B14: Hörðuvellir | C14: Tanya Saori Vanegas Avila | D14: Hamar | E14: vegan | G14: Aðalréttur → Marrakesh pottréttur (mjólkur-/kjötlaus) | H14: vegan (kjöt) | I14: ho-2
A15: 46195 | B15: Hörðuvellir | C15: Antoni Malysa | D15: Hraun | E15: vegan | G15: Aðalréttur → Marrakesh pottréttur (mjólkur-/kjötlaus) | H15: vegan (kjöt) | I15: ho-2
A16: 46195 | B16: Hörðuvellir | C16: Agnes Ósk Viðarsdóttir | E16: vegan | G16: Aðalréttur → Marrakesh pottréttur (mjólkur-/kjötlaus) | H16: vegan (kjöt) | I16: ho-2
A17: 46195 | B17: Hörðuvellir | C17: Anna Katrín Kristmundsdóttir | E17: vegan | G17: Aðalréttur → Marrakesh pottréttur (mjólkur-/kjötlaus) | H17: vegan (kjöt) | I17: ho-2
A18: 46195 | B18: Hörðuvellir | C18: Anna Jaskulke | E18: vegan | G18: Aðalréttur → Marrakesh pottréttur (mjólkur-/kjötlaus) | H18: vegan (kjöt) | I18: ho-2
A19: 46195 | B19: 📍 Hraunvallaleikskóli
A20: 46195 | B20: Hraunvallaleikskóli | C20: Rósa Jóna Magnúsdóttir | E20: Mjólk, Kókos | G20: Aðalréttur → Marrakesh pottréttur (mjólkur-/kjötlaus) | H20: Kókos | I20: hr-2
A21: 46195 | B21: Hraunvallaleikskóli | C21: Galyna Oliinyk | E21: vegan | G21: Aðalréttur → Marrakesh pottréttur (mjólkur-/kjötlaus) | H21: vegan (kjöt) | I21: hr-2
A22: 46195 | B22: Hraunvallaleikskóli | C22: Nina Stoyanova Atanasova | E22: vegan | G22: Aðalréttur → Marrakesh pottréttur (mjólkur-/kjötlaus) | H22: vegan (kjöt) | I22: hr-2
A23: 46195 | B23: 📍 Skarðshlíðarleikskóli
A24: 46195 | B24: Skarðshlíðarleikskóli | C24: Brynhildur Ásgeirsdóttir | E24: vegan | G24: Aðalréttur → Marrakesh pottréttur (mjólkur-/kjötlaus) | H24: vegan (kjöt) | I24: sk-2
A25: 46195 | B25: 📍 Stekkjarás
A26: 46195 | B26: Stekkjarás | C26: Kristrún Birna Birkisdóttir | D26: Álfheimar | E26: Pescaterian | F26: borðar ekki kjöt | G26: Aðalréttur → Marrakesh pottréttur (mjólkur-/kjötlaus) | H26: Pescaterian (kjöt) | I26: st-2
A27: 46195 | B27: Stekkjarás | C27: Sindri Björn Linnet | D27: Fífa | E27: Pescaterian | F27: Má ekki borða kjöt eða kjúkling, en hann má borða egg, mjólk og fisk | G27: Aðalréttur → Marrakesh pottréttur (mjólkur-/kjötlaus) | H27: Pescaterian (kjöt) | I27: st-2
A28: 46195 | B28: Stekkjarás | C28: Heena | E28: vegan | G28: Aðalréttur → Marrakesh pottréttur (mjólkur-/kjötlaus) | H28: vegan (kjöt) | I28: st-2
A29: 46195 | B29: 📍 Tjarnarás
A30: 46195 | B30: Tjarnarás | C30: Perla | E30: Pescaterian | F30: Hliðarréttur á fiskidögum | G30: Aðalréttur → Marrakesh pottréttur (mjólkur-/kjötlaus) | H30: Pescaterian (kjöt) | I30: tj-2
A31: 46195 | B31: Tjarnarás | C31: Eva Kaldal | D31: Vantar deild | E31: Vegetarian | G31: Aðalréttur → Marrakesh pottréttur (mjólkur-/kjötlaus) | H31: Vegetarian (kjöt) | I31: tj-2
A32: 46195 | B32: 📍 Víðivellir
A33: 46195 | B33: Víðivellir | C33: Saga Jónsdóttir | E33: Pescaterian | F33: Borðar ekki kjöt, borðar kjúkling, fisk, egg og mjólkurvörur | G33: Aðalréttur → Marrakesh pottréttur (mjólkur-/kjötlaus) | H33: Pescaterian (kjöt) | I33: vv-2
A34: 46195 | B34: Víðivellir | C34: Harlow Esjar Mallinson | D34: Kanínudeild | E34: Pescaterian | F34: borðar fisk, egg og mjólkurvörur | G34: Aðalréttur → Marrakesh pottréttur (mjólkur-/kjötlaus) | H34: Pescaterian (kjöt) | I34: vv-2
A35: 46195 | B35: Víðivellir | C35: Rakel Halldórs | E35: vegan | G35: Aðalréttur → Marrakesh pottréttur (mjólkur-/kjötlaus) | H35: vegan (kjöt) | I35: vv-2
A36: 46195 | B36: 📍 Norðuberg
A37: 46195 | B37: Norðuberg | C37: Anna Bielinska | E37: vegan | F37: 22 juni til 2. juli | G37: Aðalréttur → Marrakesh pottréttur (mjólkur-/kjötlaus) | H37: vegan (kjöt)
A38: 46196 | B38: 📍 Álfaberg
A39: 46196 | B39: Álfaberg | C39: Andri Antonsson | D39: Esja | E39: Fiskur, Mjólk | F39: Hvorki hvítan né bleikan | G39: Aðalréttur → ENGINN RÉTTUR HENTAR | H39: Fiskur | I39: en-2
A40: 46196 | B40: Álfaberg | C40: Marta | E40: Glúten | G40: Aðalréttur → Kjúklingabollur (fisklaust) | H40: Glúten | I40: en-2
...

Sheet Skóladeildarlisti
A1: Skóli | B1: Deildir (aðskildar með kommu)
A2: Engidalsskóli | B2: 1. bekkur | C2: 2. bekkur | D2: 3. bekkur | E2: 4. bekkur | F2: 5. bekkur | G2: 6. bekkur | H2: 7. bekkur | I2: 8. bekkur | J2: 9. bekkur | K2: 10. bekkur | L2: Einhverfurdeild | M2: Sérdeild | N2: Frístundaheimili | O2: Starfsmaður | P2: Vantar bekk
A3: Hraunvallaskóli | B3: 1. bekkur | C3: 2. bekkur | D3: 3. bekkur | E3: 4. bekkur | F3: 5. bekkur | G3: 6. bekkur | H3: 7. bekkur | I3: 8. bekkur | J3: 9. bekkur | K3: 10. bekkur | L3: Einhverfurdeild | M3: Sérdeild | N3: Frístundaheimili | O3: Starfsmaður | P3: Vantar bekk
