Workbook

Sheet Vöruskrá
A1: VÖRUSKRÁ – HRÁEFNI OG INNIHALDSEFNI
A2: Heiti vöru | B2: Framleiðandi / Byrgi | C2: Vörúnúmer | D2: Vörúflokkur | E2: Innihaldslýsing | F2: Ofnæmisvaldar | G2: Fyrirvari | H2: Hlekkur á gagnablað | I2: Orka (kcal/100g) | J2: Fita (g/100g) | K2: Mettuð fita (g/100g) | L2: Kolvetni (g/100g) | M2: Sykur (g/100g) | N2: Prótein (g/100g) | O2: Salt (g/100g) | P2: Trefjar (g/100g) | Q2: Kostnaður (kr/kg) | R2: Athugasemdir
A3: Ömmu skonsur heilar | B3: Gæðabakstur / Ömmubakstur ehf. | C3: 121 | D3: Bakkelsi | E3: Vatn, **hveiti**, **HAFRAMJÖL**, repjuolía, sykur, **HEILHVEITI**, **egg**, **MYSUDUFT**, pálmaolía, lyftiefni (E450, E500), salt, maltað **hveiti**, mjölmeðhöndlunarefni (E300), rotvarnarefni (E282), sykur, bindiefni (E322 úr sólblómum, E471), dextrósi, bragðefni, rotvarnarefni (E211), sýrustillir (E330), vanillubragðefni, kókosolía, litarefni (E150c, E150a), kekkjarvarnarefni (E535) | F3: Glúten (hveiti, haframjöl), egg, mjólk | G3: Gæti innihaldið snefil af sesam. | H3: https://gaedabakstur.is/vara/ommuskonsur-heilar-10stk-i-pakka/ | I3: 260 | J3: 12 | K3: 1.3 | L3: 31 | M3: 10 | N3: 5.3 | O3: 1 | P3: 2.3
A4: Bananaskonsur | B4: Gæðabakstur / Ömmubakstur ehf. | C4: 122 | D4: Bakkelsi | E4: Hrísmjólk (vatn, hrísgrjón, sólblómaolía, kalsíum, maltextrakt, salt, bindiefni E418, vítamín B12, D2, sýrustillir E340), **hveiti**, vatn, sykur, banani, repjuolía, maltað **hveiti**, mjölmeðhöndlunarefni (E300), lyftiefni (E450, E500), salt, vanillubragðefni, litarefni (E150c), kekkjarvarnarefni (E535) | F4: Glúten (hveiti) | G4: Gæti innihaldið snefil af sesam, mjólk og eggjum. | H4: https://gaedabakstur.is/vara/bananaskonsur/ | I4: 237 | J4: 4.3 | K4: 0.3 | L4: 44 | M4: 16 | N4: 4.4 | O4: 0.4 | P4: 1.5
A5: Sólkjarnabrauð plötubrauð | B5: Gæðabakstur / Ömmubakstur ehf. | C5: 730 | D5: Brauð | E5: **Hveiti**, vatn, 12,3% - sólkjarnafræ, **rúgmjöl**, hörfræ, maltað **hveiti**, salt, maltað **bygg**, mjölmeðhöndlunarefni (E300), ger, malt extrakt (úr **byggi**), súrdeigsduft úr **hveiti** (**hveiti**, gerlar), dextrósi, **hveitiglúten**, bindiefni (E472e, E491), ensím, kekkjarvarnarefni (E535) | F5: Glúten | G5: Gæti innihaldið snefil af sesamfræjum | H5: https://gaedabakstur.is/vara/solkjarnabraud/ | I5: 311 | J5: 10.8 | K5: 1.3 | L5: 40.3 | M5: 1.7 | N5: 10.5 | O5: 1.1 | P5: 4.7
A6: Beyglur fínar KS(48) | B6: Myllan | C6: 3413 | D6: Brauð / Frystar vörur | E6: **hveiti**, vatn, sykur, maltað mjöl (**bygg**, **hveiti**), salt, ger, óvirkt þurrger, ýruefni (E472e), repjuolía, mjölmeðhöndlunarefni (E300), ensím. | F6: Glúten (hveiti, bygg) | G6: Framleitt á svæði þar sem unnið er með sesamfræ, mjólk, egg, lúpínu, soja | H6: https://www.myllan.is/is/vorulinur/frosin-pokkud-vara/beyglur-finar | I6: 257 | J6: 0.9 | K6: 0.2 | L6: 51 | M6: 2.6 | N6: 9.4 | O6: 1.5 | P6: 2.4
A7: Heilkornasamlokubrauð stórt | B7: Myllan | C7: 1036 | D7: Brauð | E7: Vatn, heilkorna **HEILHVEITI** 17%, heilkorna **RÚGMJÖL** 17%, **hveiti**, **HVEITIGLÚTEN**, **HVEITIFLÖGUR**, **RÚGMJÖL**, þurrkað súrdeig (**RÚGUR**, súrdeigsgerlar), **HVEITIKURL**, ger, maltextrakt (**bygg**), repjuolía, salt, þykkingarefni (E415), sýrustillir (E262), ýruefni (E471, E472e), þurrkað súrdeig (**hveiti**, súrdeigsgerlar), mjölmeðhöndlunarefni (E300) | F7: Glúten (hveiti, rúgur, bygg) | G7: Framleitt á svæði þar sem unnið er með sesamfræ, egg, mjólk og lúpínu | H7: https://www.myllan.is/is/vorulinur/samlokubraud/heilkornasamlokubraud-stort | I7: 244 | J7: 2.9 | K7: 0.6 | L7: 37 | M7: 1.6 | N7: 14 | O7: 1 | P7: 6.6
A8: Heimilisbrauð 1/1 | B8: Myllan | C8: 1023 | D8: Brauð | E8: **Hveiti**, vatn, **HVEITIKURL**, repjuolía, ger, salt, **HVEITITREFJAR**, mjölmeðhöndlunarefni (E300), ýruefni (E481) | F8: Glúten (hveiti) | G8: Framleitt á svæði þar sem unnið er með sesamfræ, mjólk, egg og lúpínu | H8: https://www.myllan.is/is/vorulinur/samlokubraud/heimilisbraud-heilt | I8: 250 | J8: 2.7 | K8: 0.4 | L8: 45 | M8: 0.3 | N8: 9 | O8: 1.4 | P8: 3.1
A9: Lífskornabrauð m/ tröllahöfrum og chia | B9: Myllan | C9: 1063 | D9: Brauð | E9: Vatn, **TRÖLLAHAFRAR** 21%, heilkorna **HEILHVEITI** 16%, **hveiti**, **HVEITIGLÚTEN**, **RÚGMJÖL**, þurrkað súrdeig (**RÚGUR**, súrdeigsgerlar), **HVEITIKURL**, ger, chia fræ 1% (Salvia hispanica), maltextrakt (**bygg**), repjuolía, joðbætt salt, þykkingarefni (E415), sýrustillir (E262), ýruefni (E471, E472e), mjölmeðhöndlunarefni (E300) | F9: Glúten (tröllahafrar, heilhveiti, hveiti, rúgur, bygg) | G9: Framleitt á svæði þar sem unnið er með sesamfræ, egg, mjólk og lúpínu | H9: https://www.myllan.is/is/vorulinur/vegan-vorur/lifskorn-trollahafrar-chiafrae | I9: 241 | J9: 4.3 | K9: 0.8 | L9: 33 | M9: 1.2 | N9: 14 | O9: 0.9 | P9: 6.8
A10: Hvítlauksbrauð / baguette | B10: Myllan | C10: 4280 | D10: Brauð / Frystar vörur | E10: Mjöl (**hveiti**, maltað **hveiti**), vatn, smjör (**mjólk**), jurtafita (pálma), jurtaolía (repju), joðbætt salt, ger, hvítlaukur 0,6%, laukduft, ýruefni (E472e, E471, sólblómalesitín), sýrustillir (E341, E450, E330), óvirkt ger, steinselja, salt, þykkingarefni (E412), bragðefni, þráavarnarefni (E300), ensím (alfaamýlasi, xýlanasi) | F10: Glúten (hveiti), mjólk | G10: Getur innihaldið snefil af eggjum, soja, sinnepi og sesamfræjum. | H10: https://drive.google.com/file/d/1ISY9dqVNVBuKMul2k8e0kwwb7vSrJhlW/view | I10: 305 | J10: 14 | K10: 6.4 | L10: 37 | M10: 0.8 | N10: 6.6 | O10: 1.5 | P10: 1.9
A11: Dökkt súrdeigsbrauð (Skanörgrova) | B11: Pågen | C11: 1003 | D11: Brauð | E11: Vatn, **hveiti**mjöl, súrdeig úr **hveiti**korni (13%), heilkorna**hveiti**mjöl, dinkel**hveiti**mjöl, muldir heilkornakjarnar úr dinkel**hveiti**, **hafra**grjón, skolað heilkorna**hafra**mjöl, **hveiti**glúten, heilkorna**rúg**mjöl, heilkorna durum**hveiti**mjöl, **hafra**trefjar, kaldpressuð repjuolía (1%), **hveiti**kímar, gul hörfræ, sykur, ger, malt úr **byggi** og **hveiti**, salt. | F11: Glúten (hveiti, rúg, hafrar, bygg) | H11: https://drive.google.com/file/d/1_xC3btJzq-zmdaQHqlJ0_0EY7KwFaCqs/view | I11: 308 | J11: 7.8 | K11: 0.8 | L11: 48 | M11: 9.1 | N11: 10 | O11: 1.4 | P11: 6
A12: Ljóst súrdeigsbrauð (LantGoda Surdegsbröd) | B12: Pågen | C12: 1004 | D12: Brauð | E12: Vatn, **hveiti**mjöl, súrdeig úr **hveiti** (13%), heilkorna**hveiti**mjöl, dinkel**hveiti**mjöl, muldir heilkornakjarnar úr dinkel**hveiti**, **hafra**grjón, skolað heilkorna**hafra**mjöl, **hveiti**glúten, heilkorna**rúg**mjöl, heilkorna durum**hveiti**mjöl, **hafra**trefjar, kaldpressuð repjuolía (1%), **hveiti**kímar, gul hörfræ, sykur, ger, malt úr **byggi** og **hveiti**, salt. | F12: Glúten (hveiti, rúg, hafrar, bygg) | H12: https://drive.google.com/file/d/1aObopm1C2qlx3QieZ3phPb3MzLNGDVZz/view | I12: 262 | J12: 3 | K12: 0.4 | L12: 45 | M12: 4.1 | N12: 11 | O12: 0.9 | P12: 5
A13: Hrökkbrauð – Spelt (Burger crispbread) | B13: Burger Knäcke GmbH + Co. KG | D13: Hrökkbrauð | E13: Heilkorna**rúg**mjöl, **spelt**flögur (**hveiti**), heilkorna**spelt**mjöl (**hveiti**), salt. | F13: Glúten (rúg, spelt (hveiti)) | G13: Getur innihaldið snefil af sesam, mjólk og öðrum glútentegundum | H13: https://drive.google.com/file/d/1z4yQiAT8epMbEaAPA9lsAZjC7K1VKYth/view | I13: 324 | J13: 1.6 | K13: 0.3 | L13: 59 | M13: 1.8 | N13: 8.6 | O13: 1.3 | P13: 21
A14: Heilhveitikex (HAUST Graham biscuit) | B14: Continental Bakeries North Europe AB | C14: 307242 | D14: Kex / Bakkelsi | E14: **Hveiti**mjöl, heilkorna **hveiti**mjöl 30%, sykur, jurtafita (pálma), lyftiefni (ammoníumkarbónöt, natríumkarbónöt), salt, bragðefni. | F14: Glúten (hveiti) | G14: Getur innihaldið snefil af hnetum og sesam | H14: https://docs.google.com/document/d/1hSm-4pt3r15YYOeuqlWMbkkVgdKc8cwt0qPlCRs1ssM/edit | I14: 478 | J14: 20.8 | K14: 10.5 | L14: 62.4 | M14: 22.7 | N14: 8 | O14: 1.1
A15: Horn / Mini croissant 25g | B15: Boulangerie Neuhauser SA | C15: 401262 | D15: Bakkelsi / Frystar vörur | E15: **Hveiti**mjöl, vatn, **smjör** 18%, ger, sykur, **egg**, salt, **hveiti**glúten, maltað **hveiti**mjöl, óvirkt ger, mjölmeðhöndlunarefni (askorbínsýra E300), ensím. | F15: Glúten (hveiti), mjólk (smjör), egg | H15: https://drive.google.com/file/d/1DNHhTRSDQjq03Ewnj0fn_EU30mAnbK52/view | I15: 308 | J15: 15 | K15: 9.2 | L15: 36 | M15: 5.4 | N15: 6.8 | O15: 1 | P15: 1.4
A16: Arna skyr vanillu | B16: Arna / MS | D16: Mjólkurvörur | E16: **Mjólk**, sykur (5.0%), maíssterkja, vanilluþykkni (0,1%), vanillukorn, sítrónusafi, skyrgerlar, laktasi. | F16: Mjólk | H16: https://drive.google.com/file/d/1yzNdxeJqQSbLVXSF15Oeij4m2PUBv2GA/view | I16: 78 | J16: 0.3 | K16: 0.2 | L16: 7.9 | M16: 7.9 | N16: 11 | O16: 0.1
A17: Heimilis grjónagrautur | B17: Matarstræti | C17: 400208 | D17: Grautar / Kælivörur | E17: **Mjólk**, hrísgrjón(12%), sykur, salt. | F17: Mjólk | H17: https://drive.google.com/file/d/1Q4ZfVecv6vttdWG8fU0WA-1aeEo59cEB/view | I17: 91 | J17: 3 | K17: 1.6 | L17: 14 | M17: 4.6 | N17: 3 | O17: 0.5
A18: Oatly iMat Fraiche (sýrður hafrarjómi) | B18: Oatly | C18: 61529 | D18: Rjómi / Kælivörur | E18: Gerjaður hafragrunnur (vatn, hafrar 10%), repjuolía, fullhertar jurtaolíur (kókos, repju), kartöflusterkja, ýruefni (E472e), bindiefni (E407), sýrur (eplasýra, mjólkursýra), kalsíumkarbónat, kalsíumfosföt. | H18: https://docs.google.com/document/d/1vtp7UoMhU2kAQ80lddgVvUUhOoVTIYypmLZ4XRd5l3E/edit | I18: 177 | J18: 15 | K18: 6.4 | L18: 9.1 | M18: 4.1 | N18: 1 | O18: 0 | P18: 1
A19: Debic Vegan Top (jurtarjómi) | B19: FrieslandCampina / Debic | C19: 1180281 | D19: Rjómi / Kælivörur | E19: Vatn (64%), jurtaolía (29%) (pálmakjarni, pálmi), þurrkað glúkósasíróp (5%), umbreytt sterkja, salt, bindiefni (E339, gellangúmmí), ýruefni (lesitín, E435, E472b), litarefni (karótín), náttúruleg bragðefni. | F19: Engir skráðir | H19: https://drive.google.com/file/d/1VkCiTqPDw5l0voO-OiMPXkFvU-St0eZv/view | I19: 295 | J19: 30 | K19: 25 | L19: 6.2 | N19: 0 | O19: 0.1 | P19: 0
A20: Ali brauðskinka 62% | B20: Síldar og Fiskur ehf. | D20: Kjöt / Kælivörur | E20: Grísakjöt (62%), vatn, kartöflumjöl, **sojaprótein**, salt, þrúgusykur, bindiefni (E451), þráavarnarefni (E301, E330), gerextrakt, þykkingarefni (E410, E407), bragðefni, rotvarnarefni (E270, E250) | F20: Soja | H20: https://docs.google.com/document/d/1tYCZIN-9wdHVdNDDkGYzBt6KHJktVy-txKVoBoCKeKQ/edit | I20: 122 | J20: 5.9 | K20: 2.4 | L20: 3.6 | M20: 1.6 | N20: 13.4 | O20: 2.7
A21: Ali kjúklingapylsur | B21: Síldar og Fiskur ehf. | D21: Kjöt / Kælivörur | E21: Kjúklingakjöt 58%, kjúklingaskinn 24%, vatn, salt, krydd (**sinnep**, hvítlaukur), gerextrakt, bragðefni, rotvarnarefni (E250) | F21: Sinnep | H21: https://drive.google.com/file/d/1YjhRYrqRfXtv7LqVwi1Ut5s0ZlUPbbqk/view | I21: 173 | J21: 13.4 | K21: 4.8 | L21: 0.3 | M21: 0.3 | N21: 13.7 | O21: 2.8
A22: Kjúklingabollur 5 kg | B22: Matfugl ehf. | C22: 174170 | D22: Kjöt / Frystar vörur | E22: Kjúklingaleggjakjöt, kartöflusterkja, vatn, **soja**prótein, salt, þurrkað grænmeti (laukur, hvítlaukur, paprika), bragðefni (**soja**), krydd (**sinnep**), þrúgusykur, **hveiti**prótein, gerextrakt, litarefni (E160c), krydd, ger, repjuolía, fosfat (E450) | F22: Hveiti, soja, sinnep | H22: https://drive.google.com/file/d/1YThV-MnjJNGCpLCeYQojXy09zGYF6MrY/view | I22: 177 | J22: 9 | K22: 1.8 | L22: 7 | M22: 0.9 | N22: 17 | O22: 1.8
A23: Kjúklingaborgarar í cornflakes | B23: Matfugl ehf. | C23: 174311 | D23: Kjöt / Frystar vörur | E23: Kjötfylling (79%) (Kjúklingakjöt (83% af fyllingu), vatn, **soja**prótein, salt, krydd, gerþykkni, laukur), Brauðhjúpur (**hveiti**, maís, vatn, sykur, salt, maltað **bygg** extrakt), repjuolía. | F23: Hveiti, soja, bygg | H23: https://drive.google.com/file/d/1eikdCgUrXnNjx_B4w2fUH_3E5nIrr0Kz/view | I23: 237 | J23: 13 | K23: 4.7 | L23: 14 | M23: 1.1 | N23: 16 | O23: 1.5
A24: kjúklinga Lærakjöt Rodizio | B24: Matfugl ehf. | C24: 171481 | D24: Kjöt / Kælivörur | E24: Úrbeinuð skinnlaus kjúklingalæri (83%), vatn, salt, jurtaolía (repju og palma olía), sykur, mango chutney, ávaxtaþykkni, sýrustillir (E500), krydd reykbragðefni, rotvarnarefni (E262), þráavarnarefni (E320) | H24: https://drive.google.com/file/d/111MXMHumSNCo1SX0OgN5_iw4ol6nI6Y0/view | I24: 206 | J24: 10 | K24: 1.8 | L24: 4 | M24: 3.3 | N24: 25 | O24: 3.2
A25: Kjúklingalæri úrbeinuð | B25: Danpo | C25: 844014 | D25: Kjöt / Frystar vörur | E25: Úrbeinað og skinnlaust kjúklingalæri 80%, vatn 19%, salt, sykur, þráavarnarefni (E331, E301), sýrustillir (E262). | H25: https://drive.google.com/file/d/1GO4O3alIJnHNWfA6fdAD_SVmAdbBm5wZ/view | I25: 137 | J25: 9 | K25: 2.3 | N25: 14 | O25: 0.8
A26: NOL Kindakæfa 200g | B26: Kjarnafæði Norðlenska hf. | C26: 70519 | D26: Kjöt / Kælivörur | E26: Lambakjöt 80%, kjötsoð, laukduft, salt, pipar. | H26: https://docs.google.com/document/d/1LXzsuB69-IC_oRxF1lHfWTuKdnHk4OhCG33dUGHUGSs/edit | I26: 264 | J26: 24 | K26: 12 | L26: 1 | M26: 0 | N26: 11 | O26: 2.1 | P26: 0
A27: Lifrarpylsa án mjólkur, soðin | B27: Kjarnafæði Norðlenska hf. | C27: 59804 | D27: Kjöt / Kælivörur | E27: Lambalifur 32%, lambamör, **RÚGMJÖL**, **HAFRAMJÖL**, vatn, salt. | F27: Glúten (RÚGMJÖL, HAFRAMJÖL) | H27: https://docs.google.com/document/d/1dqgFZjSbMdctBpuTsZ86-uVkLNdvEtPTC6Kh8455--Y/edit | I27: 401 | J27: 32.7 | K27: 16.6 | L27: 15.7 | M27: 0.3 | N27: 10.3 | O27: 1 | P27: 3.8
A28: Ýsa í raspi | B28: Hafið fiskverslun | C28: 1164 | D28: Fiskur / Kælivörur | E28: Ýsa, raspur (**hveiti**, vatn, ger, salt, litarefni (E100, E160b)), hjúpur (**hveiti**, **glúten**, salt, umbreytt **hveiti**sterkja). | F28: Fiskur, hveiti, glúten | H28: https://docs.google.com/document/d/1mrPTXRk_Pt2msU-ckh0eoh4oUCEKrI5g/edit | I28: 125 | J28: 1 | K28: 0.3 | L28: 11 | M28: 0.2 | N28: 18 | O28: 0.7
A29: Fiskibollur án glúten | B29: Norðanfiskur | C29: 9060 | D29: Fiskur / Frystar vörur | E29: **Þorskur**, laukur, kartöflumjöl, umbreytt sterkja, jurtatrefjar, **soja**prótein, laukduft, salt, bindiefni (E451), hvítur pipar repjuolía. | F29: Fiskur, soja | H29: https://drive.google.com/file/d/1su1X4NqQ06JKbPrLHqbYVzuDSI9b-_ZY/view | I29: 125 | J29: 1.3 | K29: 0.1 | L29: 14.2 | M29: 0.7 | N29: 14.1 | O29: 1.4
A30: Anamma Vegan Nuggets Pea | B30: Anamma / Orkla Foods Sweden | C30: 454071477 | D30: Plantabasað / Frystar vörur | E30: Vatn, baunaprótein(17%), repjuolía, glútenlaus raspur (hrísgrjónamjöl, kjúklingabaunamjöl, maíssterkja, salt, dextrósi), hrísgrjónamjöl, maíssterkja, laukur, salt, náttúruleg bragðefni (paprika, kóríander, múskat), bindiefni (metýlsellulósi) | G30: Getur innihaldið snefil af soja | H30: https://docs.google.com/document/d/1hD7vfcvl0f75johYoY3PnnS548AlpCDkNKyTSEnJezk/edit | I30: 256 | J30: 17 | K30: 1.2 | L30: 14 | M30: 0 | N30: 12 | O30: 1.2
A31: BBQ Oumph! (Pulled) | B31: LiveKindly Collective AB | C31: 1407 | D31: Plantabasað / Frystar vörur | E31: Sojaprótein 54,3% (vatn, sojapróteinþykkni), grillsósa 45,7% (vatn, krydd, sykur, salt, karamellaður sykur, tómatur, laukur, hvítlaukur, sinnep, cayennepipar, engifer, steinselja, svartur pipar, sítrónusýra, repjuolía, náttúruleg bragðefni, maltódextrín, umbreytt maíssterkja, bragðefni), tómatpúrra, eplaþykkni, edik, reykbragðefni. | F31: Soja (sojabaunir) | H31: https://drive.google.com/file/d/1ny7Hc5Bb9td7Jjuz8iDeeFNvGw0ASEur/view | I31: 115 | J31: 0.7 | K31: 0.1 | L31: 11 | M31: 9.4 | N31: 14 | O31: 1.5 | P31: 4.7
A32: Asískar grænmetisbollur | B32: Avita | C32: 8808 | D32: Plantabasað / Frystar vörur | E32: Grænmeti (gulrætur, hvítkál, bambus, paprika, svartir sveppir, blaðlaukur, laukur, sykurbaunir) 40,5%, hrísgrjón 35%, repjuolía, kartöfluflögur, baunasterkja, döðlur 3%, sólblómaolía, krydd, salt, sykur, steinselja, kartöflusterkja, bindiefni (hýdroxýprópýl metýlsellulósi) | H32: https://drive.google.com/file/d/1apWuKGpcNAqp6PlmDeLj6QCa3EUrWc9L/view | I32: 182 | J32: 7.5 | K32: 0.8 | L32: 24.7 | M32: 5.3 | N32: 1.9 | O32: 1.4
A33: Falafel bollur Funky Harissa & Grilled Pepper | B33: Salomon FoodWorld | C33: 8530200 | D33: Plantabasað / Frystar vörur | E33: Kjúklingabaunir (33%), kartöflur, **hveiti**mjöl, kjúklingabaunamjöl, vatn, paprika (5%), gulrætur, þurrkaðir tómatar (3%), laukur, piparþykkni, repjuolía, krydd, svart kúmen, hvítlaukur, maísmjöl, salt, chili, kryddþykkni, sýra (sítrónusýra), tómatþykkni, **hveiti**sterkja, kryddjurtir, lyftiefni (dífosföt, natríumkarbónöt) | F33: Glúten (hveiti) | H33: https://drive.google.com/file/d/1Y-R-GvIw5gcBuCYDUT2F0S5nWJRmSJ_/view | I33: 222 | J33: 7.4 | K33: 0.9 | L33: 28 | M33: 3.6 | N33: 7.6 | O33: 1.1 | P33: 6.5
A34: Garden Gourmet Vegan Nuggets | B34: Nestlé Professional | C34: 12608135 | D34: Plantabasað / Frystar vörur | E34: Endurvökvað **hveiti**prótein 40,9% (vatn, **hveiti**prótein 9,7%, **hveiti**mjöl 2,8%), raspur 17% (**hveiti**mjöl, salt, ger, repjuolía, kryddþykkni paprika), vatn, jurtaolíur (repja, sólblómaolía), **hveiti**mjöl, baunaprótein, sýrustillir (buffrað edik), bindiefni (metýlsellulósi), **hveiti**glúten 1,7%, náttúruleg bragðefni, sterkja, sítrustrefjar, salt, bambustrefjar, laukduft, hvítur pipar, **soja**sósa (**sojabaunir**, **hveiti**, salt) | F34: Glúten (hveiti), soja | G34: Getur innihaldið snefil af eggjum. | H34: https://drive.google.com/file/d/1_5EjaAcN-dT9_KQ7b3yra7RJppPeaS/view | I34: 238 | J34: 13.4 | K34: 1.6 | L34: 13.3 | M34: 1.7 | N34: 13.6 | O34: 1.1 | P34: 5.1
A35: Marrakesh pottréttur | B35: Álfasaga ehf. / Móðir Náttúra | C35: 816 | D35: Plantabasað / Frystar vörur | E35: Tómatar, kjúklingabaunir, laukur, gulrætur, sætar kartöflur, eplasafi, blómkál, repjuolía, döðlur, limesafi (inniheldur **SÚLFÍÐ**), paprikamauk, hvítlaukur, salt, kóríander, chilimauk, grænmetiskraftur (salt, pálmaolía, maltodextrín, grænmetisblanda, sykur, krydd), kúmen, engifer, túrmerik, svartur pipar, kanill. | F35: Súlfít, sellerí. | G35: Framleitt á svæði þar sem unnið er með hnetur | H35: https://docs.google.com/document/d/1lFUBZ6JnrNhmfGUHlIWLvOeyf8UZVP0UP7Z3nm8HOlw/edit | I35: 118 | J35: 4.5 | K35: 0.4 | L35: 13.5 | M35: 5.7 | N35: 3.8 | O35: 0.9 | P35: 4
A36: Vegan grjónagrautur | B36: Í-MAT / Matarstund | C36: FH-20260127-01 | D36: Plantabasað / Grautar | E36: Vegan rjómi (vatn, kókoskjarnaolía, pálmaolía, þurrkað glúkósasíróp, umbreytt sterkja, salt, stöðugleikaefni fosfat E339, gellangúmmí, ýruefni lesitín, E435, E472b, litarefni karótín, náttúrulegt bragðefni), vatn, hrísgrjón, sykur, salt. | F36: Engir skráðir | H36: https://drive.google.com/file/d/12DfeqymW1tAoO22_uIYQhTJKAtpxDRqo/view | I36: 74 | J36: 1.6 | K36: 0.3 | L36: 13 | M36: 1.2 | N36: 1.8 | O36: 0.4
A37: Brunoise grænmetisblanda | B37: Ardo | C37: MMB610 | D37: Grænmeti / Frystar vörur | E37: Sellerírót (33%), gulrætur (32%), blaðlaukur (15%), **sellerí** (10%), laukur (10%) | F37: Sellerí | H37: https://drive.google.com/file/d/1GJCXmg1Vj2I1EBYaQMCHQKoAVtxomxaURI/view | I37: 26 | J37: 0.4 | K37: 0.1 | L37: 3.4 | M37: 2.9 | N37: 1 | O37: 0.1 | P37: 2.5
A38: Grænmetisblanda - Country grill | B38: Ardo | C38: ESP_AC187 | D38: Grænmeti / Frystar vörur | E38: Blandað Grænmeti: kartöflur, kúrbítur, eggaldin, laukur, papríka (græn, rauð og gul). Sólblómaolía. | G38: Framleitt á svæði þar sem unnið er með sellerí. | H38: https://drive.google.com/file/d/1yXrneQvgPYgKej8AvDXUQiRbl8MHsviy/view | I38: 99 | J38: 6 | K38: 0.8 | L38: 8.3 | M38: 3.9 | N38: 1.8 | O38: 0.1 | P38: 2.5
A39: Franskar Mydibel Classic 9/9 | B39: Clarebout Potatoes | D39: Kartöflur / Frystar vörur | E39: Kartöflur 97%, sólblómaolía 3%. Vinnsluhjálparefni (dextrósi, tvínatríumdífosfat). | H39: https://drive.google.com/file/d/1NTqzKXREB617l_w7DuQp8ELURiDGn_ti/view | I39: 120 | J39: 2.7 | K39: 0.4 | L39: 22.9 | N39: 2.2 | O39: 0.1 | P39: 2.6
A40: Kartöflubátar (Potato Wedges) | B40: Mydibel | D40: Kartöflur / Frystar vörur | E40: Kartöflur 97%, sólblómaolía. | H40: https://vefverslun.ojk-isam.is/api/BlobForward/inline/ojkisam/189951b7.pdf | I40: 130 | J40: 3.8 | K40: 2.1 | L40: 20 | N40: 2.7 | O40: 0.1 | P40: 2.7
...

Sheet Réttabanki
A1: RÉTTABANKI – UPPSKRIFTIR OG KOSTNAÐUR
A2: Heiti réttar | B2: Framleiðandi / Byrgi | C2: Framleiðslunúmer | D2: Athugasemd | E2: Vara 1 | F2: Magn 1 (g) | G2: Vara 2 | H2: Magn 2 (g) | I2: Vara 3 | J2: Magn 3 (g) | K2: Vara 4 | L2: Magn 4 (g) | M2: Vara 5 | N2: Magn 5 (g) | O2: Vara 6 | P2: Magn 6 (g) | Q2: Vara 7 | R2: Magn 7 (g) | S2: Vara 8 | T2: Magn 8 (g) | U2: Vara 9 | V2: Magn 9 (g) | W2: Vara 10 | X2: Magn 10 (g) | Y2: Vara 11 | Z2: Magn 11 (g) | AA2: Vara 12 | AB2: Magn 12 (g) | AC2: Vara 13 | AD2: Magn 13 (g) | AE2: Vara 14 | AF2: Magn 14 (g) | AG2: Vara 15 | AH2: Magn 15 (g) | AI2: Vara 16 | AJ2: Magn 16 (g) | AK2: Vara 17 | AL2: Magn 17 (g) | AM2: Vara 18 | AN2: Magn 18 (g) | AO2: Vara 19 | AP2: Magn 19 (g) | AQ2: Vara 20 | AR2: Magn 20 (g) | AS2: Innihaldslýsing (sjálfvirkt) | AT2: Ofnæmisvaldar (sjálfvirkt) | AU2: Fyrirvari (sjálfvirkt) | AV2: Orka (kcal/100g) | AW2: Fita (g/100g) | AX2: Mettuð fita (g/100g) | AY2: Kolvetni (g/100g) | AZ2: Sykur (g/100g) | BA2: Prótein (g/100g) | BB2: Salt (g/100g) | BC2: Trefjar (g/100g) | BD2: Kostnaður (kr/skammt)
A3: Pasta með kjötbollum í mildri tómatsósu | B3: Í-Mat / Matarstund | D3: Pastahlutfall 40%, sósa og kjötbollur 60% | E3: Forsoðið pasta – Ójk - Ísam | F3: 40000 | G3: Skólabollur, Kjöt og grænmeti – Kjarnafæði Norðlenska hf. | H3: 25000 | I3: Tómatpuré Doppio Concentrato 800 g (Menu) – Menu SRL | J3: 18000 | K3: Laukur (ferskur) | L3: 5000 | M3: Gulrætur (ferskar) | N3: 3000 | O3: Vatn | P3: 4000 | Q3: Crystal Sugar (Sykur) – Cosun Beet Company | R3: 300 | S3: Oregano – Nordic Spice AB | T3: 80 | U3: Svartur pipar, malaður – Nordic Spice AB | V3: 40 | W3: Borðsalt – Katla matvælaiðja ehf. | X3: 800 | AV3: 152.5 | AW3: 4.6 | AX3: 1.6 | AY3: 25.9 | AZ3: 4.4 | BA3: 7.8
A4: Lambakjötspottréttur með kartöflum | B4: Matarstund | C4: LP-100KG-20260529 | D4: 100 kg uppskrift | E4: Lambakjöt teningar | F4: 35000 | G4: Kartöflur (ferskar) | H4: 30000 | I4: Gulrætur (ferskar) | J4: 10000 | K4: Laukur (ferskur) | L4: 8000 | M4: Tómatpuré Doppio Concentrato 800 g (Menu) – Menu SRL | N4: 2500 | O4: Repjuolía | P4: 1500 | Q4: Kjúklingakraftur Vegan (Essential Cuisine) – Essential Cuisine Ltd. | R4: 1200 | S4: Hvítlauksduft (Vitlökspulver) – Nordic Spice AB | T4: 400 | U4: Maizenamjöl (majssterkja) – Maizena / Unilever | V4: 1200 | W4: Borðsalt – Katla matvælaiðja ehf. | X4: 600 | Y4: Svartur pipar, malaður – Nordic Spice AB | Z4: 80 | AA4: Vatn | AB4: 7350 | AV4: 121.9 | AW4: 6.5 | AX4: 2.4 | AY4: 9.1 | AZ4: 2.3 | BA4: 7.2
A5: Mildur kjúklingakarrýréttur | B5: Matarstund | C5: MK-100KG-20260529 | D5: 100 kg uppskrift. Glútenfrítt ef kraftur og karrýblanda eru glútenlaus. | E5: Kjúklingalæri úrbeinuð – Danpo | F5: 35000 | G5: Hrísgrjón Thai Hom Mali (Royal Umbrella) – Khao C.P. Co., Ltd. | H5: 18000 | I5: Forsteiktur laukur (Pre-fried sliced onions) – Ardo Violaines SAS | J5: 8000 | K5: Gulrætur (ferskar) | L5: 8000 | M5: Kókosmjólk Roland Coconut Milk – Roland Foods LLC | N5: 12000 | O5: Kjúklingakraftur Vegan (Essential Cuisine) – Essential Cuisine Ltd. | P5: 1200 | Q5: Hvítlauksduft (Vitlökspulver) – Nordic Spice AB | R5: 500 | S5: Maizenamjöl (majssterkja) – Maizena / Unilever | T5: 1000 | U5: Borðsalt – Katla matvælaiðja ehf. | V5: 600 | W5: Svartur pipar, malaður – Nordic Spice AB | X5: 100 | Y5: Vatn | Z5: 7600 | AV5: 106.7 | AW5: 7.6 | AX5: 2.8 | AY5: 4.6 | AZ5: 2.2 | BA5: 5.8
A6: Mild tikka masala með kjúklingi | B6: Matarstund | C6: TMK-100KG-20260529 | D6: 100 kg uppskrift. Ofnæmisvaldur: SINNEP. | E6: Kjúklingalæri úrbeinuð – Danpo | F6: 70000 | G6: Sauce tikka masala GT-CHEF – GoldenTurtleForChefs (ZLI) | H6: 18000 | I6: Kókosmjólk Roland Coconut Milk – Roland Foods LLC | J6: 6000 | K6: Brunoise grænmetisblanda – Ardo | L6: 2000 | M6: Tómatpuré Doppio Concentrato 800 g (Menu) – Menu SRL | N6: 1500 | O6: Hvítlaukur í olíu (Crushed garlic) – APPETIT Levnedsmidler A/S / Wiik & Co. | P6: 500 | Q6: Borðsalt – Katla matvælaiðja ehf. | R6: 200 | S6: Crystal Sugar (Sykur) – Cosun Beet Company | T6: 100 | U6: Vatn | V6: 600 | AV6: 145.9 | AW6: 9.4 | AX6: 2.7 | AY6: 4.8 | AZ6: 3.7 | BA6: 10.3
A7: Kjúklingasúpa með núðlum og grænmeti | B7: Matarstund | C7: KSN-100KG-20260529 | D7: 100 kg uppskrift. Glúten inniheldur núðlur. | E7: Kjúklingalæri úrbeinuð – Danpo | F7: 25000 | G7: Núðlur (eggjanuðlur) | H7: 12000 | I7: Vatn | J7: 45000 | K7: Kjúklingakraftur Vegan (Essential Cuisine) – Essential Cuisine Ltd. | L7: 5000 | M7: Gulrætur (ferskar) | N7: 5000 | O7: Laukur (ferskur) | P7: 3000 | Q7: Blaðlaukur (ferskur) | R7: 2000 | S7: Sellerí (ferskt) | T7: 1000 | U7: Hvítlauksduft (Vitlökspulver) – Nordic Spice AB | V7: 500 | W7: Borðsalt – Katla matvælaiðja ehf. | X7: 400 | Y7: Svartur pipar, malaður – Nordic Spice AB | Z7: 300 | AV7: 61.2 | AW7: 2.9 | AX7: 0.6 | AY7: 4.7 | AZ7: 2.5 | BA7: 4.5
A8: Pastagratín með osti og grænmeti | B8: Matarstund | C8: POG-100KG-20260529 | D8: 100 kg uppskrift. Inniheldur glúten og mjólk. | E8: Forsoðið pasta – Ójk - Ísam | F8: 35000 | G8: Rifinn ostur – Pizzatopping mozzarella (Ulkjær) – Natan - Arla Foods / Ulkjær | H8: 18000 | I8: Nýmjólk 1 L (MS) – MS / Mjólkursamsalan | J8: 20000 | K8: Gulrætur sneiðar – Ardo | L8: 4000 | M8: Laukur (ferskur) | N8: 2000 | O8: Maizenamjöl (majssterkja) – Maizena / Unilever | P8: 1200 | Q8: Borðsalt – Katla matvælaiðja ehf. | R8: 400 | S8: Svartur pipar, malaður – Nordic Spice AB | T8: 200 | AV8: 136.5 | AW8: 5.3 | AX8: 2.8 | AY8: 18 | AZ8: 2.4 | BA8: 4.3
A9: Vegan mexicosúpa | B9: Matarstund | C9: FH-MEX-100KG-01 | D9: 100 kg uppskrift | E9: Tómatsúpugrunnur (Oscar) – Oscar A/S | F9: 5500 | G9: Paprikuteningar litblandir – Ardo | H9: 2500 | I9: Forsteiktur laukur (Pre-fried sliced onions) – Ardo Violaines SAS | J9: 2000 | K9: Fennel frosinn (Diced Fennel) – Ardo | L9: 1250 | M9: Kjúklingakraftur Vegan (Essential Cuisine) – Essential Cuisine Ltd. | N9: 5000 | O9: Hvítlaukur í olíu (Crushed garlic) – APPETIT Levnedsmidler A/S / Wiik & Co. | P9: 400 | Q9: Borðsalt – Katla matvælaiðja ehf. | R9: 500 | S9: Svartur pipar, malaður – Nordic Spice AB | T9: 50 | U9: Country Grill grænmetisblanda – Ardo | V9: 9000 | W9: Vatn | X9: 64526 | Y9: Violife Grated Mozzarella Flavour – Arivia S.A. | Z9: 1000 | AA9: Oatly iMat Fraiche (sýrður hafrarjómi) – Oatly | AB9: 1000 | AV9: 62.7 | AW9: 2.9 | AX9: 1.1 | AY9: 7.5 | AZ9: 3.8 | BA9: 1.4
A10: Mac and Cheese | B10: Matarstund | C10: FH-MAC-100KG-01 | D10: 100 kg uppskrift. Inniheldur glúten, mjólk og sinnep. | E10: Gomiti / Macaroni pasta – Garri | F10: 25000 | G10: Nýmjólk 1 L (MS) – MS / Mjólkursamsalan | H10: 23125 | I10: Smjör 500 g – MS (Mjólkursamsalan Íslands) | J10: 3125 | K10: Laukur (ferskur) | L10: 2500 | M10: Country Grill grænmetisblanda – Ardo | N10: 3750 | O10: Rustic gulrætur frosnar – Ardo | P10: 2500 | Q10: Borðsalt – Katla matvælaiðja ehf. | R10: 375 | S10: Svartur pipar, malaður – Nordic Spice AB | T10: 50 | U10: Vatn | V10: 1500 | AV10: 130.6 | AW10: 3.1 | AX10: 1.6 | AY10: 19.8 | AZ10: 2.2 | BA10: 5.4
A11: Plokkfiskur (vegan) | B11: Matarstund | C11: PLK-100KG-20260529 | D11: Glúten-, mjólkur-, hnetu-, soja- og eggjalaus útgáfa. Ofnæmisvaldar: Fiskur og súlfít. | E11: Ýsa nætursöltuð – Hafið fiskverslun | F11: 40000 | G11: Kartöflur (ferskar) | H11: 36000 | I11: Laukur (ferskur) | J11: 4500 | K11: Debic Vegan Top (jurtarjómi) – FrieslandCampina / Debic | L11: 10000 | M11: Vatn | N11: 5000 | O11: Maizenamjöl (majssterkja) – Maizena / Unilever | P11: 1800 | Q11: Borðsalt – Katla matvælaiðja ehf. | R11: 450 | S11: Svartur pipar, malaður – Nordic Spice AB | T11: 50 | AV11: 68.2 | AW11: 3.9 | AX11: 2.6 | AY11: 8.1 | AZ11: 1 | BA11: 0.8

Sheet Grunnmatseðill
A1: GRUNNMATSEÐILL
A2: Dagsetning | B2: Dagur (sjálfvirkt) | C2: Vika (sjálfvirkt) | D2: Gildir fyrir | E2: Máltíðartegund | F2: Tegund (Vara/Réttur) | G2: Vara / Réttur | H2: Birtingarlýsing (vefur) | I2: Skammtur Leikskóli (g) | J2: Skammtur Grunnskóli (g) | K2: Kostnaður (kr/skammt) | L2: Innihaldslýsing (sjálfvirkt) | M2: Ofnæmisvaldar (sjálfvirkt) | N2: Fyrirvari (sjálfvirkt) | O2: Orka (kcal) | P2: Fita (g) | Q2: Prótein (g)
A3: 46140 | B3: =IF(A3<>"",CHOOSE(WEEKDAY(A3,2),"Mánudagur","Þriðjudagur","Miðvikudagur","Fimmtudagur","Föstudagur","Laugardagur","Sunnudagur"),"") -> Þriðjudagur | C3: =IF(A3<>"",WEEKNUM(A3,21),"") -> 18 | D3: Bæði | E3: Ávaxtastund | H3: Ferskir ávextir alla daga. | L3: =IF(OR(F3 = "", G3 = ""), "", IF(F3 = "Vara", IFERROR(_xlfn.SINGLE(_xlfn.XLOOKUP(G3, Vöruskrá!A:A, Vöruskrá!E:E, "")), ""), IF(F3 = "Réttur", IFERROR(_xlfn.SINGLE(_xlfn.XLOOKUP(G3, Réttabanki!A:A, Réttabanki!AS:AS, "")), ""), ""))) | M3: =IF(OR(F3 = "", G3 = ""), "", IF(F3 = "Vara", IFERROR(_xlfn.SINGLE(_xlfn.XLOOKUP(G3, Vöruskrá!A:A, Vöruskrá!F:F, "")), ""), IF(F3 = "Réttur", IFERROR(_xlfn.SINGLE(_xlfn.XLOOKUP(G3, Réttabanki!A:A, Réttabanki!AT:AT, "")), ""), ""))) | N3: =IF(OR(F3 = "", G3 = ""), "", IF(F3 = "Vara", IFERROR(_xlfn.SINGLE(_xlfn.XLOOKUP(G3, Vöruskrá!A:A, Vöruskrá!G:G, "")), ""), IF(F3 = "Réttur", IFERROR(_xlfn.SINGLE(_xlfn.XLOOKUP(G3, Réttabanki!A:A, Réttabanki!AU:AU, "")), ""), ""))) | O3: =IF(OR(F3 = "", G3 = "", I3 = ""), "", IF(F3 = "Vara", IFERROR(_xlfn.SINGLE(_xlfn.XLOOKUP(G3, Vöruskrá!A:A, Vöruskrá!I:I, "")) * I3 / 100, ""), IF(F3 = "Réttur", IFERROR(_xlfn.SINGLE(_xlfn.XLOOKUP(G3, Réttabanki!A:A, Réttabanki!AV:AV, "")) * I3 / 100, ""), ""))) | P3: =IF(OR(F3 = "", G3 = "", I3 = ""), "", IF(F3 = "Vara", IFERROR(_xlfn.SINGLE(_xlfn.XLOOKUP(G3, Vöruskrá!A:A, Vöruskrá!J:J, "")) * I3 / 100, ""), IF(F3 = "Réttur", IFERROR(_xlfn.SINGLE(_xlfn.XLOOKUP(G3, Réttabanki!A:A, Réttabanki!AW:AW, "")) * I3 / 100, ""), ""))) | Q3: =IF(OR(F3 = "", G3 = "", I3 = ""), "", IF(F3 = "Vara", IFERROR(_xlfn.SINGLE(_xlfn.XLOOKUP(G3, Vöruskrá!A:A, Vöruskrá!N:N, "")) * I3 / 100, ""), IF(F3 = "Réttur", IFERROR(_xlfn.SINGLE(_xlfn.XLOOKUP(G3, Réttabanki!A:A, Réttabanki!BB:BB, "")) * I3 / 100, ""), "")))
B4: =IF(A4<>"",CHOOSE(WEEKDAY(A4,2),"Mánudagur","Þriðjudagur","Miðvikudagur","Fimmtudagur","Föstudagur","Laugardagur","Sunnudagur"),IF(B3<>"",B3,"")) -> Þriðjudagur | C4: =IF(A4<>"",WEEKNUM(A4,21),IF(C3<>"",C3,"")) -> 18 | D4: Bæði | E4: Ávaxtastund | F4: Vara | G4: Epli – Meðaltal af netinu | H4: Epli | I4: 100 | J4: 120 | L4: =IF(OR(F4 = "", G4 = ""), "", IF(F4 = "Vara", IFERROR(_xlfn.SINGLE(_xlfn.XLOOKUP(G4, Vöruskrá!A:A, Vöruskrá!E:E, "")), ""), IF(F4 = "Réttur", IFERROR(_xlfn.SINGLE(_xlfn.XLOOKUP(G4, Réttabanki!A:A, Réttabanki!AS:AS, "")), ""), ""))) | M4: =IF(OR(F4 = "", G4 = ""), "", IF(F4 = "Vara", IFERROR(_xlfn.SINGLE(_xlfn.XLOOKUP(G4, Vöruskrá!A:A, Vöruskrá!F:F, "")), ""), IF(F4 = "Réttur", IFERROR(_xlfn.SINGLE(_xlfn.XLOOKUP(G4, Réttabanki!A:A, Réttabanki!AT:AT, "")), ""), ""))) | N4: =IF(OR(F4 = "", G4 = ""), "", IF(F4 = "Vara", IFERROR(_xlfn.SINGLE(_xlfn.XLOOKUP(G4, Vöruskrá!A:A, Vöruskrá!G:G, "")), ""), IF(F4 = "Réttur", IFERROR(_xlfn.SINGLE(_xlfn.XLOOKUP(G4, Réttabanki!A:A, Réttabanki!AU:AU, "")), ""), ""))) | O4: =IF(OR(F4 = "", G4 = "", I4 = ""), "", IF(F4 = "Vara", IFERROR(_xlfn.SINGLE(_xlfn.XLOOKUP(G4, Vöruskrá!A:A, Vöruskrá!I:I, "")) * I4 / 100, ""), IF(F4 = "Réttur", IFERROR(_xlfn.SINGLE(_xlfn.XLOOKUP(G4, Réttabanki!A:A, Réttabanki!AV:AV, "")) * I4 / 100, ""), ""))) | P4: =IF(OR(F4 = "", G4 = "", I4 = ""), "", IF(F4 = "Vara", IFERROR(_xlfn.SINGLE(_xlfn.XLOOKUP(G4, Vöruskrá!A:A, Vöruskrá!J:J, "")) * I4 / 100, ""), IF(F4 = "Réttur", IFERROR(_xlfn.SINGLE(_xlfn.XLOOKUP(G4, Réttabanki!A:A, Réttabanki!AW:AW, "")) * I4 / 100, ""), ""))) | Q4: =IF(OR(F4 = "", G4 = "", I4 = ""), "", IF(F4 = "Vara", IFERROR(_xlfn.SINGLE(_xlfn.XLOOKUP(G4, Vöruskrá!A:A, Vöruskrá!N:N, "")) * I4 / 100, ""), IF(F4 = "Réttur", IFERROR(_xlfn.SINGLE(_xlfn.XLOOKUP(G4, Réttabanki!A:A, Réttabanki!BB:BB, "")) * I4 / 100, ""), "")))
B5: =IF(A5<>"",CHOOSE(WEEKDAY(A5,2),"Mánudagur","Þriðjudagur","Miðvikudagur","Fimmtudagur","Föstudagur","Laugardagur","Sunnudagur"),IF(B4<>"",B4,"")) -> Þriðjudagur | C5: =IF(A5<>"",WEEKNUM(A5,21),IF(C4<>"",C4,"")) -> 18 | D5: Bæði | E5: Ávaxtastund | F5: Vara | G5: Banani – Meðaltal af netinu | H5: Banani | I5: 100 | J5: 120 | L5: =IF(OR(F5 = "", G5 = ""), "", IF(F5 = "Vara", IFERROR(_xlfn.SINGLE(_xlfn.XLOOKUP(G5, Vöruskrá!A:A, Vöruskrá!E:E, "")), ""), IF(F5 = "Réttur", IFERROR(_xlfn.SINGLE(_xlfn.XLOOKUP(G5, Réttabanki!A:A, Réttabanki!AS:AS, "")), ""), ""))) | M5: =IF(OR(F5 = "", G5 = ""), "", IF(F5 = "Vara", IFERROR(_xlfn.SINGLE(_xlfn.XLOOKUP(G5, Vöruskrá!A:A, Vöruskrá!F:F, "")), ""), IF(F5 = "Réttur", IFERROR(_xlfn.SINGLE(_xlfn.XLOOKUP(G5, Réttabanki!A:A, Réttabanki!AT:AT, "")), ""), ""))) | N5: =IF(OR(F5 = "", G5 = ""), "", IF(F5 = "Vara", IFERROR(_xlfn.SINGLE(_xlfn.XLOOKUP(G5, Vöruskrá!A:A, Vöruskrá!G:G, "")), ""), IF(F5 = "Réttur", IFERROR(_xlfn.SINGLE(_xlfn.XLOOKUP(G5, Réttabanki!A:A, Réttabanki!AU:AU, "")), ""), ""))) | O5: =IF(OR(F5 = "", G5 = "", I5 = ""), "", IF(F5 = "Vara", IFERROR(_xlfn.SINGLE(_xlfn.XLOOKUP(G5, Vöruskrá!A:A, Vöruskrá!I:I, "")) * I5 / 100, ""), IF(F5 = "Réttur", IFERROR(_xlfn.SINGLE(_xlfn.XLOOKUP(G5, Réttabanki!A:A, Réttabanki!AV:AV, "")) * I5 / 100, ""), ""))) | P5: =IF(OR(F5 = "", G5 = "", I5 = ""), "", IF(F5 = "Vara", IFERROR(_xlfn.SINGLE(_xlfn.XLOOKUP(G5, Vöruskrá!A:A, Vöruskrá!J:J, "")) * I5 / 100, ""), IF(F5 = "Réttur", IFERROR(_xlfn.SINGLE(_xlfn.XLOOKUP(G5, Réttabanki!A:A, Réttabanki!AW:AW, "")) * I5 / 100, ""), ""))) | Q5: =IF(OR(F5 = "", G5 = "", I5 = ""), "", IF(F5 = "Vara", IFERROR(_xlfn.SINGLE(_xlfn.XLOOKUP(G5, Vöruskrá!A:A, Vöruskrá!N:N, "")) * I5 / 100, ""), IF(F5 = "Réttur", IFERROR(_xlfn.SINGLE(_xlfn.XLOOKUP(G5, Réttabanki!A:A, Réttabanki!BB:BB, "")) * I5 / 100, ""), "")))
B6: =IF(A6<>"",CHOOSE(WEEKDAY(A6,2),"Mánudagur","Þriðjudagur","Miðvikudagur","Fimmtudagur","Föstudagur","Laugardagur","Sunnudagur"),IF(B5<>"",B5,"")) -> Þriðjudagur | C6: =IF(A6<>"",WEEKNUM(A6,21),IF(C5<>"",C5,"")) -> 18 | D6: Bæði | E6: Ávaxtastund | F6: Vara | G6: Pera – Meðaltal af netinu | H6: Pera | I6: 100 | J6: 120 | L6: =IF(OR(F6 = "", G6 = ""), "", IF(F6 = "Vara", IFERROR(_xlfn.SINGLE(_xlfn.XLOOKUP(G6, Vöruskrá!A:A, Vöruskrá!E:E, "")), ""), IF(F6 = "Réttur", IFERROR(_xlfn.SINGLE(_xlfn.XLOOKUP(G6, Réttabanki!A:A, Réttabanki!AS:AS, "")), ""), ""))) | M6: =IF(OR(F6 = "", G6 = ""), "", IF(F6 = "Vara", IFERROR(_xlfn.SINGLE(_xlfn.XLOOKUP(G6, Vöruskrá!A:A, Vöruskrá!F:F, "")), ""), IF(F6 = "Réttur", IFERROR(_xlfn.SINGLE(_xlfn.XLOOKUP(G6, Réttabanki!A:A, Réttabanki!AT:AT, "")), ""), ""))) | N6: =IF(OR(F6 = "", G6 = ""), "", IF(F6 = "Vara", IFERROR(_xlfn.SINGLE(_xlfn.XLOOKUP(G6, Vöruskrá!A:A, Vöruskrá!G:G, "")), ""), IF(F6 = "Réttur", IFERROR(_xlfn.SINGLE(_xlfn.XLOOKUP(G6, Réttabanki!A:A, Réttabanki!AU:AU, "")), ""), ""))) | O6: =IF(OR(F6 = "", G6 = "", I6 = ""), "", IF(F6 = "Vara", IFERROR(_xlfn.SINGLE(_xlfn.XLOOKUP(G6, Vöruskrá!A:A, Vöruskrá!I:I, "")) * I6 / 100, ""), IF(F6 = "Réttur", IFERROR(_xlfn.SINGLE(_xlfn.XLOOKUP(G6, Réttabanki!A:A, Réttabanki!AV:AV, "")) * I6 / 100, ""), ""))) | P6: =IF(OR(F6 = "", G6 = "", I6 = ""), "", IF(F6 = "Vara", IFERROR(_xlfn.SINGLE(_xlfn.XLOOKUP(G6, Vöruskrá!A:A, Vöruskrá!J:J, "")) * I6 / 100, ""), IF(F6 = "Réttur", IFERROR(_xlfn.SINGLE(_xlfn.XLOOKUP(G6, Réttabanki!A:A, Réttabanki!AW:AW, "")) * I6 / 100, ""), ""))) | Q6: =IF(OR(F6 = "", G6 = "", I6 = ""), "", IF(F6 = "Vara", IFERROR(_xlfn.SINGLE(_xlfn.XLOOKUP(G6, Vöruskrá!A:A, Vöruskrá!N:N, "")) * I6 / 100, ""), IF(F6 = "Réttur", IFERROR(_xlfn.SINGLE(_xlfn.XLOOKUP(G6, Réttabanki!A:A, Réttabanki!BB:BB, "")) * I6 / 100, ""), "")))
B7: =IF(A7<>"",CHOOSE(WEEKDAY(A7,2),"Mánudagur","Þriðjudagur","Miðvikudagur","Fimmtudagur","Föstudagur","Laugardagur","Sunnudagur"),IF(B6<>"",B6,"")) -> Þriðjudagur | C7: =IF(A7<>"",WEEKNUM(A7,21),IF(C6<>"",C6,"")) -> 18 | D7: Bæði | E7: Ávaxtastund | F7: Vara | G7: Vatnsmelóna – Meðaltal af netinu | H7: Vatnsmelóna | I7: 100 | J7: 120 | L7: =IF(OR(F7 = "", G7 = ""), "", IF(F7 = "Vara", IFERROR(_xlfn.SINGLE(_xlfn.XLOOKUP(G7, Vöruskrá!A:A, Vöruskrá!E:E, "")), ""), IF(F7 = "Réttur", IFERROR(_xlfn.SINGLE(_xlfn.XLOOKUP(G7, Réttabanki!A:A, Réttabanki!AS:AS, "")), ""), ""))) | M7: =IF(OR(F7 = "", G7 = ""), "", IF(F7 = "Vara", IFERROR(_xlfn.SINGLE(_xlfn.XLOOKUP(G7, Vöruskrá!A:A, Vöruskrá!F:F, "")), ""), IF(F7 = "Réttur", IFERROR(_xlfn.SINGLE(_xlfn.XLOOKUP(G7, Réttabanki!A:A, Réttabanki!AT:AT, "")), ""), ""))) | N7: =IF(OR(F7 = "", G7 = ""), "", IF(F7 = "Vara", IFERROR(_xlfn.SINGLE(_xlfn.XLOOKUP(G7, Vöruskrá!A:A, Vöruskrá!G:G, "")), ""), IF(F7 = "Réttur", IFERROR(_xlfn.SINGLE(_xlfn.XLOOKUP(G7, Réttabanki!A:A, Réttabanki!AU:AU, "")), ""), ""))) | O7: =IF(OR(F7 = "", G7 = "", I7 = ""), "", IF(F7 = "Vara", IFERROR(_xlfn.SINGLE(_xlfn.XLOOKUP(G7, Vöruskrá!A:A, Vöruskrá!I:I, "")) * I7 / 100, ""), IF(F7 = "Réttur", IFERROR(_xlfn.SINGLE(_xlfn.XLOOKUP(G7, Réttabanki!A:A, Réttabanki!AV:AV, "")) * I7 / 100, ""), ""))) | P7: =IF(OR(F7 = "", G7 = "", I7 = ""), "", IF(F7 = "Vara", IFERROR(_xlfn.SINGLE(_xlfn.XLOOKUP(G7, Vöruskrá!A:A, Vöruskrá!J:J, "")) * I7 / 100, ""), IF(F7 = "Réttur", IFERROR(_xlfn.SINGLE(_xlfn.XLOOKUP(G7, Réttabanki!A:A, Réttabanki!AW:AW, "")) * I7 / 100, ""), ""))) | Q7: =IF(OR(F7 = "", G7 = "", I7 = ""), "", IF(F7 = "Vara", IFERROR(_xlfn.SINGLE(_xlfn.XLOOKUP(G7, Vöruskrá!A:A, Vöruskrá!N:N, "")) * I7 / 100, ""), IF(F7 = "Réttur", IFERROR(_xlfn.SINGLE(_xlfn.XLOOKUP(G7, Réttabanki!A:A, Réttabanki!BB:BB, "")) * I7 / 100, ""), "")))
B8: =IF(A8<>"",CHOOSE(WEEKDAY(A8,2),"Mánudagur","Þriðjudagur","Miðvikudagur","Fimmtudagur","Föstudagur","Laugardagur","Sunnudagur"),IF(B7<>"",B7,"")) -> Þriðjudagur | C8: =IF(A8<>"",WEEKNUM(A8,21),IF(C7<>"",C7,"")) -> 18 | D8: Bæði | E8: Ávaxtastund | F8: Vara | G8: Appelsína – Meðaltal af netinu | H8: Appelsína | I8: 100 | J8: 120 | L8: =IF(OR(F8 = "", G8 = ""), "", IF(F8 = "Vara", IFERROR(_xlfn.SINGLE(_xlfn.XLOOKUP(G8, Vöruskrá!A:A, Vöruskrá!E:E, "")), ""), IF(F8 = "Réttur", IFERROR(_xlfn.SINGLE(_xlfn.XLOOKUP(G8, Réttabanki!A:A, Réttabanki!AS:AS, "")), ""), ""))) | M8: =IF(OR(F8 = "", G8 = ""), "", IF(F8 = "Vara", IFERROR(_xlfn.SINGLE(_xlfn.XLOOKUP(G8, Vöruskrá!A:A, Vöruskrá!F:F, "")), ""), IF(F8 = "Réttur", IFERROR(_xlfn.SINGLE(_xlfn.XLOOKUP(G8, Réttabanki!A:A, Réttabanki!AT:AT, "")), ""), ""))) | N8: =IF(OR(F8 = "", G8 = ""), "", IF(F8 = "Vara", IFERROR(_xlfn.SINGLE(_xlfn.XLOOKUP(G8, Vöruskrá!A:A, Vöruskrá!G:G, "")), ""), IF(F8 = "Réttur", IFERROR(_xlfn.SINGLE(_xlfn.XLOOKUP(G8, Réttabanki!A:A, Réttabanki!AU:AU, "")), ""), ""))) | O8: =IF(OR(F8 = "", G8 = "", I8 = ""), "", IF(F8 = "Vara", IFERROR(_xlfn.SINGLE(_xlfn.XLOOKUP(G8, Vöruskrá!A:A, Vöruskrá!I:I, "")) * I8 / 100, ""), IF(F8 = "Réttur", IFERROR(_xlfn.SINGLE(_xlfn.XLOOKUP(G8, Réttabanki!A:A, Réttabanki!AV:AV, "")) * I8 / 100, ""), ""))) | P8: =IF(OR(F8 = "", G8 = "", I8 = ""), "", IF(F8 = "Vara", IFERROR(_xlfn.SINGLE(_xlfn.XLOOKUP(G8, Vöruskrá!A:A, Vöruskrá!J:J, "")) * I8 / 100, ""), IF(F8 = "Réttur", IFERROR(_xlfn.SINGLE(_xlfn.XLOOKUP(G8, Réttabanki!A:A, Réttabanki!AW:AW, "")) * I8 / 100, ""), ""))) | Q8: =IF(OR(F8 = "", G8 = "", I8 = ""), "", IF(F8 = "Vara", IFERROR(_xlfn.SINGLE(_xlfn.XLOOKUP(G8, Vöruskrá!A:A, Vöruskrá!N:N, "")) * I8 / 100, ""), IF(F8 = "Réttur", IFERROR(_xlfn.SINGLE(_xlfn.XLOOKUP(G8, Réttabanki!A:A, Réttabanki!BB:BB, "")) * I8 / 100, ""), "")))
B9: =IF(A9<>"",CHOOSE(WEEKDAY(A9,2),"Mánudagur","Þriðjudagur","Miðvikudagur","Fimmtudagur","Föstudagur","Laugardagur","Sunnudagur"),IF(B8<>"",B8,"")) -> Þriðjudagur | C9: =IF(A9<>"",WEEKNUM(A9,21),IF(C8<>"",C8,"")) -> 18 | D9: Bæði | E9: Ávaxtastund | F9: Vara | G9: Vínber – Meðaltal af netinu | H9: Vínber | I9: 50 | J9: 60 | L9: =IF(OR(F9 = "", G9 = ""), "", IF(F9 = "Vara", IFERROR(_xlfn.SINGLE(_xlfn.XLOOKUP(G9, Vöruskrá!A:A, Vöruskrá!E:E, "")), ""), IF(F9 = "Réttur", IFERROR(_xlfn.SINGLE(_xlfn.XLOOKUP(G9, Réttabanki!A:A, Réttabanki!AS:AS, "")), ""), ""))) | M9: =IF(OR(F9 = "", G9 = ""), "", IF(F9 = "Vara", IFERROR(_xlfn.SINGLE(_xlfn.XLOOKUP(G9, Vöruskrá!A:A, Vöruskrá!F:F, "")), ""), IF(F9 = "Réttur", IFERROR(_xlfn.SINGLE(_xlfn.XLOOKUP(G9, Réttabanki!A:A, Réttabanki!AT:AT, "")), ""), ""))) | N9: =IF(OR(F9 = "", G9 = ""), "", IF(F9 = "Vara", IFERROR(_xlfn.SINGLE(_xlfn.XLOOKUP(G9, Vöruskrá!A:A, Vöruskrá!G:G, "")), ""), IF(F9 = "Réttur", IFERROR(_xlfn.SINGLE(_xlfn.XLOOKUP(G9, Réttabanki!A:A, Réttabanki!AU:AU, "")), ""), ""))) | O9: =IF(OR(F9 = "", G9 = "", I9 = ""), "", IF(F9 = "Vara", IFERROR(_xlfn.SINGLE(_xlfn.XLOOKUP(G9, Vöruskrá!A:A, Vöruskrá!I:I, "")) * I9 / 100, ""), IF(F9 = "Réttur", IFERROR(_xlfn.SINGLE(_xlfn.XLOOKUP(G9, Réttabanki!A:A, Réttabanki!AV:AV, "")) * I9 / 100, ""), ""))) | P9: =IF(OR(F9 = "", G9 = "", I9 = ""), "", IF(F9 = "Vara", IFERROR(_xlfn.SINGLE(_xlfn.XLOOKUP(G9, Vöruskrá!A:A, Vöruskrá!J:J, "")) * I9 / 100, ""), IF(F9 = "Réttur", IFERROR(_xlfn.SINGLE(_xlfn.XLOOKUP(G9, Réttabanki!A:A, Réttabanki!AW:AW, "")) * I9 / 100, ""), ""))) | Q9: =IF(OR(F9 = "", G9 = "", I9 = ""), "", IF(F9 = "Vara", IFERROR(_xlfn.SINGLE(_xlfn.XLOOKUP(G9, Vöruskrá!A:A, Vöruskrá!N:N, "")) * I9 / 100, ""), IF(F9 = "Réttur", IFERROR(_xlfn.SINGLE(_xlfn.XLOOKUP(G9, Réttabanki!A:A, Réttabanki!BB:BB, "")) * I9 / 100, ""), "")))
A10: 46188 | B10: =IF(A10<>"",CHOOSE(WEEKDAY(A10,2),"Mánudagur","Þriðjudagur","Miðvikudagur","Fimmtudagur","Föstudagur","Laugardagur","Sunnudagur"),IF(B9<>"",B9,"")) -> Mánudagur | C10: =IF(A10<>"",WEEKNUM(A10,21),IF(C9<>"",C9,"")) -> 25 | D10: Leikskóli | E10: Aðalréttur | H10: Vanilluskyr með jarðaberjum og bláberjum | L10: =IF(OR(F10 = "", G10 = ""), "", IF(F10 = "Vara", IFERROR(_xlfn.SINGLE(_xlfn.XLOOKUP(G10, Vöruskrá!A:A, Vöruskrá!E:E, "")), ""), IF(F10 = "Réttur", IFERROR(_xlfn.SINGLE(_xlfn.XLOOKUP(G10, Réttabanki!A:A, Réttabanki!AS:AS, "")), ""), ""))) | M10: =IF(OR(F10 = "", G10 = ""), "", IF(F10 = "Vara", IFERROR(_xlfn.SINGLE(_xlfn.XLOOKUP(G10, Vöruskrá!A:A, Vöruskrá!F:F, "")), ""), IF(F10 = "Réttur", IFERROR(_xlfn.SINGLE(_xlfn.XLOOKUP(G10, Réttabanki!A:A, Réttabanki!AT:AT, "")), ""), ""))) | N10: =IF(OR(F10 = "", G10 = ""), "", IF(F10 = "Vara", IFERROR(_xlfn.SINGLE(_xlfn.XLOOKUP(G10, Vöruskrá!A:A, Vöruskrá!G:G, "")), ""), IF(F10 = "Réttur", IFERROR(_xlfn.SINGLE(_xlfn.XLOOKUP(G10, Réttabanki!A:A, Réttabanki!AU:AU, "")), ""), ""))) | O10: =IF(OR(F10 = "", G10 = "", I10 = ""), "", IF(F10 = "Vara", IFERROR(_xlfn.SINGLE(_xlfn.XLOOKUP(G10, Vöruskrá!A:A, Vöruskrá!I:I, "")) * I10 / 100, ""), IF(F10 = "Réttur", IFERROR(_xlfn.SINGLE(_xlfn.XLOOKUP(G10, Réttabanki!A:A, Réttabanki!AV:AV, "")) * I10 / 100, ""), ""))) | P10: =IF(OR(F10 = "", G10 = "", I10 = ""), "", IF(F10 = "Vara", IFERROR(_xlfn.SINGLE(_xlfn.XLOOKUP(G10, Vöruskrá!A:A, Vöruskrá!J:J, "")) * I10 / 100, ""), IF(F10 = "Réttur", IFERROR(_xlfn.SINGLE(_xlfn.XLOOKUP(G10, Réttabanki!A:A, Réttabanki!AW:AW, "")) * I10 / 100, ""), ""))) | Q10: =IF(OR(F10 = "", G10 = "", I10 = ""), "", IF(F10 = "Vara", IFERROR(_xlfn.SINGLE(_xlfn.XLOOKUP(G10, Vöruskrá!A:A, Vöruskrá!N:N, "")) * I10 / 100, ""), IF(F10 = "Réttur", IFERROR(_xlfn.SINGLE(_xlfn.XLOOKUP(G10, Réttabanki!A:A, Réttabanki!BB:BB, "")) * I10 / 100, ""), "")))
B11: =IF(A11<>"",CHOOSE(WEEKDAY(A11,2),"Mánudagur","Þriðjudagur","Miðvikudagur","Fimmtudagur","Föstudagur","Laugardagur","Sunnudagur"),IF(B10<>"",B10,"")) -> Mánudagur | C11: =IF(A11<>"",WEEKNUM(A11,21),IF(C10<>"",C10,"")) -> 25 | D11: Leikskóli | E11: Aðalréttur | F11: Vara | G11: Arna skyr vanillu – Arna / MS | H11: Vanilluskyr | I11: 250 | J11: 300 | L11: =IF(OR(F11 = "", G11 = ""), "", IF(F11 = "Vara", IFERROR(_xlfn.SINGLE(_xlfn.XLOOKUP(G11, Vöruskrá!A:A, Vöruskrá!E:E, "")), ""), IF(F11 = "Réttur", IFERROR(_xlfn.SINGLE(_xlfn.XLOOKUP(G11, Réttabanki!A:A, Réttabanki!AS:AS, "")), ""), ""))) | M11: =IF(OR(F11 = "", G11 = ""), "", IF(F11 = "Vara", IFERROR(_xlfn.SINGLE(_xlfn.XLOOKUP(G11, Vöruskrá!A:A, Vöruskrá!F:F, "")), ""), IF(F11 = "Réttur", IFERROR(_xlfn.SINGLE(_xlfn.XLOOKUP(G11, Réttabanki!A:A, Réttabanki!AT:AT, "")), ""), ""))) | N11: =IF(OR(F11 = "", G11 = ""), "", IF(F11 = "Vara", IFERROR(_xlfn.SINGLE(_xlfn.XLOOKUP(G11, Vöruskrá!A:A, Vöruskrá!G:G, "")), ""), IF(F11 = "Réttur", IFERROR(_xlfn.SINGLE(_xlfn.XLOOKUP(G11, Réttabanki!A:A, Réttabanki!AU:AU, "")), ""), ""))) | O11: =IF(OR(F11 = "", G11 = "", I11 = ""), "", IF(F11 = "Vara", IFERROR(_xlfn.SINGLE(_xlfn.XLOOKUP(G11, Vöruskrá!A:A, Vöruskrá!I:I, "")) * I11 / 100, ""), IF(F11 = "Réttur", IFERROR(_xlfn.SINGLE(_xlfn.XLOOKUP(G11, Réttabanki!A:A, Réttabanki!AV:AV, "")) * I11 / 100, ""), ""))) | P11: =IF(OR(F11 = "", G11 = "", I11 = ""), "", IF(F11 = "Vara", IFERROR(_xlfn.SINGLE(_xlfn.XLOOKUP(G11, Vöruskrá!A:A, Vöruskrá!J:J, "")) * I11 / 100, ""), IF(F11 = "Réttur", IFERROR(_xlfn.SINGLE(_xlfn.XLOOKUP(G11, Réttabanki!A:A, Réttabanki!AW:AW, "")) * I11 / 100, ""), ""))) | Q11: =IF(OR(F11 = "", G11 = "", I11 = ""), "", IF(F11 = "Vara", IFERROR(_xlfn.SINGLE(_xlfn.XLOOKUP(G11, Vöruskrá!A:A, Vöruskrá!N:N, "")) * I11 / 100, ""), IF(F11 = "Réttur", IFERROR(_xlfn.SINGLE(_xlfn.XLOOKUP(G11, Réttabanki!A:A, Réttabanki!BB:BB, "")) * I11 / 100, ""), "")))
B12: =IF(A12<>"",CHOOSE(WEEKDAY(A12,2),"Mánudagur","Þriðjudagur","Miðvikudagur","Fimmtudagur","Föstudagur","Laugardagur","Sunnudagur"),IF(B11<>"",B11,"")) -> Mánudagur | C12: =IF(A12<>"",WEEKNUM(A12,21),IF(C11<>"",C11,"")) -> 25 | D12: Leikskóli | E12: Aðalréttur | F12: Vara | G12: Jarðarber frosið – Global Food Link S.L.U. | H12: Jarðarber | I12: 50 | J12: 60 | L12: =IF(OR(F12 = "", G12 = ""), "", IF(F12 = "Vara", IFERROR(_xlfn.SINGLE(_xlfn.XLOOKUP(G12, Vöruskrá!A:A, Vöruskrá!E:E, "")), ""), IF(F12 = "Réttur", IFERROR(_xlfn.SINGLE(_xlfn.XLOOKUP(G12, Réttabanki!A:A, Réttabanki!AS:AS, "")), ""), ""))) | M12: =IF(OR(F12 = "", G12 = ""), "", IF(F12 = "Vara", IFERROR(_xlfn.SINGLE(_xlfn.XLOOKUP(G12, Vöruskrá!A:A, Vöruskrá!F:F, "")), ""), IF(F12 = "Réttur", IFERROR(_xlfn.SINGLE(_xlfn.XLOOKUP(G12, Réttabanki!A:A, Réttabanki!AT:AT, "")), ""), ""))) | N12: =IF(OR(F12 = "", G12 = ""), "", IF(F12 = "Vara", IFERROR(_xlfn.SINGLE(_xlfn.XLOOKUP(G12, Vöruskrá!A:A, Vöruskrá!G:G, "")), ""), IF(F12 = "Réttur", IFERROR(_xlfn.SINGLE(_xlfn.XLOOKUP(G12, Réttabanki!A:A, Réttabanki!AU:AU, "")), ""), ""))) | O12: =IF(OR(F12 = "", G12 = "", I12 = ""), "", IF(F12 = "Vara", IFERROR(_xlfn.SINGLE(_xlfn.XLOOKUP(G12, Vöruskrá!A:A, Vöruskrá!I:I, "")) * I12 / 100, ""), IF(F12 = "Réttur", IFERROR(_xlfn.SINGLE(_xlfn.XLOOKUP(G12, Réttabanki!A:A, Réttabanki!AV:AV, "")) * I12 / 100, ""), ""))) | P12: =IF(OR(F12 = "", G12 = "", I12 = ""), "", IF(F12 = "Vara", IFERROR(_xlfn.SINGLE(_xlfn.XLOOKUP(G12, Vöruskrá!A:A, Vöruskrá!J:J, "")) * I12 / 100, ""), IF(F12 = "Réttur", IFERROR(_xlfn.SINGLE(_xlfn.XLOOKUP(G12, Réttabanki!A:A, Réttabanki!AW:AW, "")) * I12 / 100, ""), ""))) | Q12: =IF(OR(F12 = "", G12 = "", I12 = ""), "", IF(F12 = "Vara", IFERROR(_xlfn.SINGLE(_xlfn.XLOOKUP(G12, Vöruskrá!A:A, Vöruskrá!N:N, "")) * I12 / 100, ""), IF(F12 = "Réttur", IFERROR(_xlfn.SINGLE(_xlfn.XLOOKUP(G12, Réttabanki!A:A, Réttabanki!BB:BB, "")) * I12 / 100, ""), "")))
B13: =IF(A13<>"",CHOOSE(WEEKDAY(A13,2),"Mánudagur","Þriðjudagur","Miðvikudagur","Fimmtudagur","Föstudagur","Laugardagur","Sunnudagur"),IF(B12<>"",B12,"")) -> Mánudagur | C13: =IF(A13<>"",WEEKNUM(A13,21),IF(C12<>"",C12,"")) -> 25 | D13: Leikskóli | E13: Aðalréttur | F13: Vara | G13: Bláber frosið (Wild Blueberries) – N.V. d'Arta | H13: Bláber | I13: 50 | J13: 60 | L13: =IF(OR(F13 = "", G13 = ""), "", IF(F13 = "Vara", IFERROR(_xlfn.SINGLE(_xlfn.XLOOKUP(G13, Vöruskrá!A:A, Vöruskrá!E:E, "")), ""), IF(F13 = "Réttur", IFERROR(_xlfn.SINGLE(_xlfn.XLOOKUP(G13, Réttabanki!A:A, Réttabanki!AS:AS, "")), ""), ""))) | M13: =IF(OR(F13 = "", G13 = ""), "", IF(F13 = "Vara", IFERROR(_xlfn.SINGLE(_xlfn.XLOOKUP(G13, Vöruskrá!A:A, Vöruskrá!F:F, "")), ""), IF(F13 = "Réttur", IFERROR(_xlfn.SINGLE(_xlfn.XLOOKUP(G13, Réttabanki!A:A, Réttabanki!AT:AT, "")), ""), ""))) | N13: =IF(OR(F13 = "", G13 = ""), "", IF(F13 = "Vara", IFERROR(_xlfn.SINGLE(_xlfn.XLOOKUP(G13, Vöruskrá!A:A, Vöruskrá!G:G, "")), ""), IF(F13 = "Réttur", IFERROR(_xlfn.SINGLE(_xlfn.XLOOKUP(G13, Réttabanki!A:A, Réttabanki!AU:AU, "")), ""), ""))) | O13: =IF(OR(F13 = "", G13 = "", I13 = ""), "", IF(F13 = "Vara", IFERROR(_xlfn.SINGLE(_xlfn.XLOOKUP(G13, Vöruskrá!A:A, Vöruskrá!I:I, "")) * I13 / 100, ""), IF(F13 = "Réttur", IFERROR(_xlfn.SINGLE(_xlfn.XLOOKUP(G13, Réttabanki!A:A, Réttabanki!AV:AV, "")) * I13 / 100, ""), ""))) | P13: =IF(OR(F13 = "", G13 = "", I13 = ""), "", IF(F13 = "Vara", IFERROR(_xlfn.SINGLE(_xlfn.XLOOKUP(G13, Vöruskrá!A:A, Vöruskrá!J:J, "")) * I13 / 100, ""), IF(F13 = "Réttur", IFERROR(_xlfn.SINGLE(_xlfn.XLOOKUP(G13, Réttabanki!A:A, Réttabanki!AW:AW, "")) * I13 / 100, ""), ""))) | Q13: =IF(OR(F13 = "", G13 = "", I13 = ""), "", IF(F13 = "Vara", IFERROR(_xlfn.SINGLE(_xlfn.XLOOKUP(G13, Vöruskrá!A:A, Vöruskrá!N:N, "")) * I13 / 100, ""), IF(F13 = "Réttur", IFERROR(_xlfn.SINGLE(_xlfn.XLOOKUP(G13, Réttabanki!A:A, Réttabanki!BB:BB, "")) * I13 / 100, ""), "")))
B14: =IF(A14<>"",CHOOSE(WEEKDAY(A14,2),"Mánudagur","Þriðjudagur","Miðvikudagur","Fimmtudagur","Föstudagur","Laugardagur","Sunnudagur"),IF(B13<>"",B13,"")) -> Mánudagur | C14: =IF(A14<>"",WEEKNUM(A14,21),IF(C13<>"",C13,"")) -> 25 | D14: Bæði | E14: Hliðarréttur | H14: Soja jógúrt með jarðaberja eða vanillubragði | L14: =IF(OR(F14 = "", G14 = ""), "", IF(F14 = "Vara", IFERROR(_xlfn.SINGLE(_xlfn.XLOOKUP(G14, Vöruskrá!A:A, Vöruskrá!E:E, "")), ""), IF(F14 = "Réttur", IFERROR(_xlfn.SINGLE(_xlfn.XLOOKUP(G14, Réttabanki!A:A, Réttabanki!AS:AS, "")), ""), ""))) | M14: =IF(OR(F14 = "", G14 = ""), "", IF(F14 = "Vara", IFERROR(_xlfn.SINGLE(_xlfn.XLOOKUP(G14, Vöruskrá!A:A, Vöruskrá!F:F, "")), ""), IF(F14 = "Réttur", IFERROR(_xlfn.SINGLE(_xlfn.XLOOKUP(G14, Réttabanki!A:A, Réttabanki!AT:AT, "")), ""), ""))) | N14: =IF(OR(F14 = "", G14 = ""), "", IF(F14 = "Vara", IFERROR(_xlfn.SINGLE(_xlfn.XLOOKUP(G14, Vöruskrá!A:A, Vöruskrá!G:G, "")), ""), IF(F14 = "Réttur", IFERROR(_xlfn.SINGLE(_xlfn.XLOOKUP(G14, Réttabanki!A:A, Réttabanki!AU:AU, "")), ""), ""))) | O14: =IF(OR(F14 = "", G14 = "", I14 = ""), "", IF(F14 = "Vara", IFERROR(_xlfn.SINGLE(_xlfn.XLOOKUP(G14, Vöruskrá!A:A, Vöruskrá!I:I, "")) * I14 / 100, ""), IF(F14 = "Réttur", IFERROR(_xlfn.SINGLE(_xlfn.XLOOKUP(G14, Réttabanki!A:A, Réttabanki!AV:AV, "")) * I14 / 100, ""), ""))) | P14: =IF(OR(F14 = "", G14 = "", I14 = ""), "", IF(F14 = "Vara", IFERROR(_xlfn.SINGLE(_xlfn.XLOOKUP(G14, Vöruskrá!A:A, Vöruskrá!J:J, "")) * I14 / 100, ""), IF(F14 = "Réttur", IFERROR(_xlfn.SINGLE(_xlfn.XLOOKUP(G14, Réttabanki!A:A, Réttabanki!AW:AW, "")) * I14 / 100, ""), ""))) | Q14: =IF(OR(F14 = "", G14 = "", I14 = ""), "", IF(F14 = "Vara", IFERROR(_xlfn.SINGLE(_xlfn.XLOOKUP(G14, Vöruskrá!A:A, Vöruskrá!N:N, "")) * I14 / 100, ""), IF(F14 = "Réttur", IFERROR(_xlfn.SINGLE(_xlfn.XLOOKUP(G14, Réttabanki!A:A, Réttabanki!BB:BB, "")) * I14 / 100, ""), "")))
B15: =IF(A15<>"",CHOOSE(WEEKDAY(A15,2),"Mánudagur","Þriðjudagur","Miðvikudagur","Fimmtudagur","Föstudagur","Laugardagur","Sunnudagur"),IF(B14<>"",B14,"")) -> Mánudagur | C15: =IF(A15<>"",WEEKNUM(A15,21),IF(C14<>"",C14,"")) -> 25 | D15: Bæði | E15: Hliðarréttur | F15: Vara | G15: Sojajógúrt jarðarberja (Oddlygood) – Oddlygood Sweden AB | H15: Soja jógúrt | I15: 150 | J15: 165 | L15: =IF(OR(F15 = "", G15 = ""), "", IF(F15 = "Vara", IFERROR(_xlfn.SINGLE(_xlfn.XLOOKUP(G15, Vöruskrá!A:A, Vöruskrá!E:E, "")), ""), IF(F15 = "Réttur", IFERROR(_xlfn.SINGLE(_xlfn.XLOOKUP(G15, Réttabanki!A:A, Réttabanki!AS:AS, "")), ""), ""))) | M15: =IF(OR(F15 = "", G15 = ""), "", IF(F15 = "Vara", IFERROR(_xlfn.SINGLE(_xlfn.XLOOKUP(G15, Vöruskrá!A:A, Vöruskrá!F:F, "")), ""), IF(F15 = "Réttur", IFERROR(_xlfn.SINGLE(_xlfn.XLOOKUP(G15, Réttabanki!A:A, Réttabanki!AT:AT, "")), ""), ""))) | N15: =IF(OR(F15 = "", G15 = ""), "", IF(F15 = "Vara", IFERROR(_xlfn.SINGLE(_xlfn.XLOOKUP(G15, Vöruskrá!A:A, Vöruskrá!G:G, "")), ""), IF(F15 = "Réttur", IFERROR(_xlfn.SINGLE(_xlfn.XLOOKUP(G15, Réttabanki!A:A, Réttabanki!AU:AU, "")), ""), ""))) | O15: =IF(OR(F15 = "", G15 = "", I15 = ""), "", IF(F15 = "Vara", IFERROR(_xlfn.SINGLE(_xlfn.XLOOKUP(G15, Vöruskrá!A:A, Vöruskrá!I:I, "")) * I15 / 100, ""), IF(F15 = "Réttur", IFERROR(_xlfn.SINGLE(_xlfn.XLOOKUP(G15, Réttabanki!A:A, Réttabanki!AV:AV, "")) * I15 / 100, ""), ""))) | P15: =IF(OR(F15 = "", G15 = "", I15 = ""), "", IF(F15 = "Vara", IFERROR(_xlfn.SINGLE(_xlfn.XLOOKUP(G15, Vöruskrá!A:A, Vöruskrá!J:J, "")) * I15 / 100, ""), IF(F15 = "Réttur", IFERROR(_xlfn.SINGLE(_xlfn.XLOOKUP(G15, Réttabanki!A:A, Réttabanki!AW:AW, "")) * I15 / 100, ""), ""))) | Q15: =IF(OR(F15 = "", G15 = "", I15 = ""), "", IF(F15 = "Vara", IFERROR(_xlfn.SINGLE(_xlfn.XLOOKUP(G15, Vöruskrá!A:A, Vöruskrá!N:N, "")) * I15 / 100, ""), IF(F15 = "Réttur", IFERROR(_xlfn.SINGLE(_xlfn.XLOOKUP(G15, Réttabanki!A:A, Réttabanki!BB:BB, "")) * I15 / 100, ""), "")))
B16: =IF(A16<>"",CHOOSE(WEEKDAY(A16,2),"Mánudagur","Þriðjudagur","Miðvikudagur","Fimmtudagur","Föstudagur","Laugardagur","Sunnudagur"),IF(B15<>"",B15,"")) -> Mánudagur | C16: =IF(A16<>"",WEEKNUM(A16,21),IF(C15<>"",C15,"")) -> 25 | D16: Bæði | E16: Hliðarréttur | F16: Vara | G16: Sojajógúrt vanillu (Oddlygood) – Oddlygood Sweden AB | H16: Soja jógúrt vanillu | I16: 150 | J16: 165 | L16: =IF(OR(F16 = "", G16 = ""), "", IF(F16 = "Vara", IFERROR(_xlfn.SINGLE(_xlfn.XLOOKUP(G16, Vöruskrá!A:A, Vöruskrá!E:E, "")), ""), IF(F16 = "Réttur", IFERROR(_xlfn.SINGLE(_xlfn.XLOOKUP(G16, Réttabanki!A:A, Réttabanki!AS:AS, "")), ""), ""))) | M16: =IF(OR(F16 = "", G16 = ""), "", IF(F16 = "Vara", IFERROR(_xlfn.SINGLE(_xlfn.XLOOKUP(G16, Vöruskrá!A:A, Vöruskrá!F:F, "")), ""), IF(F16 = "Réttur", IFERROR(_xlfn.SINGLE(_xlfn.XLOOKUP(G16, Réttabanki!A:A, Réttabanki!AT:AT, "")), ""), ""))) | N16: =IF(OR(F16 = "", G16 = ""), "", IF(F16 = "Vara", IFERROR(_xlfn.SINGLE(_xlfn.XLOOKUP(G16, Vöruskrá!A:A, Vöruskrá!G:G, "")), ""), IF(F16 = "Réttur", IFERROR(_xlfn.SINGLE(_xlfn.XLOOKUP(G16, Réttabanki!A:A, Réttabanki!AU:AU, "")), ""), ""))) | O16: =IF(OR(F16 = "", G16 = "", I16 = ""), "", IF(F16 = "Vara", IFERROR(_xlfn.SINGLE(_xlfn.XLOOKUP(G16, Vöruskrá!A:A, Vöruskrá!I:I, "")) * I16 / 100, ""), IF(F16 = "Réttur", IFERROR(_xlfn.SINGLE(_xlfn.XLOOKUP(G16, Réttabanki!A:A, Réttabanki!AV:AV, "")) * I16 / 100, ""), ""))) | P16: =IF(OR(F16 = "", G16 = "", I16 = ""), "", IF(F16 = "Vara", IFERROR(_xlfn.SINGLE(_xlfn.XLOOKUP(G16, Vöruskrá!A:A, Vöruskrá!J:J, "")) * I16 / 100, ""), IF(F16 = "Réttur", IFERROR(_xlfn.SINGLE(_xlfn.XLOOKUP(G16, Réttabanki!A:A, Réttabanki!AW:AW, "")) * I16 / 100, ""), ""))) | Q16: =IF(OR(F16 = "", G16 = "", I16 = ""), "", IF(F16 = "Vara", IFERROR(_xlfn.SINGLE(_xlfn.XLOOKUP(G16, Vöruskrá!A:A, Vöruskrá!N:N, "")) * I16 / 100, ""), IF(F16 = "Réttur", IFERROR(_xlfn.SINGLE(_xlfn.XLOOKUP(G16, Réttabanki!A:A, Réttabanki!BB:BB, "")) * I16 / 100, ""), "")))
B17: =IF(A17<>"",CHOOSE(WEEKDAY(A17,2),"Mánudagur","Þriðjudagur","Miðvikudagur","Fimmtudagur","Föstudagur","Laugardagur","Sunnudagur"),IF(B16<>"",B16,"")) -> Mánudagur | C17: =IF(A17<>"",WEEKNUM(A17,21),IF(C16<>"",C16,"")) -> 25 | D17: Bæði | E17: Meðlæti | H17: Rúnstykki, smjörvi, ostur og ávöxtur | L17: =IF(OR(F17 = "", G17 = ""), "", IF(F17 = "Vara", IFERROR(_xlfn.SINGLE(_xlfn.XLOOKUP(G17, Vöruskrá!A:A, Vöruskrá!E:E, "")), ""), IF(F17 = "Réttur", IFERROR(_xlfn.SINGLE(_xlfn.XLOOKUP(G17, Réttabanki!A:A, Réttabanki!AS:AS, "")), ""), ""))) | M17: =IF(OR(F17 = "", G17 = ""), "", IF(F17 = "Vara", IFERROR(_xlfn.SINGLE(_xlfn.XLOOKUP(G17, Vöruskrá!A:A, Vöruskrá!F:F, "")), ""), IF(F17 = "Réttur", IFERROR(_xlfn.SINGLE(_xlfn.XLOOKUP(G17, Réttabanki!A:A, Réttabanki!AT:AT, "")), ""), ""))) | N17: =IF(OR(F17 = "", G17 = ""), "", IF(F17 = "Vara", IFERROR(_xlfn.SINGLE(_xlfn.XLOOKUP(G17, Vöruskrá!A:A, Vöruskrá!G:G, "")), ""), IF(F17 = "Réttur", IFERROR(_xlfn.SINGLE(_xlfn.XLOOKUP(G17, Réttabanki!A:A, Réttabanki!AU:AU, "")), ""), ""))) | O17: =IF(OR(F17 = "", G17 = "", I17 = ""), "", IF(F17 = "Vara", IFERROR(_xlfn.SINGLE(_xlfn.XLOOKUP(G17, Vöruskrá!A:A, Vöruskrá!I:I, "")) * I17 / 100, ""), IF(F17 = "Réttur", IFERROR(_xlfn.SINGLE(_xlfn.XLOOKUP(G17, Réttabanki!A:A, Réttabanki!AV:AV, "")) * I17 / 100, ""), ""))) | P17: =IF(OR(F17 = "", G17 = "", I17 = ""), "", IF(F17 = "Vara", IFERROR(_xlfn.SINGLE(_xlfn.XLOOKUP(G17, Vöruskrá!A:A, Vöruskrá!J:J, "")) * I17 / 100, ""), IF(F17 = "Réttur", IFERROR(_xlfn.SINGLE(_xlfn.XLOOKUP(G17, Réttabanki!A:A, Réttabanki!AW:AW, "")) * I17 / 100, ""), ""))) | Q17: =IF(OR(F17 = "", G17 = "", I17 = ""), "", IF(F17 = "Vara", IFERROR(_xlfn.SINGLE(_xlfn.XLOOKUP(G17, Vöruskrá!A:A, Vöruskrá!N:N, "")) * I17 / 100, ""), IF(F17 = "Réttur", IFERROR(_xlfn.SINGLE(_xlfn.XLOOKUP(G17, Réttabanki!A:A, Réttabanki!BB:BB, "")) * I17 / 100, ""), "")))
B18: =IF(A18<>"",CHOOSE(WEEKDAY(A18,2),"Mánudagur","Þriðjudagur","Miðvikudagur","Fimmtudagur","Föstudagur","Laugardagur","Sunnudagur"),IF(B17<>"",B17,"")) -> Mánudagur | C18: =IF(A18<>"",WEEKNUM(A18,21),IF(C17<>"",C17,"")) -> 25 | D18: Bæði | E18: Meðlæti | F18: Vara | G18: Rúnstykki Kaiserbrauð 60 g (Diversi Foods) – Natan -Diversi Foods NV | H18: Rúnstykki | I18: 60 | J18: 120 | L18: =IF(OR(F18 = "", G18 = ""), "", IF(F18 = "Vara", IFERROR(_xlfn.SINGLE(_xlfn.XLOOKUP(G18, Vöruskrá!A:A, Vöruskrá!E:E, "")), ""), IF(F18 = "Réttur", IFERROR(_xlfn.SINGLE(_xlfn.XLOOKUP(G18, Réttabanki!A:A, Réttabanki!AS:AS, "")), ""), ""))) | M18: =IF(OR(F18 = "", G18 = ""), "", IF(F18 = "Vara", IFERROR(_xlfn.SINGLE(_xlfn.XLOOKUP(G18, Vöruskrá!A:A, Vöruskrá!F:F, "")), ""), IF(F18 = "Réttur", IFERROR(_xlfn.SINGLE(_xlfn.XLOOKUP(G18, Réttabanki!A:A, Réttabanki!AT:AT, "")), ""), ""))) | N18: =IF(OR(F18 = "", G18 = ""), "", IF(F18 = "Vara", IFERROR(_xlfn.SINGLE(_xlfn.XLOOKUP(G18, Vöruskrá!A:A, Vöruskrá!G:G, "")), ""), IF(F18 = "Réttur", IFERROR(_xlfn.SINGLE(_xlfn.XLOOKUP(G18, Réttabanki!A:A, Réttabanki!AU:AU, "")), ""), ""))) | O18: =IF(OR(F18 = "", G18 = "", I18 = ""), "", IF(F18 = "Vara", IFERROR(_xlfn.SINGLE(_xlfn.XLOOKUP(G18, Vöruskrá!A:A, Vöruskrá!I:I, "")) * I18 / 100, ""), IF(F18 = "Réttur", IFERROR(_xlfn.SINGLE(_xlfn.XLOOKUP(G18, Réttabanki!A:A, Réttabanki!AV:AV, "")) * I18 / 100, ""), ""))) | P18: =IF(OR(F18 = "", G18 = "", I18 = ""), "", IF(F18 = "Vara", IFERROR(_xlfn.SINGLE(_xlfn.XLOOKUP(G18, Vöruskrá!A:A, Vöruskrá!J:J, "")) * I18 / 100, ""), IF(F18 = "Réttur", IFERROR(_xlfn.SINGLE(_xlfn.XLOOKUP(G18, Réttabanki!A:A, Réttabanki!AW:AW, "")) * I18 / 100, ""), ""))) | Q18: =IF(OR(F18 = "", G18 = "", I18 = ""), "", IF(F18 = "Vara", IFERROR(_xlfn.SINGLE(_xlfn.XLOOKUP(G18, Vöruskrá!A:A, Vöruskrá!N:N, "")) * I18 / 100, ""), IF(F18 = "Réttur", IFERROR(_xlfn.SINGLE(_xlfn.XLOOKUP(G18, Réttabanki!A:A, Réttabanki!BB:BB, "")) * I18 / 100, ""), "")))
