Workbook
Name Álfaberg: Skóladeildarlisti!$B$10:$G$10
Name Álfakot: Skóladeildarlisti!#REF!
Name Arnarberg: Skóladeildarlisti!$B$11:$F$11
Name Bjarkalundur: Skóladeildarlisti!$B$12:$C$12
Name Engidalsskóli: Skóladeildarlisti!$B$2:$M$2
Name Hlíðarberg: Skóladeildarlisti!$B$13:$E$13
Name Holtasel: Skóladeildarlisti!#REF!
Name Hörðuvellir: Skóladeildarlisti!$B$14:$E$14
Name Hraunkot: Skóladeildarlisti!#REF!
Name Hraunsel: Skóladeildarlisti!#REF!
Name Hraunvallaskóli: Skóladeildarlisti!$B$3:$P$3
Name Hvaleyrarskóli: Skóladeildarlisti!$B$4:$P$4
Name Krakkaberg: Skóladeildarlisti!#REF!
Name Lækjarsel: Skóladeildarlisti!#REF!
Name Lækjarskóli: Skóladeildarlisti!$B$5:$P$5
Name Leikskólinn_við_Hraunvallaskóla: Skóladeildarlisti!$B$15:$F$15
Name Leikskólinn_við_Skarðshlíðarskó: Skóladeildarlisti!$B$16:$F$16
Name Öldutúnsskóli: Skóladeildarlisti!$B$6:$P$6
Name Selið: Skóladeildarlisti!#REF!
Name Setbergsskóli: Skóladeildarlisti!$B$7:$P$7
Name Skarðshlíðarskóli: Skóladeildarlisti!$B$8:$P$8
Name Skarðssel: Skóladeildarlisti!#REF!
Name Smáralundur: Skóladeildarlisti!$B$17:$F$17
Name Stekkjarás: Skóladeildarlisti!$B$18:$I$18
Name Tjarnarás: Skóladeildarlisti!$B$19:$F$19
Name Vesturkot: Skóladeildarlisti!$B$20:$F$20
Name Víðistaðaskóli: Skóladeildarlisti!$B$9:$P$9
Name Víðivellir: Skóladeildarlisti!$B$21:$D$21

Sheet Fjöldi núna
A1: Skóli | B1: Bekkur / Deild | C1: Fjöldi í dag | D1: Starfsmenn | E1: Vikudagamynstur | F1: Gildir frá | H1: Þetta blað fyllist sjálfkrafa út þegar Office-skriftan (Matarstund_Script.ts) keyrir næst — sýnir núverandi gildandi fjöldatölur fyrir alla skóla, reiknaðar út frá Fjöldatölur-sögunni.
A2: Arnarberg | B2: Annað starfsfólk | C2: 0 | D2: 2 | E2: sama alla daga
A3: Arnarberg | B3: Hamar | C3: 22 | D3: 4 | E3: sama alla daga | F3: 46265
A4: Arnarberg | B4: Klettur | C4: 22 | D4: 4 | E4: sama alla daga | F4: 46265
A5: Arnarberg | B5: Krókur | C5: 10 | D5: 2 | E5: sama alla daga | F5: 46265
A6: Arnarberg | B6: Reitur | C6: 15 | D6: 4 | E6: sama alla daga | F6: 46265
A7: Álfaberg | B7: Askja | C7: 22 | D7: 4 | E7: Mán:22 Þri:22 Mið:22 Fim:22 Fös:22 | F7: 46268
A8: Álfaberg | B8: Búrfell | C8: 13 | D8: 4 | E8: Mán:13 Þri:13 Mið:13 Fim:13 Fös:13 | F8: 46268
A9: Álfaberg | B9: Esja | C9: 15 | D9: 4 | E9: Mán:15 Þri:15 Mið:15 Fim:15 Fös:15 | F9: 46268
A10: Álfaberg | B10: Heildarfjöldi — ekki tengt ákveðnum bekk (t.d. stjórnendur) — leggst VIÐ bekkjartölurnar | C10: 0 | D10: 3 | E10: Mán:0 Þri:0 Mið:0 Fim:0 Fös:0 | F10: 46268
A11: Álfaberg | B11: Helgafell | C11: 18 | D11: 4 | E11: Mán:18 Þri:18 Mið:18 Fim:18 Fös:18 | F11: 46268
A12: Álfaberg | B12: Keili | C12: 10 | D12: 4 | E12: Mán:10 Þri:10 Mið:10 Fim:10 Fös:10 | F12: 46268
A13: Álfakot | B13: Setja inn heildarfjölda | C13: 76 | D13: 0 | E13: Mán:76 Þri:76 Mið:76 Fim:76 Fös:76 | F13: 46267
A14: Bjarkalundur | B14: Heildarfjöldi — ekki tengt ákveðnum bekk (t.d. stjórnendur) — leggst VIÐ bekkjartölurnar | C14: 68 | D14: 24 | E14: Mán:68 Þri:68 Mið:68 Fim:68 Fös:68 | F14: 46272
... A21: Engidalsskóli | B21: 7. bekkur | C21: 34 | D21: 0 | E21: Mán:34 Þri:34 Mið:34 Fim:34 Fös:34 | F21: 46261
A22: Engidalsskóli | B22: Heildarfjöldi (fyllt út AÐEINS ef bekkja-/deildaskipting er ekki þekkt) | C22: 0 | D22: 48 | E22: sama alla daga
A23: Hlíðarberg | B23: Heildarfjöldi — ekki tengt ákveðnum bekk (t.d. stjórnendur) — leggst VIÐ bekkjartölurnar | C23: 90 | D23: 28 | E23: Mán:90 Þri:90 Mið:90 Fim:90 Fös:90 | F23: 46274
A24: Holtasel | B24: Setja inn heildarfjölda | C24: 90 | D24: 0 | E24: sama alla daga | F24: 46251
A25: Hraunkot | B25: Setja inn heildarfjölda | C25: 89 | D25: 9 | E25: Mán:89 Þri:89 Mið:89 Fim:89 Fös:89 | F25: 46266
A26: Hraunsel | C26: 137 | D26: 0 | E26: Mán:137 Þri:138 Mið:137 Fim:136 Fös:136 | F26: 46260
A27: Hraunsel | B27: Setja inn heildarfjölda | C27: 145 | D27: 20 | E27: sama alla daga | F27: 46272
A28: Hraunvallaleikskóli | B28: Heildarfjöldi — ekki tengt ákveðnum bekk (t.d. stjórnendur) — leggst VIÐ bekkjartölurnar | C28: 67 | D28: 24 | E28: sama alla daga | F28: 46251
A29: Hraunvallaskóli | B29: 1. bekkur | C29: 65 | D29: 0 | E29: sama alla daga | F29: 46251
A30: Hraunvallaskóli | B30: 2. bekkur | C30: 64 | D30: 0 | E30: sama alla daga | F30: 46251
A31: Hraunvallaskóli | B31: 3. bekkur | C31: 34 | D31: 0 | E31: sama alla daga | F31: 46251
A32: Hraunvallaskóli | B32: 4. bekkur | C32: 55 | D32: 0 | E32: sama alla daga | F32: 46251
A33: Hraunvallaskóli | B33: 5. bekkur | C33: 50 | D33: 0 | E33: sama alla daga | F33: 46251
A34: Hraunvallaskóli | B34: 6. bekkur | C34: 58 | D34: 0 | E34: sama alla daga | F34: 46251
A35: Hraunvallaskóli | B35: 7. bekkur | C35: 49 | D35: 0 | E35: sama alla daga | F35: 46251
A36: Hraunvallaskóli | B36: 8. bekkur | C36: 54 | D36: 0 | E36: sama alla daga | F36: 46251
A37: Hraunvallaskóli | B37: 9. bekkur | C37: 53 | D37: 0 | E37: sama alla daga | F37: 46251
A38: Hraunvallaskóli | B38: 10. bekkur | C38: 66 | D38: 0 | E38: sama alla daga | F38: 46251
A39: Hraunvallaskóli | B39: Heildarfjöldi (fyllt út AÐEINS ef bekkja-/deildaskipting er ekki þekkt) | C39: 0 | D39: 125 | E39: sama alla daga
A40: Hvaleyrarskóli | B40: 1. bekkur | C40: 37 | D40: 0 | E40: sama alla daga | F40: 46253
A41: Hvaleyrarskóli | B41: 2. bekkur | C41: 34 | D41: 0 | E41: sama alla daga | F41: 46253
A42: Hvaleyrarskóli | B42: 3. bekkur | C42: 26 | D42: 0 | E42: sama alla daga | F42: 46253
A43: Hvaleyrarskóli | B43: 4. bekkur | C43: 26 | D43: 0 | E43: sama alla daga | F43: 46253
A44: Hvaleyrarskóli | B44: 5. bekkur | C44: 38 | D44: 0 | E44: sama alla daga | F44: 46253
A45: Hvaleyrarskóli | B45: 6. bekkur | C45: 35 | D45: 0 | E45: sama alla daga | F45: 46253
A46: Hvaleyrarskóli | B46: 7. bekkur | C46: 31 | D46: 0 | E46: sama alla daga | F46: 46253
...

Sheet Vöruskrá
A1: VÖRUSKRÁ – HRÁEFNI OG INNIHALDSEFNI | U1: Soðið-hlutfall (verðlagning)
A2: Heiti vöru | B2: Leitarnafn (dropdown) | C2: Framleiðandi / Byrgi | D2: Vörúnúmer | E2: Vöruflokkur | F2: Innihaldslýsing | G2: Ofnæmisvaldar | H2: Fyrirvari | I2: Hlekkur á gagnablað | J2: Orka (kcal/100g) | K2: Fita (g/100g) | L2: Mettuð fita (g/100g) | M2: Kolvetni (g/100g) | N2: Sykur (g/100g) | O2: Prótein (g/100g) | P2: Salt (g/100g) | Q2: Trefjar (g/100g) | R2: Kostnaður (kr/kg) | S2: Athugasemdir | U2: 1.5
A3: Ömmu skonsur heilar | B3: Ömmu skonsur heilar | C3: Gæðabakstur / Ömmubakstur ehf. | D3: 121 | E3: Brauð og bakkelsi | F3: Vatn, **hveiti**, **haframjöl**, repjuolía, sykur, **heilhveiti**, **egg**, **mysuduft**, pálmaolía, lyftiefni (E450, E500), salt, maltað **hveiti**, mjölmeðhöndlunarefni (E300), rotvarnarefni (E282), sykur, bindiefni (E322 úr sólblómum, E471), dextrósi, bragðefni, rotvarnarefni (E211), sýrustillir (E330), vanillubragðefni, kókosolía, litarefni (E150c, E150a), kekkjarvarnarefni (E535) | G3: Glúten (hveiti, hafrar), egg, mjólk | H3: Gæti innihaldið snefil af sesam. | I3: https://gaedabakstur.is/vara/ommuskonsur-heilar-10stk-i-pakka/ | J3: 260 | K3: 12 | L3: 1.3 | M3: 31 | N3: 10 | O3: 5.3 | P3: 1 | Q3: 2.3 | R3: 600 | S3: 160 g/stk. Geymsluþol 5 dagar við stofuhita. | U3: Verðlagningarhlutfall – samþykkt. Tengt: R249, R288, R345. R54 og R239 eru ótengd (sjá skýringar í þeim hólfum).
A4: Bananaskonsur | B4: Bananaskonsur | C4: Gæðabakstur / Ömmubakstur ehf. | D4: 122 | E4: Brauð og bakkelsi | F4: Hrísmjólk (vatn, hrísgrjón, sólblómaolía, kalsíum, maltextrakt, salt, bindiefni E418, vítamín B12, D2, sýrustillir E340), **hveiti**, vatn, sykur, banani, repjuolía, maltað **hveiti**, mjölmeðhöndlunarefni (E300), lyftiefni (E450, E500), salt, vanillubragðefni, litarefni (E150c), kekkjarvarnarefni (E535) | G4: Glúten (hveiti) | H4: Gæti innihaldið snefil af sesam, mjólk og eggjum. | I4: https://gaedabakstur.is/vara/bananaskonsur/ | J4: 237 | K4: 4.3 | L4: 0.3 | M4: 44 | N4: 16 | O4: 4.4 | P4: 0.4 | Q4: 1.5 | R4: 600 | S4: 75 g/stk, 10 stk/pakki. Frystivara (-18°C) 3 mánuðir.
A5: Sólkjarnabrauð plötubrauð | B5: Sólkjarnabrauð plötubrauð | C5: Gæðabakstur / Ömmubakstur ehf. | D5: 730 | E5: Brauð og bakkelsi | F5: **Hveiti**, vatn, sólkjarnafræ, **rúgmjöl**, hörfræ, maltað **hveiti**, salt, maltað **bygg**, mjölmeðhöndlunarefni (E300), ger, malt extrakt (úr **byggi**), súrdeigsduft úr hveiti (**hveiti**, gerlar), dextrósi, **hveitiglúten**, bindiefni (E472e, E491), ensím, kekkjarvarnarefni (E535) | G5: Glúten (hveiti, rúgur, bygg) | H5: Gæti innihaldið snefil af sesamfræjum | I5: https://drive.google.com/file/d/1p07uLGGtQjJr-CEfMOPWvz0nx16AzC1e/view?usp=sharing | J5: 311 | K5: 10.8 | L5: 1.3 | M5: 40.3 | N5: 1.7 | O5: 10.5 | P5: 1.1 | Q5: 4.7 | R5: 600 | S5: 500 g. Geymsluþol 2 dagar eftir framleiðslu.
A6: Beyglur fínar KS(48) | B6: Beyglur fínar KS(48) | C6: Myllan | D6: 3413 | E6: Brauð og bakkelsi | F6: **Hveiti**, vatn, sykur, maltað mjöl (**bygg**, **hveiti**), salt, ger, óvirkt þurrger, ýruefni (E472e), repjuolía, mjölmeðhöndlunarefni (E300), ensím. | G6: Glúten (hveiti, bygg) | H6: Framleitt á svæði þar sem unnið er með sesamfræ, mjólk, egg, lúpínu, soja | I6: https://www.myllan.is/is/vorulinur/frosin-pokkud-vara/beyglur-finar | J6: 257 | K6: 0.9 | L6: 0.2 | M6: 51 | N6: 2.6 | O6: 9.4 | P6: 1.5 | Q6: 2.4 | R6: 600 | S6: 95 g/stk, 48 stk í söluein. Frystivara -18°C, geymsluþol 270 dagar.
A7: Heilkornasamlokubrauð stórt | B7: Heilkornasamlokubrauð stórt | C7: Myllan | D7: 1036 | E7: Brauð og bakkelsi | F7: Vatn, heilkorna **heilhveiti** 17%, heilkorna **rúgmjöl** 17%, **hveiti**, **hveitiglúten**, **hveitiflögur**, **rúgmjöl**, þurrkað súrdeig (**rúgur**, súrdeigsgerlar), **hveitikurl**, ger, maltextrakt (**bygg**), repjuolía, salt, þykkingarefni (E415), sýrustillir (E262), ýruefni (E471, E472e), þurrkað súrdeig (**hveiti**, súrdeigsgerlar), mjölmeðhöndlunarefni (E300) | G7: Glúten (hveiti, rúgur, bygg) | H7: Framleitt á svæði þar sem unnið er með sesamfræ, egg, mjólk og lúpínu | I7: https://www.myllan.is/is/vorulinur/samlokubraud/heilkornasamlokubraud-stort | J7: 244 | K7: 2.9 | L7: 0.6 | M7: 37 | N7: 1.6 | O7: 14 | P7: 1 | Q7: 6.6 | R7: 600 | S7: 1000 g. Geymsluþol 5 dagar. 49% af þurrefnum heilkorn.
A8: Heimilisbrauð 1/1 | B8: Heimilisbrauð 1/1 | C8: Myllan | D8: 1023 | E8: Brauð og bakkelsi | F8: **Hveiti**, vatn, **hveitikurl**, repjuolía, ger, salt, **hveititrefjar**, mjölmeðhöndlunarefni (E300), ýruefni (E481) | G8: Glúten (hveiti) | H8: Framleitt á svæði þar sem unnið er með sesamfræ, mjólk, egg og lúpínu | I8: https://www.myllan.is/is/vorulinur/samlokubraud/heimilisbraud-heilt | J8: 250 | K8: 2.7 | L8: 0.4 | M8: 45 | N8: 0.3 | O8: 9 | P8: 1.4 | Q8: 3.1 | R8: 531 | S8: 770 g. Geymsluþol 5 dagar. Vegan, trefjagjafi.
A9: Lífskornabrauð m/ tröllahöfrum og chia | B9: Lífskornabrauð m/ tröllahöfrum og chia | C9: Myllan | D9: 1063 | E9: Brauð og bakkelsi | F9: Vatn, **tröllahafrar** 21%, heilkorna **heilhveiti** 16%, **hveiti**, **hveitiglúten**, **rúgmjöl**, þurrkað súrdeig (**rúgur**, súrdeigsgerlar), **hveitikurl**, ger, chia fræ 1% (Salvia hispanica), maltextrakt (**bygg**), repjuolía, joðbætt salt, þykkingarefni (E415), sýrustillir (E262), ýruefni (E471, E472e), mjölmeðhöndlunarefni (E300) | G9: Glúten (hafrar, hveiti, rúgur, bygg) | H9: Framleitt á svæði þar sem unnið er með sesamfræ, egg, mjólk og lúpínu | I9: https://www.myllan.is/is/vorulinur/vegan-vorur/lifskorn-trollahafrar-chiafrae | J9: 241 | K9: 4.3 | L9: 0.8 | M9: 33 | N9: 1.2 | O9: 14 | P9: 0.9 | Q9: 6.8 | R9: 600 | S9: 450 g. Geymsluþol 6 dagar. Vegan, trefjaríkt.
A10: Hvítlauksbrauð / baguette | B10: Hvítlauksbrauð / baguette | C10: Myllan | D10: 4280 | E10: Brauð og bakkelsi | F10: Mjöl (**hveiti**, maltað **hveiti**), vatn, smjör (**mjólk**), jurtafita (pálma), jurtaolía (repju), joðbætt salt, ger, hvítlaukur 0,6%, laukduft, ýruefni (E472e, E471, sólblómalesitín), sýrustillir (E341, E450, E330), óvirkt ger, steinselja, salt, þykkingarefni (E412), bragðefni, þráavarnarefni (E300), ensím (alfaamýlasi, xýlanasi) | G10: Glúten (hveiti), mjólk | H10: Getur innihaldið snefil af eggjum, soja, sinnepi og sesamfræjum. | I10: https://drive.google.com/file/d/1ISY9dqVNVBuKMul2k8e0kwwb7vSrJhlW/view?usp=sharing | J10: 305 | K10: 14 | L10: 6.4 | M10: 37 | N10: 0.8 | O10: 6.6 | P10: 1.5 | Q10: 1.9 | R10: 797 | S10: 175 g/stk. 36 stk í söluein. Frystivara -18°C, geymsluþol 548 dagar. Næringargildi miðast við forbakaða/óbakaða vöru.
A11: Dökkt súrdeigsbrauð (Skanörgrova) | B11: Dökkt súrdeigsbrauð (Skanörgrova) | C11: Pågen/ Ójk | D11: 1003 | E11: Brauð og bakkelsi | F11: Vatn, **hveiti**mjöl, súrdeig úr **hveiti**korni (13%), heilkorna**hveiti**mjöl, dinkel**hveiti**mjöl, muldir heilkornakjarnar úr dinkel**hveiti**, **hafra**grjón, skolað heilkorna**hafra**mjöl, **hveiti**glúten, heilkorna**rúg**mjöl, heilkorna durum**hveiti**mjöl, **hafra**trefjar, kaldpressuð repjuolía (1%), **hveiti**kímar, gul hörfræ, sykur (eingöngu sem næring fyrir ger), ger, malt úr **byggi** og **hveiti**, salt. | G11: Glúten (hveiti, rúgur, hafrar, bygg) | I11: https://drive.google.com/file/d/1_xC3btJzq-zmdaQHqlJ0_0EY7KwFaCqs/view?usp=sharing | J11: 308 | K11: 7.8 | L11: 0.8 | M11: 48 | N11: 9.1 | O11: 10 | P11: 1.4 | Q11: 6 | R11: 600
A12: Ljóst súrdeigsbrauð (LantGoda Surdegsbröd) | B12: Ljóst súrdeigsbrauð (LantGoda Surdegsbröd) | C12: Pågen/ Ójk | D12: 1004 | E12: Brauð og bakkelsi | F12: Vatn, **hveiti**mjöl, súrdeig úr **hveiti** (13%), heilkorna**hveiti**mjöl, dinkel**hveiti**mjöl, muldir heilkornakjarnar úr dinkel**hveiti**, **hafra**grjón, skolað heilkorna**hafra**mjöl, **hveiti**glúten, heilkorna**rúg**mjöl, heilkorna durum**hveiti**mjöl, **hafra**trefjar, kaldpressuð repjuolía (1%), **hveiti**kímar, gul hörfræ, sykur (eingöngu sem næring fyrir ger), ger, malt úr **byggi** og **hveiti**, salt. | G12: Glúten (hveiti, rúg, hafrar, bygg) | I12: https://drive.google.com/file/d/1aObopp1C2qlx3QieZ3phPb3MzLNGDVZz/view?usp=sharing | J12: 262 | K12: 3 | L12: 0.4 | M12: 45 | N12: 4.1 | O12: 11 | P12: 0.9 | Q12: 5 | R12: 600 | S12: 650 g. Frystivara 180 dagar, kælivara 7 dagar þiðnuð.
A13: Hrökkbrauð – Spelt (Burger crispbread) | B13: Hrökkbrauð – Spelt (Burger crispbread) | C13: Burger Knäcke/ Nathan | E13: Brauð og bakkelsi | F13: Heilkorna**rúg**mjöl, speltflögur (**hveiti**), heilkorna**spelt**mjöl (**hveiti**), salt. | G13: Glúten (Hveiti, rúgur, spelt) | H13: Getur innihaldið snefil af sesam, mjólk og öðrum glútentegundum | I13: https://drive.google.com/file/d/1vwvU9xL9chLkyyy34xePImiUaHAxA66A/view?usp=sharing | J13: 324 | K13: 1.6 | L13: 0.3 | M13: 59 | N13: 1.8 | O13: 8.6 | P13: 1.3 | Q13: 21 | R13: 600 | S13: 250 g. Þurrgeymist 12 mánuðir.
A14: Heilhveitikex (HAUST Graham biscuit) | B14: Heilhveitikex (HAUST Graham biscuit) | C14: Continental Bakeries North Europe AB | D14: 307242 | E14: Brauð og bakkelsi | F14: **Hveiti**mjöl, heilkorna **hveiti**mjöl 30%, sykur, jurtafita (pálma), lyftiefni (ammoníumkarbónöt, natríumkarbónöt), salt, bragðefni. | G14: Glúten (hveiti) | H14: Getur innihaldið snefil af hnetum og sesam | I14: https://docs.google.com/document/d/1hSm-4pt3r15YYOeuqlWMbkkVgdKc8cwt0qPlCRs1ssM/edit?usp=sharingex.pdf | J14: 478 | K14: 20.8 | L14: 10.5 | M14: 62.4 | N14: 22.7 | O14: 8 | P14: 1.1 | R14: 800 | S14: 225 g. Þurrgeymist 12 mánuðir. Upprunaland: Þýskaland.
A15: Horn / Mini croissant 25g | B15: Horn / Mini croissant 25g | C15: Boulangerie Neuhauser SA | D15: 401262 | E15: Brauð og bakkelsi | F15: **Hveiti**mjöl, vatn, **smjör** 18%, ger, sykur, **egg**, salt, **hveiti**glúten, maltað **hveiti**mjöl, óvirkt ger, mjölmeðhöndlunarefni (askorbínsýra E300), ensím. | G15: Glúten (hveiti), mjólk, egg | I15: https://drive.google.com/file/d/1DNHhTRSDQjq03Ewnj0fn_Ex30mAnbK52/view?usp=sharing | J15: 308 | K15: 15 | L15: 9.2 | M15: 36 | N15: 5.4 | O15: 6.8 | P15: 1 | Q15: 1.4 | R15: 600 | S15: 25 g/stk. 40 stk/poki. Frystivara -18°C. Bakið 10–12 mín við 165°C.
A16: Arna skyr vanillu | B16: Arna skyr vanillu | C16: Arna | E16: Mjólkurvörur | F16: **Mjólk**, sykur (5.0%), maíssterkja, vanilluþykkni (0,1%), vanillukorn, sítrónusafi, skyrgerlar, laktasi. | G16: Mjólk (laktósalaus) | I16: https://drive.google.com/file/d/1yzNdxeJqQSbLVXSF15Oeij4m2PUBv2GA/view?usp=sharing | J16: 78 | K16: 0.3 | L16: 0.2 | M16: 7.9 | N16: 7.9 | O16: 11 | P16: 0.1 | R16: 933 | S16: 1 kg. Kælivara 0–4°C. Þar af viðbættur sykur 5,0 g.
A17: Heimilis grjónagrautur | B17: Heimilis grjónagrautur | C17: Matarstræti | D17: 400208 | E17: Grautar og morgunmatur | F17: **Mjólk**, hrísgrjón(12%), sykur, salt. | G17: Mjólk | I17: https://drive.google.com/file/d/1Q4ZfVecv6vttdWG8fU0WA-1aeEo59cEB/view?usp=sharing | J17: 91 | K17: 3 | L17: 1.6 | M17: 14 | N17: 4.6 | O17: 3 | P17: 0.5 | R17: 350 | S17: 2 kg. Kælivara. Geymsluþol 20 dagar.
A18: Oatly iKaffe haframjólk 1lt | B18: Oatly iKaffe haframjólk 1lt | R18: 407
A19: Oatly iMat Fraiche (sýrður hafrarjómi) | B19: Oatly iMat Fraiche (sýrður hafrarjómi) | C19: Oatly/ Innnes | D19: 61529 | E19: Plöntubasað | F19: Gerjaður hafragrunnur (vatn, **hafrar** 10%), repjuolía, fullhertar jurtaolíur (kókos, repju), kartöflusterkja, ýruefni (E472e), bindiefni (E407), sýrur (eplasýra, mjólkursýra), kalsíumkarbónat, kalsíumfosföt. | G19: Glúten (hafrar) | I19: https://docs.google.com/document/d/1vtp7UoMhU2kAQ80lddgVvUUhOoVTIYypmLZ4XRd5l3E/edit?usp=sharing | J19: 177 | K19: 15 | L19: 6.4 | M19: 9.1 | N19: 4.1 | O19: 1 | P19: 0 | Q19: 1 | R19: 1800 | S19: 200 ml. Kælivara. Geymsluþol 158 dagar.
A20: Debic Vegan Top (jurtarjómi) | B20: Debic Vegan Top (jurtarjómi) | C20: FrieslandCampina/Nathan | D20: 1180281 | E20: Plöntubasað | F20: Vatn (64%), jurtaolía (29%) (pálmakjarni, pálmi), þurrkað glúkósasíróp (5%), umbreytt sterkja, salt, bindiefni (E339, gellangúmmí), ýruefni (lesitín, E435, E472b), litarefni (karótín), náttúruleg bragðefni. | G20: Engir skráðir | I20: https://drive.google.com/file/d/1VkCiTqPDw5l0voO-OiMPXkFvU-St0eZv/view?usp=sharing | J20: 295 | K20: 30 | L20: 25 | M20: 6.2 | O20: 0 | P20: 0.1 | Q20: 0 | R20: 1800 | S20: EAN: 8713300128979. 5 L Bag-in-Box. Kælivara 2–7°C. Geymsluþol 183 dagar. Eftir opnun: nota innan 4 daga.
A21: Ali brauðskinka 62% | B21: Ali brauðskinka 62% | C21: Ali | E21: Kjöt / Alifuglar | F21: Grísakjöt (62%), vatn, kartöflumjöl, **sojaprótein**, salt, þrúgusykur, bindiefni (E451), þráavarnarefni (E301, E330), gerextrakt, þykkingarefni (E410, E407), bragðefni, rotvarnarefni (E270, E250) | G21: Soja | I21: https://docs.google.com/document/d/1tYCZIN-9wdHVdNDDkGYzBt6KHJktVy-txKVoBoCKeKQ/edit?usp=sharing | J21: 122 | K21: 5.9 | L21: 2.4 | M21: 3.6 | N21: 1.6 | O21: 13.4 | P21: 2.7 | R21: 1836 | S21: Kælivara 0–4°C. Vacumpakkar, geymsluþol 21 dagur.
A22: Ali kjúklingapylsur | B22: Ali kjúklingapylsur | C22: Ali | E22: Kjöt / Alifuglar | F22: Kjúklingakjöt 58%, kjúklingaskinn 24%, vatn, salt, krydd (**sinnep**, hvítlaukur), gerextrakt, bragðefni, rotvarnarefni (E250) | G22: Sinnep | I22: https://drive.google.com/file/d/1YjhRYrqRfXtv7LqVwi1Ut5s0ZlUPbbqk/view?usp=sharing | J22: 173 | K22: 13.4 | L22: 4.8 | M22: 0.3 | N22: 0.3 | O22: 13.7 | P22: 2.8 | R22: 1900 | S22: Kælivara 0–4°C. Geymsluþol 21 dagur.
A23: Kjúklingabollur 5 kg | B23: Kjúklingabollur 5 kg | C23: Matfugl ehf. | D23: 174170 | E23: Kjöt / Alifuglar | F23: Kjúklingaleggjakjöt, kartöflusterkja, vatn, **soja**prótein, salt, þurrkað grænmeti (laukur, hvítlaukur, paprika), bragðefni (**soja**), krydd (**sinnep**), þrúgusykur, **hveiti**prótein, gerextrakt, litarefni (E160c), krydd, ger, repjuolía, fosfat (E450) | G23: Glúten (hveiti), soja, sinnep | I23: https://drive.google.com/file/d/1YThV-MnjJNGCpLCeYQojXy09zGYF6MrY/view?usp=sharing | J23: 177 | K23: 9 | L23: 1.8 | M23: 7 | N23: 0.9 | O23: 17 | P23: 1.8 | R23: 1900 | S23: Frystivara -18°C, geymsluþol 10 mánuðir. Kælivara 0–4°C, 20 dagar.
A24: Kjúklingabollur án ofnæmisvalda | B24: Kjúklingabollur án ofnæmisvalda | C24: Matfugl ehf. | D24: 174171 | E24: Kjöt / Alifuglar | F24: Kjúklingakjöt (90%), vatn, kartöflusterkja, salt, baunamjöl, sykur, krydd, bindiefni (E450), kryddjurtir, karrý (turmerik, kóríander, fenugreek, dillfræ, negull, chili), broddkúmen, laukur, hvítlaukur, kóríander, bragðefni, cayennepipar, svartur pipar, engifer, kanill, kekkjavarnarefni (E551), litarefni paprika (E 160c), negull, sýra (E330), repjuolía. | R24: 1400
A25: Kjúklingaborgarar í cornflakes | B25: Kjúklingaborgarar í cornflakes | C25: Matfugl ehf. | D25: 174311 / 174312 / 174350 | E25: Kjöt / Alifuglar | F25: Kjötfylling (79%) (Kjúklingakjöt (83% af fyllingu), vatn, **soja**prótein, salt, krydd, gerþykkni, laukur), Brauðhjúpur (**hveiti**, maís, vatn, sykur, salt, maltað **bygg** extrakt), repjuolía. | G25: Glúten (hveiti, bygg), soja | I25: https://drive.google.com/file/d/1eikdCgUrXnNjx_B4w2fUH_3E5nIrr0Kz/view?usp=sharing | J25: 237 | K25: 13 | L25: 4.7 | M25: 14 | N25: 1.1 | O25: 16 | P25: 1.5 | R25: 1900 | S25: Frystivara -18°C, geymsluþol 10 mánuðir. Kælivara 0–4°C, 20 dagar.
A26: Kjúklinga lærakjöt Rodizio | B26: Kjúklinga lærakjöt Rodizio | C26: Matfugl ehf. | D26: 171481 / 171482 / 171483 / 171484 / 171498 / 171499 | E26: Kjöt / Alifuglar | F26: Úrbeinuð skinnlaus kjúklingalæri (83%), vatn, salt, jurtaolia (repju og palma olia), sykur, mango chutney, ávaxtaþykkni, sýrustillir (E500), krydd reykbragðefni, rotvarnarefni (E262), þráavarnarefni (E320) | I26: https://drive.google.com/file/d/111MXMHumSNCo1SX0OgN5_iw4ol6nI6Y0/view?usp=sharing | J26: 206 | K26: 10 | L26: 1.8 | M26: 4 | N26: 3.3 | O26: 25 | P26: 3.2 | R26: 2400 | S26: Kælivara 0–4°C, 21 dagur. Frystivara -18°C, 8 mánuðir.
A27: Kjúklingalærkjöt, hráir strimlar | B27: Kjúklingalærkjöt, hráir strimlar | C27: Innnes Flevo | D27: 309924 | E27: Kjöt / Alifuglar | F27: Úrbeinuð, skinnlaus kjúklingalæri | I27: https://innnes.is/media/r4em233a/309924_rawstripes_71467_309924.pdf | J27: 153 | K27: 8.5 | L27: 2.4 | M27: 1.4 | N27: 0.2 | O27: 17.5 | P27: 0.4 | Q27: 0.5 | R27: 1734
A28: Kjúklingalæri úrbeinuð | B28: Kjúklingalæri úrbeinuð | C28: Danpo | D28: 844014 | E28: Kjöt / Alifuglar | F28: Úrbeinuð og skinnlaus kjúklingalæri 80%, vatn 19%, salt, sykur, þráavarnarefni (E331, E301), sýrustillir (E262). | I28: https://drive.google.com/file/d/1GO4O3alIJnHNWfA6fdAD_SVmAdbBm5wZ/view?usp=sharing | J28: 137 | K28: 9 | L28: 2.3 | O28: 14 | P28: 0.8 | R28: 2400 | S28: 4 x 2500 g. Frystivara -18°C, geymsluþol 12 mánuðir. Halal viðurkennt. <0,5 g kolvetni og sykur.
A29: NOL Kindakæfa 200g | B29: NOL Kindakæfa 200g | C29: Kjarnafæði Norðlenska hf. | D29: 70519 | E29: Kjöt / Alifuglar | F29: Lambakjöt 80%, kjötsoð, laukduft, salt, pipar. | I29: https://docs.google.com/document/d/1LXzsuB69-IC_oRxF1lHfWTuKdnHk4OhCG33dUGHUGSs/edit?usp=sharing | J29: 264 | K29: 24 | L29: 12 | M29: 1 | N29: 0 | O29: 11 | P29: 2.1 | Q29: 0 | R29: 1800 | S29: Kælivara 0–4°C. Geymsluþol 14 dagar. Soðin vara. Upprunaland: Ísland.
A30: Lifrarpylsa án mjólkur, soðin | B30: Lifrarpylsa án mjólkur, soðin | C30: Kjarnafæði Norðlenska hf. | D30: 59804 | E30: Kjöt / Alifuglar | F30: Lambalifur 32%, lambamör, **rúgmjöl**, **haframjöl**, vatn, salt. | G30: Glúten (rúgur, hafrar) | I30: https://docs.google.com/document/d/1dqgFZjSbMdctBpuTsZ86-uVkLNdvEtPTC6Kh8455--Y/edit?usp=sharing | J30: 401 | K30: 32.7 | L30: 16.6 | M30: 15.7 | N30: 0.3 | O30: 10.3 | P30: 1 | Q30: 3.8 | R30: 1800 | S30: 1 kg. Kælivara 0–4°C. Geymsluþol 35 dagar. Upprunaland: Ísland.
A31: Ýsa í raspi - Hafið | B31: Ýsa í raspi - Hafið | C31: Hafið fiskverslun | D31: 1164 | E31: Fiskur | F31: **Ýsa**, raspur (**hveiti**, vatn, ger, salt, litarefni (E100, E160b)), hjúpur (**hveiti**glúten, salt, umbreytt **hveiti**sterkja). | G31: Glúten (hveiti), fiskur | I31: https://docs.google.com/document/d/1mrPTXRk_Pt2msU-ckh0eoh4oUCEKrI5g/edit?usp=sharing&ouid=115242652208709673085&rtpof=true&sd=true | J31: 125 | K31: 1 | L31: 0.3 | M31: 11 | N31: 0.2 | O31: 18 | P31: 0.7 | R31: 1800 | S31: Orka: 530 kJ/125 kcal. Umbúðir: plastbakki, plastfilma, pappahólkur.
A32: Fiskibollur án glúten | B32: Fiskibollur án glúten | C32: Norðanfiskur | D32: 9060 | E32: Fiskur | F32: **Þorskur**, laukur, kartöflumjöl, umbreytt maíssterkja, jurtatrefjar, **soja**prótein, laukduft, salt, bindiefni (E451), hvítur pipar repjuolía. | G32: Fiskur, soja | I32: https://drive.google.com/file/d/1su1X4NqQ06JKbPrLHqbYVzuDSI9b-_ZY/view?usp=sharing | J32: 125 | K32: 1.3 | L32: 0.1 | M32: 14.2 | N32: 0.7 | O32: 14.1 | P32: 1.4 | R32: 1800 | S32: 5 kg/kassa. Án glutens, mjólkurvara og eggja.
A33: Anamma Vegan Nuggets Pea | B33: Anamma Vegan Nuggets Pea | C33: Orkla Foods Sweden/Danól | D33: 454071477 | E33: Plöntubasað | F33: Vatn, baunaprótein(17%), repjuolía, glútenlaus raspur (hrísgrjónamjöl, kjúklingabaunamjöl, maíssterkja, salt, dextrósi), hrísgrjónamjöl, maíssterkja, laukur, salt, náttúruleg bragðefni (paprika, kóríander, múskat), bindiefni (metýlsellulósi) | G33: Engir skráðir | H33: Getur innihaldið snefil af soja | I33: https://docs.google.com/document/d/1hD7vfcvl0f75johYoY3PnnS548AlpCDkNKyTSEnJezk/edit?usp=sharing | J33: 256 | K33: 17 | L33: 1.2 | M33: 14 | N33: 0 | O33: 12 | P33: 1.2 | R33: 2500 | S33: 3 kg pakki (~100 stk, 22–23 g/stk). Frystivara -18°C. Vegan, án glútens, mjólkur og eggs.
A34: BBQ Oumph! (Pulled) | B34: BBQ Oumph! (Pulled) | C34: LiveKindly Collective AB | D34: 1407 | E34: Plöntubasað | F34: **Soja**prótein 54,3% (vatn, **soja**próteinþykkni), grillsósa 45,7% (vatn, krydd, sykur, salt, karamellaður sykur, tómatur, laukur, hvítlaukur, pipar, engifer, steinselja, svartur pipar, cayennepipar, sýrustillir sítrónusýra, repjuolía, náttúruleg bragðefni, maltódextrín, umbreytt maíssterkja, bragðefni), tómatpúrra, eplaþykkni, edik, reykbragðefni. | G34: Soja | I34: https://drive.google.com/file/d/1ny7Hc5Bb9td7Jjuz8iDeeFNvGw0ASEur/view?usp=sharing | J34: 115 | K34: 0.7 | L34: 0.1 | M34: 11 | N34: 9.4 | O34: 14 | P34: 1.5 | Q34: 4.7 | R34: 1800 | S34: EAN: 07316641014072. 2 kg. Frystivara -18°C, geymsluþol 547 dagar.
A35: Asískar grænmetisbollur | B35: Asískar grænmetisbollur | C35: Avita/Danco | D35: 8808 | E35: Plöntubasað | F35: Grænmeti (gulrætur, hvítkál, bambus, paprika, svartir sveppir, blaðlaukur, laukur, sykurbaunir) 40,5%, hrísgrjón 35%, repjuolía, kartöfluflögur, baunasterkja, döðlur 3%, sólblómaolía, krydd, salt, sykur, steinselja, kartöflusterkja, bindiefni (hýdroxýprópýl metýlsellulósi) | G35: Engir skráðir | I35: https://drive.google.com/file/d/1apWuKGpcNAqp6PlmDeLj6QCa3EUrWc9L/view?usp=sharing | J35: 182 | K35: 7.5 | L35: 0.8 | M35: 24.7 | N35: 5.3 | O35: 1.9 | P35: 1.4 | R35: 350 | S35: ~25 g/stk. 5 x 1.200 g í kassa. Frystivara -18°C, geymsluþol 18 mánuðir.
A36: Falafel bollur Funky Harissa & Grilled Pepper | B36: Falafel bollur Funky Harissa & Grilled Pepper | C36: Salomon FoodWorld | D36: 8530200 | E36: Plöntubasað | F36: Kjúklingabaunir (33%), kartöflur, **hveiti**mjöl, kjúklingabaunamjöl, vatn, paprika (5%), gulrætur, þurrkaðir tómatar (3%), laukur, piparþykkni, repjuolía, krydd, svart kúmen, hvítlaukur, maísmjöl, salt, chili, kryddþykkni, sýra (sítrónusýra), tómatþykkni, **hveiti**sterkja, kryddjurtir, lyftiefni (dífosföt, natríumkarbónöt) | G36: Glúten (hveiti) | I36: https://drive.google.com/file/d/1Y-R-GvIw5gcBuCYDUT2F0S5nKyBx43UH/view?usp=sharing | J36: 222 | K36: 7.4 | L36: 0.9 | M36: 28 | N36: 3.6 | O36: 7.6 | P36: 1.1 | Q36: 6.5 | R36: 1800 | S36: 1 kg (52–56 stk). 3 x 1 kg = 3 kg/kassa. Frystivara -18°C, geymsluþol 450 dagar. Vegan.
A37: Garden Gourmet Vegan Nuggets - EKKI í notkun | B37: Garden Gourmet Vegan Nuggets - EKKI í notkun | C37: Nestlé Professional/ Innnes | D37: 12608135 | E37: Plöntubasað | F37: Endurvatnað **hveiti**prótein 40,9% (vatn, **hveiti**prótein 9,7%, **hveiti**mjöl 2,8%), raspur 17% (**hveiti**mjöl, salt, ger, repjuolía, kryddþykkni paprika), vatn, jurtaolíur (repja, sólblómaolía), **hveiti**mjöl, baunaprótein, sýrustillir (buffrað edik), bindiefni (metýlsellulósi), **hveiti**glúten 1,7%, náttúruleg bragðefni, sterkja, sítrustrefjar, salt, bambustrefjar, laukduft, hvítur pipar, **soja**sósa (**sojabaunir**, **hveiti**, salt) | G37: Glúten (hveiti), soja | H37: Getur innihaldið snefil af eggjum. | I37: https://drive.google.com/file/d/1_5EjaAcN-dT9_KQ7b3yra7RVnqiPPeaS/view?usp=sharing | J37: 238 | K37: 13.4 | L37: 1.6 | M37: 13.3 | N37: 1.7 | O37: 13.6 | P37: 1.1 | Q37: 5.1 | R37: 1800 | S37: 2 kg pakki (~100 stk). Frystivara -18°C, geymsluþol 15 mánuðir. Vegan.
A38: Marrakesh pottréttur | B38: Marrakesh pottréttur | C38: Álfasaga ehf. / Móðir Náttúra | D38: 816 | E38: Plöntubasað | F38: Tómatar, kjúklingabaunir, laukur, gulrætur, sætar kartöflur, eplasafi (eplasafi, þráavarnarefni E330), blómkál, repjuolía, döðlur, limesafi (lime safi, þráavarnarefni E224, inniheldur **SÚLFÍÐ**), paprikumauk (rauð paprika, eggaldin, sólblómaolía, sykur, salt, sýrustillir E260, krydd, chili, náttúruleg bragðefni), hvítlaukur, salt, kóríander, chilimauk (rauður chili, salt, sykur, sýrustillir E260, E330, rotvarnarefni E211), grænmetiskraftur (salt, pálmaolía, maltodextrín, gulrætur, laukur, **sellerí**, blaðlaukur, graslaukur), sykur, krydd (túrmerik, hvítur pipar, kóríander, múskat, **sellerí**), rósmarínkraftur, kúmen, engifer, túrmerik, svartur pipar, kanill. | G38: Súlfít, sellerí. | H38: Framleitt á svæði þar sem unnið er með hnetur | I38: https://docs.google.com/document/d/1lFUBZ6JnrNhmfGUHlIWLvOeyf8UZVP0UP7Z3nm8HOlw/edit?usp=sharing | J38: 118 | K38: 4.5 | L38: 0.4 | M38: 13.5 | N38: 5.7 | O38: 3.8 | P38: 0.9 | Q38: 4 | R38: 1800 | S38: 2 x 2,5 kg í kassa. Frystivara -18°C. Geymsluþol 1 ár. Tilbúið til neyslu, þarf aðeins að hita.
A39: Vegan grjónagrautur | B39: Vegan grjónagrautur | C39: Í-MAT / Matarstund | D39: FH-20260127-01 | E39: Plöntubasað | F39: Vegan rjómi (vatn , jurtaolía pálmakjarni, pálmi, þurrkað glúkósasíróp, umbreytt sterkja, salt, bindiefni E339, gellangúmmí, ýruefni lesitín, E435, E472b, litarefni karótín, náttúruleg bragðefni), vatn, hrísgrjón, sykur, salt. | G39: Engir skráðir | I39: https://drive.google.com/file/d/12DfeqymW1tAoO22_uIYQhTJKAtpxDRqo/view?usp=sharing | J39: 74 | K39: 1.6 | L39: 0.3 | M39: 13 | N39: 1.2 | O39: 1.8 | P39: 0.4 | R39: 350 | S39: ~10 L (~40 skammtar á 250 g). Kælivara 0–4°C / Frystivara. Vegan, laktósalaust. Næringargildi eru áætluð viðmið.
A40: Brunoise grænmetisblanda | B40: Brunoise grænmetisblanda | C40: Ardo/Garri | D40: MMB610 | E40: Grænmeti | F40: Sellerírót (33%), gulrætur (32%), blaðlaukur (15%), **sellerí** (10%), laukur (10%) | G40: Sellerí | I40: https://drive.google.com/file/d/1GJCXmg1Vj2I1EBYaQMCFT7B1s7hEMNUD/view?usp=sharing | J40: 26 | K40: 0.4 | L40: 0.1 | M40: 3.4 | N40: 2.9 | O40: 1 | P40: 0.1 | Q40: 2.5 | R40: 400 | S40: Frystivara -18°C.
...

Sheet Réttabanki
A1: RÉTTABANKI – UPPSKRIFTIR
A2: Heiti réttar | B2: Vara (leitarnafn) | C2: Magn (g/100kg) | D2: Innihaldslýsing (sjálfvirkt) | E2: Ofnæmisvaldar (sjálfvirkt) | F2: Fyrirvari (sjálfvirkt) | G2: Orka (kcal/100g) | H2: Fita (g/100g) | I2: Mettuð fita (g/100g) | J2: Kolvetni (g/100g) | K2: Sykur (g/100g) | L2: Prótein (g/100g) | M2: Salt (g/100g) | N2: Trefjar (g/100g) | O2: Foodcost (kr/100kg) | P2: Athugasemd | Q2: Eldunarleiðbeiningar | R2: Eldunarleiðbeiningar (template) | S2: Réttur (fyllt niður) | T2: Línukostnaður (kr) | U2: Kostnaður (kr/kg réttar) | W2: (lykill)
A3: Pasta með kjötbollum í mildri tómatsósu | D3: Kinda- og nautgripakjöt 50% (uppruni Ísland), grænmeti 41% (kartöflur, brokkólí, laukur, gulrætur), kartöflusterkja, salt, krydd (pipar, oregano, basil, paprika) | Tómatar | Laukur | Gulrætur | Vatn | Súkrósi | Oregano 100% (Origanum vulgare L.). | Svartur pipar 100% (Piper nigrum), hitaþurrkað. | Hvítlaukur 95%, repjuolía 4%, mjólkursýra (E270) 1%. | Salt (salt, kekkjavarnarefni E535, lyftiefni E500). | Maíssterkja. | Repjuolía | Grænmetiskraftur (vatn, laukur, gulrótþykkni, tómatur, **sellerí**rót, jurtaextrakt), bragðefni, glúkósasíróp, gerþykkni, salt, litarefni (karamellusykur), repjuolía, maltódextrín, sykur. | E3: Súlfít, Sellerí | G3: 117.83 | H3: 7.2 | I3: 2.65 | J3: 16.4 | L3: 7.25 | M3: 2.62 | N3: 0.3 | P3: Í-Mat / Matarstund | Pastahlutfall 40%, sósa og kjötbollur 60% | Q3: 1. Hitið sósu í potti við meðalhita í 15-20 mín, hrærið reglulega. 2. Hitið kjötbollur í ofni 180°C í 10-12 mín. 3. Eldið pasta skv. leiðbeiningum á pakka. 4. Berið fram með pasta og kjötbollum í sósu. | R3: Hitið sósu í potti við meðalhita í 15-20 mín. Hitið kjötbollur í ofni 180°C í 10-12 mín. Eldið pasta skv. leiðbeiningum. Berið fram saman. | S3: Pasta með kjötbollum í mildri tómatsósu | U3: 977 kr/kg | W3: Pasta með kjötbollum í mildri tómatsósu
B4: Skólabollur, Kjöt og grænmeti | C4: 25000 | D4: Kinda- og nautgripakjöt 50% (uppruni Ísland), grænmeti 41% (kartöflur, brokkólí, laukur, gulrætur), kartöflusterkja, salt, krydd (pipar, oregano, basil, paprika) | G4: 110 | H4: 12 | I4: 6 | J4: 12 | K4: 0.6 | L4: 12 | M4: 1.6 | O4: 45 | S4: Pasta með kjötbollum í mildri tómatsósu | T4: 45000 | W4: Pasta með kjötbollum í mildri tómatsósu
B5: Tómatpuré Doppio Concentrato 800 g (Menu) | C5: 18000 | D5: Tómatar | E5: Engir skráðir | G5: 113 | H5: 0.4 | I5: 0 | J5: 19 | K5: 14 | L5: 6 | M5: 0.1 | O5: 8 | S5: Pasta með kjötbollum í mildri tómatsósu | T5: 8100 | W5: Pasta með kjötbollum í mildri tómatsósu
B6: Laukur (ferskur) | C6: 5000 | D6: Laukur | E6: Engir skráðir | G6: 40 | H6: 0.1 | I6: 0 | J6: 9.3 | K6: 4.2 | L6: 1.1 | M6: 0 | N6: 1.7 | O6: 1 | S6: Pasta með kjötbollum í mildri tómatsósu | T6: 1250 | W6: Pasta með kjötbollum í mildri tómatsósu
B7: Gulrætur (ferskar) | C7: 3000 | D7: Gulrætur | E7: Engir skráðir | G7: 41 | H7: 0.2 | I7: 0 | J7: 9.6 | K7: 4.7 | L7: 0.9 | M7: 0.1 | N7: 2.8 | O7: 1 | S7: Pasta með kjötbollum í mildri tómatsósu | T7: 750 | W7: Pasta með kjötbollum í mildri tómatsósu
B8: Vatn | C8: 4000 | D8: Vatn | E8: Engir skráðir | G8: 0 | H8: 0 | I8: 0 | J8: 0 | K8: 0 | L8: 0 | M8: 0 | N8: 0 | O8: 0 | S8: Pasta með kjötbollum í mildri tómatsósu | T8: 400 | W8: Pasta með kjötbollum í mildri tómatsósu
B9: Crystal Sugar (Sykur) | C9: 300 | D9: Súkrósi | E9: Engir skráðir | G9: 400 | H9: 0 | I9: 0 | J9: 100 | K9: 100 | L9: 0 | M9: 0 | N9: 0 | O9: 0 | S9: Pasta með kjötbollum í mildri tómatsósu | T9: 105 | W9: Pasta með kjötbollum í mildri tómatsósu
B10: Oregano | C10: 80 | D10: Oregano 100% (Origanum vulgare L.). | F10: Framleitt á svæði þar sem unnið er með glúten, fisk, krabbadýr, lindýr, mjólk, soja, sellerí, sinnep og sesam. | G10: 480 | H10: 10 | I10: 2.7 | J10: 64 | K10: 4.1 | L10: 11 | M10: 0 | O10: 1 | S10: Pasta með kjötbollum í mildri tómatsósu | T10: 788 | W10: Pasta með kjötbollum í mildri tómatsósu
B11: Svartur pipar, malaður | C11: 40 | D11: Svartur pipar 100% (Piper nigrum), hitaþurrkað. | F11: Framleitt á svæði þar sem unnið er með glúten, fisk, krabbadýr, lindýr, mjólk, soja, sellerí, sinnep og sesam. | G11: 386 | H11: 3.3 | I11: 1 | J11: 65 | K11: 0.6 | L11: 11 | M11: 0.1 | O11: 0 | S11: Pasta með kjötbollum í mildri tómatsósu | T11: 280 | W11: Pasta með kjötbollum í mildri tómatsósu
B12: Hvítlaukur í olíu (Crushed garlic, coarse cut with oil) | C12: 300 | D12: Hvítlaukur 95%, repjuolía 4%, mjólkursýra (E270) 1%. | E12: Súlfít | S12: Pasta með kjötbollum í mildri tómatsósu | T12: 270 | W12: Pasta með kjötbollum í mildri tómatsósu
B13: Borðsalt | C13: 800 | D13: Salt (salt, kekkjavarnarefni E535, lyftiefni E500). | E13: Engir skráðir | F13: Framleitt á svæði þar sem unnið er með mjólk, glúten, egg, sesam, sellerí, soja og sinnep. | G13: 0 | H13: 0 | I13: 0 | J13: 0 | K13: 0 | L13: 0 | M13: 100 | O13: 0 | S13: Pasta með kjötbollum í mildri tómatsósu | T13: 96 | W13: Pasta með kjötbollum í mildri tómatsósu
B14: Tómat kryddblanda | C14: 80 | S14: Pasta með kjötbollum í mildri tómatsósu | T14: 48 | W14: Pasta með kjötbollum í mildri tómatsósu
B15: Maizenamjöl (majssterkja) | C15: 1200 | D15: Maíssterkja. | E15: Engir skráðir | O15: 0 | S15: Pasta með kjötbollum í mildri tómatsósu | T15: 480 | W15: Pasta með kjötbollum í mildri tómatsósu
B16: Repjuolía | C16: 1200 | D16: Repjuolía | E16: Engir skráðir | S16: Pasta með kjötbollum í mildri tómatsósu | T16: 474 | W16: Pasta með kjötbollum í mildri tómatsósu
B17: Nautakraftur Vegan | C17: 1000 | D17: Grænmetiskraftur (vatn, laukur, gulrótþykkni, tómatur, **sellerí**rót, jurtaextrakt), bragðefni, glúkósasíróp, gerþykkni, salt, litarefni (karamellusykur), repjuolía, maltódextrín, sykur. | E17: Sellerí | S17: Pasta með kjötbollum í mildri tómatsósu | T17: 600 | W17: Pasta með kjötbollum í mildri tómatsósu
A18: Lambakjötspottréttur með kartöflum | D18: Lambakjöt 100% (Ísland) | Gulrætur | Fersk paprika | **Sellerí** | Laukur | Tómatar | Salt (salt, kekkjavarnarefni E535, lyftiefni E500). | Svartur pipar 100% (Piper nigrum), hitaþurrkað. | Repjuolía | Grænmetiskraftur (vatn, laukur, gulrótþykkni, tómatur, **sellerí**rót, jurtaextrakt), bragðefni, glúkósasíróp, gerþykkni, salt, litarefni (karamellusykur), repjuolía, maltódextrín, sykur. | Hvítlauksduft 100% | Þurrkað rósmarín (Rosmarinus officinalis) | Vatn | Maíssterkja. | E18: Engir, Sellerí | G18: 113.55 | H18: 6.55 | I18: 2.39 | J18: 7.33 | L18: 6.86 | M18: 1.08 | N18: 1.8 | P18: Matarstund | LP-100KG-20260529 | Q18: 1. Hitið pottrétt í ofni 160°C í 45-60 mín. 2. Potturinn er tilbúinn þegar kjötið er mjúkt. 3. Berið fram heitt. | R18: Hitið pottrétt í ofni 160°C í 45-60 mín. Tilbúinn þegar kjötið er mjúkt. Berið fram heitt. | S18: Lambakjötspottréttur með kartöflum | U18: 1.659 kr/kg | W18: Lambakjötspottréttur með kartöflum
B19: Lambakjöt teningar | C19: 35000 | D19: Lambakjöt 100% (Ísland) | E19: Engir skráðir | G19: 77 | H19: 0.1 | I19: 0 | J19: 17 | K19: 0.8 | L19: 2 | M19: 0 | N19: 2.2 | O19: 137 | S19: Lambakjötspottréttur með kartöflum | T19: 136500 | W19: Lambakjötspottréttur með kartöflum
B20: Gulrætur (ferskar) | C20: 18000 | D20: Gulrætur | E20: Engir skráðir | G20: 41 | H20: 0.2 | I20: 0 | J20: 9.6 | K20: 4.7 | L20: 0.9 | M20: 0.1 | N20: 2.8 | O20: 5 | S20: Lambakjötspottréttur með kartöflum | T20: 4500 | W20: Lambakjötspottréttur með kartöflum
B21: Paprika (fersk) | C21: 18000 | D21: Fersk paprika | E21: Engir | S21: Lambakjötspottréttur með kartöflum | T21: 14400 | W21: Lambakjötspottréttur með kartöflum
B22: Sellerí (ferskt) | C22: 2000 | D22: **Sellerí** | E22: Sellerí | S22: Lambakjötspottréttur með kartöflum | T22: 1000 | W22: Lambakjötspottréttur með kartöflum
B23: Laukur (ferskur) | C23: 12000 | D23: Laukur | E23: Engir skráðir | G23: 40 | H23: 0.1 | I23: 0 | J23: 9.3 | K23: 4.2 | L23: 1.1 | M23: 0 | N23: 1.7 | O23: 3 | S23: Lambakjötspottréttur með kartöflum | T23: 3000 | W23: Lambakjötspottréttur með kartöflum
B24: Tómatpuré Doppio Concentrato 800 g (Menu) | C24: 2500 | D24: Tómatar | E24: Engir skráðir | G24: 113 | H24: 0.4 | I24: 0 | J24: 19 | K24: 14 | L24: 6 | M24: 0.1 | O24: 1 | S24: Lambakjötspottréttur með kartöflum | T24: 1125 | W24: Lambakjötspottréttur með kartöflum
B25: Borðsalt | C25: 600 | D25: Salt (salt, kekkjavarnarefni E535, lyftiefni E500). | E25: Engir skráðir | F25: Framleitt á svæði þar sem unnið er með mjólk, glúten, egg, sesam, sellerí, soja og sinnep. | G25: 0 | H25: 0 | I25: 0 | J25: 0 | K25: 0 | L25: 0 | M25: 100 | O25: 0 | S25: Lambakjötspottréttur með kartöflum | T25: 72 | W25: Lambakjötspottréttur með kartöflum
B26: Svartur pipar, malaður | C26: 80 | D26: Svartur pipar 100% (Piper nigrum), hitaþurrkað. | F26: Framleitt á svæði þar sem unnið er með glúten, fisk, krabbadýr, lindýr, mjólk, soja, sellerí, sinnep og sesam. | G26: 386 | H26: 3.3 | I26: 1 | J26: 65 | K26: 0.6 | L26: 11 | M26: 0.1 | O26: 1 | S26: Lambakjötspottréttur með kartöflum | T26: 560 | W26: Lambakjötspottréttur með kartöflum
B27: Repjuolía | C27: 1500 | D27: Repjuolía | E27: Engir skráðir | S27: Lambakjötspottréttur með kartöflum | T27: 593 | W27: Lambakjötspottréttur með kartöflum
B28: Nautakraftur Vegan | C28: 1200 | D28: Grænmetiskraftur (vatn, laukur, gulrótþykkni, tómatur, **sellerí**rót, jurtaextrakt), bragðefni, glúkósasíróp, gerþykkni, salt, litarefni (karamellusykur), repjuolía, maltódextrín, sykur. | E28: Sellerí | S28: Lambakjötspottréttur með kartöflum | T28: 720 | W28: Lambakjötspottréttur með kartöflum
B29: Hvítlauksduft (Vitlökspulver) | C29: 400 | D29: Hvítlauksduft 100% | E29: Engir skráðir | F29: Framleitt á svæði þar sem unnið er með glúten, fisk, krabbadýr, lindýr, mjólk, soja, sellerí, sinnep og sesam. | S29: Lambakjötspottréttur með kartöflum | T29: 1725 | W29: Lambakjötspottréttur með kartöflum
B30: Timían | C30: 100 | S30: Lambakjötspottréttur með kartöflum | T30: 300 | W30: Lambakjötspottréttur með kartöflum
B31: Rósmarín (þurrkað) | C31: 50 | D31: Þurrkað rósmarín (Rosmarinus officinalis) | E31: Engir skráðir | F31: Framleitt á svæði þar sem unnið er með glúten, fisk, mjólk, soja, sellerí, sinnep og sesam. | S31: Lambakjötspottréttur með kartöflum | T31: 150 | W31: Lambakjötspottréttur með kartöflum
B32: Vatn | C32: 7350 | D32: Vatn | E32: Engir skráðir | G32: 0 | H32: 0 | I32: 0 | J32: 0 | K32: 0 | L32: 0 | M32: 0 | N32: 0 | O32: 1 | S32: Lambakjötspottréttur með kartöflum | T32: 735 | W32: Lambakjötspottréttur með kartöflum
B33: Maizenamjöl (majssterkja) | C33: 1200 | D33: Maíssterkja. | E33: Engir skráðir | O33: 0 | S33: Lambakjötspottréttur með kartöflum | T33: 480 | W33: Lambakjötspottréttur með kartöflum
A34: Mildur kjúklingakarrýréttur | D34: Úrbeinuð, skinnlaus kjúklingalæri | Fersk paprika | Laukur (90%), repjuolía (10%). | Gulrætur | Kókosmjólk, vatn, gúargúmmí. | Grænmetiskraftur (vatn, laukur, gulrótarsafi, tómatur, jurtaextrakt), glúkósasíróp, bragðefni, salt, gerextrakt, maltódextrín, sykur, sólblómaolía. | Hvítlauksduft 100% | Maíssterkja. | Salt, svartur pipar, hvítlaukur, paprikubitar, laukur, steinselja, dextrósi, timían, estragon. | Túrmerik, dillfræ, fenugreek (grikkjasmári), kóríander, cayennepipar, svartur pipar, negull. | Salt (salt, kekkjavarnarefni E535, lyftiefni E500). | Svartur pipar 100% (Piper nigrum), hitaþurrkað. | Vatn | E34: Engir | G34: 123.69 | H34: 7.79 | I34: 3.39 | J34: 5.39 | L34: 8.81 | M34: 1.55 | N34: 0.7 | P34: Matarstund | MK-100KG-20260529 | Q34: 1. Hitið karrýsósu í potti við meðalhita í 20-25 mín, hrærið reglulega. 2. Eldið hrísgrjón skv. leiðbeiningum. 3. Berið fram karrý yfir hrísgrjónum. | R34: Hitið karrýsósu í potti við meðalhita í 20-25 mín, hrærið reglulega. Eldið hrísgrjón skv. leiðbeiningum. Berið fram. | S34: Mildur kjúklingakarrýréttur | U34: 1.017 kr/kg | W34: Mildur kjúklingakarrýréttur
B35: Kjúklingalærkjöt - Rose | C35: 35000 | D35: Úrbeinuð, skinnlaus kjúklingalæri | G35: 137 | H35: 9 | I35: 2.3 | L35: 14 | M35: 0.8 | O35: 61 | S35: Mildur kjúklingakarrýréttur | T35: 60690 | W35: Mildur kjúklingakarrýréttur
B36: Paprika (fersk) | C36: 6000 | D36: Fersk paprika | E36: Engir | O36: 5 | R36: GUFA 98°C, lok á, kjarnhiti 75°C. Hrá: 3,3 kg hrísgrjón + 5 kg sjóðandi vatn, 55 mín. Endurhituð: 25 mín. | S36: Mildur kjúklingakarrýréttur | T36: 4800 | W36: Mildur kjúklingakarrýréttur
B37: Forsteiktur laukur (Pre-fried sliced onions) | C37: 8000 | D37: Laukur (90%), repjuolía (10%). | E37: Engir skráðir | G37: 114 | H37: 8.6 | I37: 1.1 | J37: 6.9 | K37: 3.9 | L37: 1.2 | M37: 0 | N37: 1.9 | O37: 3 | S37: Mildur kjúklingakarrýréttur | T37: 3200 | W37: Mildur kjúklingakarrýréttur
B38: Gulrætur (ferskar) | C38: 8000 | D38: Gulrætur | E38: Engir skráðir | G38: 41 | H38: 0.2 | I38: 0 | J38: 9.6 | K38: 4.7 | L38: 0.9 | M38: 0.1 | N38: 2.8 | O38: 2 | S38: Mildur kjúklingakarrýréttur | T38: 2000 | W38: Mildur kjúklingakarrýréttur
B39: Kókosmjólk Roland Coconut Milk | C39: 12000 | D39: Kókosmjólk, vatn, gúargúmmí. | E39: Engir skráðir | G39: 181 | H39: 18 | I39: 15.3 | J39: 2.8 | K39: 1 | L39: 2 | M39: 0 | N39: 0 | O39: 5 | S39: Mildur kjúklingakarrýréttur | T39: 5400 | W39: Mildur kjúklingakarrýréttur
B40: Kjúklingakraftur Vegan (Essential Cuisine) | C40: 1200 | D40: Grænmetiskraftur (vatn, laukur, gulrótarsafi, tómatur, jurtaextrakt), glúkósasíróp, bragðefni, salt, gerextrakt, maltódextrín, sykur, sólblómaolía. | S40: Mildur kjúklingakarrýréttur | T40: 720 | W40: Mildur kjúklingakarrýréttur
...

Sheet Grunnmatseðill
A1: GRUNNMATSEÐILL | T1: Eldunarleiðbeiningar | AB1: Gildir-listi (sjálfvirkt) ↓ | AC1: Bæði | AD1: Áætluð stækkun skammts – Grunnskóli vs Leikskóli | AF1: Kostnaðareftirlit (sjálfvirkt) ↓
A2: Dagsetning | B2: Dagur (sjálfvirkt) | C2: Vika (sjálfvirkt) | D2: Gildir fyrir | E2: Máltíðartegund | F2: Vara / Réttur (leitarnafn) | G2: Birtingarnafn (vefur) | H2: Skammtur Leikskóli (g) | I2: Skammtur Grunnskóli (g) | J2: Foodcost (blandað viðmið) | K2: Innihaldslýsing (sjálfvirkt) | L2: Ofnæmisvaldar (sjálfvirkt) | M2: Fyrirvari (sjálfvirkt) | N2: Orka (kcal) | O2: Fita (g) | P2: Mettuð fita (g) | Q2: Kolvetni (g) | R2: Prótein (g) | S2: Salt (g) | T2: Eldunarpöntun (1, 2, 3...) | U2: Upphafsástand | V2: Eldunaraðferð | W2: Ofnhiti (°C) | X2: Eldunartími (mín) | Y2: Kjarnhiti (°C) | Z2: Athugasemd | AA2: Hvíld eftir eldun (mín) | AB2: Leikskóli | AC2: Leikskóli | AD2: 0.5 | AF2: Foodcost Leikskóli (kr/skammt) | AG2: Foodcost Grunnskóli (kr/skammt) | AH2: Hlutfall af fjárheimild | AI2: Staða (30% hámark) | AJ2: Dagsetning (fyllt)
A3: 46258 | B3: Mánudagur | C3: 35 | D3: Grunnskólar starfsmenn | E3: Aðalréttur | G3: Nautapottréttur Provence, kartöflumús | J3: =IF($F3="","",IFERROR(IFERROR(INDEX(Réttabanki!$U:$U,MATCH($F3,Réttabanki!$A:$A,0)),INDEX(Vöruskrá!$R:$R,MATCH($F3,Vöruskrá!$B:$B,0)))*($H3+IF($I3="",$H3*(1+$AD$2),$I3))/2/1000,"")) | K3: VANTAR – innihaldslýsing af umbúðum | Tómatar 100%. | Gulrætur | Laukur | Blaðlaukur | **Sellerí** | Hvítlaukur | Tómatar | Grænmetiskraftur (vatn, laukur, gulrótþykkni, tómatur, **sellerí**rót, jurtaextrakt), bragðefni, glúkósasíróp, gerþykkni, salt, litarefni (karamellusykur), repjuolía, maltódextrín, sykur. | Þurrkað rósmarín (Rosmarinus officinalis) | Oregano 100% (Origanum vulgare L.). | Lárviðarlauf 100% (Laurus nobilis). | Svartur pipar 100% (Piper nigrum), hitaþurrkað. | Salt (salt, kekkjavarnarefni E535, lyftiefni E500). | Repjuolía | Vatn | Kartöflur (80%), **nýmjólk**, **smjörfita**, salt, ýruefni (mónó- og díglýseríð fitusýra), krydd | L3: VANTAR – staðfesta ofnæmisvalda, Sellerí, Mjólk | M3: =IF($F3="","",IFERROR(IFERROR(INDEX(Réttabanki!$F:$F,MATCH($F3,Réttabanki!$A:$A,0)),INDEX(Vöruskrá!$H:$H,MATCH($F3,Vöruskrá!$B:$B,0))),"")) | N3: =IF($F3="","",IFERROR(IFERROR(INDEX(Réttabanki!$G:$G,MATCH($F3,Réttabanki!$A:$A,0)),INDEX(Vöruskrá!$J:$J,MATCH($F3,Vöruskrá!$B:$B,0)))*($H3+IF($I3="",$H3*(1+$AD$2),$I3))/2/100,"")) | O3: =IF($F3="","",IFERROR(IFERROR(INDEX(Réttabanki!$H:$H,MATCH($F3,Réttabanki!$A:$A,0)),INDEX(Vöruskrá!$K:$K,MATCH($F3,Vöruskrá!$B:$B,0)))*($H3+IF($I3="",$H3*(1+$AD$2),$I3))/2/100,"")) | P3: =IF($F3="","",IFERROR(IFERROR(INDEX(Réttabanki!$I:$I,MATCH($F3,Réttabanki!$A:$A,0)),INDEX(Vöruskrá!$L:$L,MATCH($F3,Vöruskrá!$B:$B,0)))*($H3+IF($I3="",$H3*(1+$AD$2),$I3))/2/100,"")) | Q3: =IF($F3="","",IFERROR(IFERROR(INDEX(Réttabanki!$J:$J,MATCH($F3,Réttabanki!$A:$A,0)),INDEX(Vöruskrá!$M:$M,MATCH($F3,Vöruskrá!$B:$B,0)))*($H3+IF($I3="",$H3*(1+$AD$2),$I3))/2/100,"")) | R3: =IF($F3="","",IFERROR(IFERROR(INDEX(Réttabanki!$L:$L,MATCH($F3,Réttabanki!$A:$A,0)),INDEX(Vöruskrá!$O:$O,MATCH($F3,Vöruskrá!$B:$B,0)))*($H3+IF($I3="",$H3*(1+$AD$2),$I3))/2/100,"")) | S3: =IF($F3="","",IFERROR(IFERROR(INDEX(Réttabanki!$M:$M,MATCH($F3,Réttabanki!$A:$A,0)),INDEX(Vöruskrá!$P:$P,MATCH($F3,Vöruskrá!$B:$B,0)))*($H3+IF($I3="",$H3*(1+$AD$2),$I3))/2/100,"")) | T3: =IF(F3="","",IFERROR(INDEX(Réttabanki!Q:Q,MATCH(F3,Réttabanki!A:A,0)),IFERROR(INDEX(Réttabanki!Q:Q,MATCH(F3,Réttabanki!B:B,0)),""))) | AC3: Grunnskóli | AF3: =IF($F3="","",IFERROR(IFERROR(INDEX(Réttabanki!$U:$U,MATCH($F3,Réttabanki!$A:$A,0)),INDEX(Vöruskrá!$R:$R,MATCH($F3,Vöruskrá!$B:$B,0)))*$H3/1000,"")) | AG3: =IF($F3="","",IFERROR(IFERROR(INDEX(Réttabanki!$U:$U,MATCH($F3,Réttabanki!$A:$A,0)),INDEX(Vöruskrá!$R:$R,MATCH($F3,Vöruskrá!$B:$B,0)))*IF($I3="",$H3*(1+$AD$2),$I3)/1000,"")) | AH3: =IF(N($AF3)+N($AG3)=0,"",MAX(N($AF3)/$AE$6,N($AG3)/$AE$5)) | AI3: =IF($AH3="","",IF($AH3>$AE$7,"⚠ Yfir "&TEXT($AE$7,"0%"),"OK")) | AJ3: =IF($A3<>"",$A3,"") -> 46258
B4: Mánudagur | C4: 35 | D4: Grunnskólar starfsmenn | E4: Aðalréttur | F4: Nautapottréttur að hætti Provence | G4: Nautapottréttur | I4: 200 | J4: =IF($F4="","",IFERROR(IFERROR(INDEX(Réttabanki!$U:$U,MATCH($F4,Réttabanki!$A:$A,0)),INDEX(Vöruskrá!$R:$R,MATCH($F4,Vöruskrá!$B:$B,0)))*($H4+IF($I4="",$H4*(1+$AD$2),$I4))/2/1000,"")) | K4: VANTAR – innihaldslýsing af umbúðum | Tómatar 100%. | Gulrætur | Laukur | Blaðlaukur | **Sellerí** | Hvítlaukur | Tómatar | Grænmetiskraftur (vatn, laukur, gulrótþykkni, tómatur, **sellerí**rót, jurtaextrakt), bragðefni, glúkósasíróp, gerþykkni, salt, litarefni (karamellusykur), repjuolía, maltódextrín, sykur. | Þurrkað rósmarín (Rosmarinus officinalis) | Oregano 100% (Origanum vulgare L.). | Lárviðarlauf 100% (Laurus nobilis). | Svartur pipar 100% (Piper nigrum), hitaþurrkað. | Salt (salt, kekkjavarnarefni E535, lyftiefni E500). | Repjuolía | Vatn | L4: VANTAR – staðfesta ofnæmisvalda, Sellerí | N4: 38.6 | O4: 1.99 | P4: 0.14 | Q4: 5.53 | R4: 0.9 | S4: 1.29 | T4: 1 | U4: Kælt | V4: Ofn | W4: 140 | X4: 50-60 | Y4: 80 | Z4: Hræra 1-2 sinnum | AC4: Leikskólar starfsmenn | AD4: Fjárheimild – forsendur ↓ | AF4: =IF($F4="","",IFERROR(IFERROR(INDEX(Réttabanki!$U:$U,MATCH($F4,Réttabanki!$A:$A,0)),INDEX(Vöruskrá!$R:$R,MATCH($F4,Vöruskrá!$B:$B,0)))*$H4/1000,"")) | AG4: =IF($F4="","",IFERROR(IFERROR(INDEX(Réttabanki!$U:$U,MATCH($F4,Réttabanki!$A:$A,0)),INDEX(Vöruskrá!$R:$R,MATCH($F4,Vöruskrá!$B:$B,0)))*IF($I4="",$H4*(1+$AD$2),$I4)/1000,"")) | AH4: =IF(N($AF4)+N($AG4)=0,"",MAX(N($AF4)/$AE$6,N($AG4)/$AE$5)) | AI4: =IF($AH4="","",IF($AH4>$AE$7,"⚠ Yfir "&TEXT($AE$7,"0%"),"OK")) | AJ4: =IF($A4<>"",$A4,AJ3) -> 46258
B5: Mánudagur | C5: 35 | D5: Grunnskólar starfsmenn | E5: Aðalréttur | F5: Kartöflumús - Mydibel | G5: Kartöflumús | I5: 100 | J5: =IF($F5="","",IFERROR(IFERROR(INDEX(Réttabanki!$U:$U,MATCH($F5,Réttabanki!$A:$A,0)),INDEX(Vöruskrá!$R:$R,MATCH($F5,Vöruskrá!$B:$B,0)))*($H5+IF($I5="",$H5*(1+$AD$2),$I5))/2/1000,"")) -> 25 | K5: Kartöflur (80%), **nýmjólk**, **smjörfita**, salt, ýruefni (mónó- og díglýseríð fitusýra), krydd | L5: Mjólk | M5: Gæti innihaldið snefil af glúten og eggjum | N5: 103 | O5: 3 | P5: 2.1 | Q5: 16 | R5: 2.2 | S5: 0.7 | T5: 2 | U5: Kælt | V5: Ofn | W5: Steam - 98 | X5: 35-45 | Y5: 75 | Z5: Með loki | AC5: Grunnskólar starfsmenn | AD5: Dagsfjárheimild Grunnskóli (kr/dag) | AE5: 1150 | AF5: =IF($F5="","",IFERROR(IFERROR(INDEX(Réttabanki!$U:$U,MATCH($F5,Réttabanki!$A:$A,0)),INDEX(Vöruskrá!$R:$R,MATCH($F5,Vöruskrá!$B:$B,0)))*$H5/1000,"")) -> 0 | AG5: =IF($F5="","",IFERROR(IFERROR(INDEX(Réttabanki!$U:$U,MATCH($F5,Réttabanki!$A:$A,0)),INDEX(Vöruskrá!$R:$R,MATCH($F5,Vöruskrá!$B:$B,0)))*IF($I5="",$H5*(1+$AD$2),$I5)/1000,"")) -> 50 | AH5: =IF(N($AF5)+N($AG5)=0,"",MAX(N($AF5)/$AE$6,N($AG5)/$AE$5)) -> 0.043478261 | AI5: =IF($AH5="","",IF($AH5>$AE$7,"⚠ Yfir "&TEXT($AE$7,"0%"),"OK")) -> OK | AJ5: =IF($A5<>"",$A5,AJ4) -> 46258
B6: Mánudagur | C6: 35 | D6: Leikskóli | E6: Aðalréttur | G6: Nautapottréttur, kartöflumús | J6: =IF($F6="","",IFERROR(IFERROR(INDEX(Réttabanki!$U:$U,MATCH($F6,Réttabanki!$A:$A,0)),INDEX(Vöruskrá!$R:$R,MATCH($F6,Vöruskrá!$B:$B,0)))*($H6+IF($I6="",$H6*(1+$AD$2),$I6))/2/1000,"")) | K6: Nautakjöt 100% (rectangular cut, standard trim, cap on). | VANTAR – innihaldslýsing af umbúðum | Maukaðir tómatar 38%, kúrbítur 20%, eggaldin 20%, laukur 10%, rauð paprika 6%, græn paprika 6%. | Gulrætur (Dökkappelsínugular gulrætur 60%, gular gulrætur 40%.) | Laukur (90%), repjuolía (10%). | Tómatar | Grænmetiskraftur (vatn, laukur, gulrótþykkni, tómatur, **sellerí**rót, jurtaextrakt), bragðefni, glúkósasíróp, gerþykkni, salt, litarefni (karamellusykur), repjuolía, maltódextrín, sykur. | Vatn | Vatn, **sinnep**sfræ, edik, salt, rotvarnarefni (**súlfít**) | Maíssterkja. | Salt (salt, kekkjavarnarefni E535, lyftiefni E500). | Reykt paprika 100% (Capsicum annuum), reykþurrkuð. | Vatn, grænmeti (laukur, hvítlaukur, gulrætur, tómatar, kryddjurtir og krydd), bragðefni, gerþykkni, hoisin-sósa (sykur, rautt misó **soja**baunir, hrísgrjón, salt, vatn, ger, tamari-sojasósa vatn, **soja**baunir, salt, alkóhól, tómatpúrra, vatn, hrísgrjónaedik, stjörnuanís, lakkrís, hvítlauksmauk, chiliduft), salt, sykur, engifermauk, þurrkað glúkósasíróp, maltódextrín, möluð krydd (engifer, chili, kóríander, túrmerik, svartur pipar), repjuolía. | Svartur pipar 100% (Piper nigrum), hitaþurrkað. | Hvítlauksduft 100% | Þurrkað rósmarín (Rosmarinus officinalis) | Kartöflur (80%), **nýmjólk**, **smjörfita**, salt, ýruefni (mónó- og díglýseríð fitusýra), krydd | Kartöflur | L6: VANTAR – staðfesta ofnæmisvalda, Sellerí, Sinnep, súlfít, Soja, Mjólk | M6: =IF($F6="","",IFERROR(IFERROR(INDEX(Réttabanki!$F:$F,MATCH($F6,Réttabanki!$A:$A,0)),INDEX(Vöruskrá!$H:$H,MATCH($F6,Vöruskrá!$B:$B,0))),"")) | N6: =IF($F6="","",IFERROR(IFERROR(INDEX(Réttabanki!$G:$G,MATCH($F6,Réttabanki!$A:$A,0)),INDEX(Vöruskrá!$J:$J,MATCH($F6,Vöruskrá!$B:$B,0)))*($H6+IF($I6="",$H6*(1+$AD$2),$I6))/2/100,"")) | O6: =IF($F6="","",IFERROR(IFERROR(INDEX(Réttabanki!$H:$H,MATCH($F6,Réttabanki!$A:$A,0)),INDEX(Vöruskrá!$K:$K,MATCH($F6,Vöruskrá!$B:$B,0)))*($H6+IF($I6="",$H6*(1+$AD$2),$I6))/2/100,"")) | P6: =IF($F6="","",IFERROR(IFERROR(INDEX(Réttabanki!$I:$I,MATCH($F6,Réttabanki!$A:$A,0)),INDEX(Vöruskrá!$L:$L,MATCH($F6,Vöruskrá!$B:$B,0)))*($H6+IF($I6="",$H6*(1+$AD$2),$I6))/2/100,"")) | Q6: =IF($F6="","",IFERROR(IFERROR(INDEX(Réttabanki!$J:$J,MATCH($F6,Réttabanki!$A:$A,0)),INDEX(Vöruskrá!$M:$M,MATCH($F6,Vöruskrá!$B:$B,0)))*($H6+IF($I6="",$H6*(1+$AD$2),$I6))/2/100,"")) | R6: =IF($F6="","",IFERROR(IFERROR(INDEX(Réttabanki!$L:$L,MATCH($F6,Réttabanki!$A:$A,0)),INDEX(Vöruskrá!$O:$O,MATCH($F6,Vöruskrá!$B:$B,0)))*($H6+IF($I6="",$H6*(1+$AD$2),$I6))/2/100,"")) | S6: =IF($F6="","",IFERROR(IFERROR(INDEX(Réttabanki!$M:$M,MATCH($F6,Réttabanki!$A:$A,0)),INDEX(Vöruskrá!$P:$P,MATCH($F6,Vöruskrá!$B:$B,0)))*($H6+IF($I6="",$H6*(1+$AD$2),$I6))/2/100,"")) | T6: =IF(F6="","",IFERROR(INDEX(Réttabanki!Q:Q,MATCH(F6,Réttabanki!A:A,0)),IFERROR(INDEX(Réttabanki!Q:Q,MATCH(F6,Réttabanki!B:B,0)),""))) | AC6: Engidalsskóli | AD6: Dagsfjárheimild Leikskóli (kr/dag) | AE6: 1350 | AF6: =IF($F6="","",IFERROR(IFERROR(INDEX(Réttabanki!$U:$U,MATCH($F6,Réttabanki!$A:$A,0)),INDEX(Vöruskrá!$R:$R,MATCH($F6,Vöruskrá!$B:$B,0)))*$H6/1000,"")) | AG6: =IF($F6="","",IFERROR(IFERROR(INDEX(Réttabanki!$U:$U,MATCH($F6,Réttabanki!$A:$A,0)),INDEX(Vöruskrá!$R:$R,MATCH($F6,Vöruskrá!$B:$B,0)))*IF($I6="",$H6*(1+$AD$2),$I6)/1000,"")) | AH6: =IF(N($AF6)+N($AG6)=0,"",MAX(N($AF6)/$AE$6,N($AG6)/$AE$5)) | AI6: =IF($AH6="","",IF($AH6>$AE$7,"⚠ Yfir "&TEXT($AE$7,"0%"),"OK")) | AJ6: =IF($A6<>"",$A6,AJ5) -> 46258
B7: Mánudagur | C7: 35 | D7: Leikskóli | E7: Aðalréttur | F7: Nautapottréttur | G7: Nautapottréttur | H7: 180 | J7: =IF($F7="","",IFERROR(IFERROR(INDEX(Réttabanki!$U:$U,MATCH($F7,Réttabanki!$A:$A,0)),INDEX(Vöruskrá!$R:$R,MATCH($F7,Vöruskrá!$B:$B,0)))*($H7+IF($I7="",$H7*(1+$AD$2),$I7))/2/1000,"")) | K7: Nautakjöt 100% (rectangular cut, standard trim, cap on). | VANTAR – innihaldslýsing af umbúðum | Maukaðir tómatar 38%, kúrbítur 20%, eggaldin 20%, laukur 10%, rauð paprika 6%, græn paprika 6%. | Gulrætur (Dökkappelsínugular gulrætur 60%, gular gulrætur 40%.) | Laukur (90%), repjuolía (10%). | Tómatar | Grænmetiskraftur (vatn, laukur, gulrótþykkni, tómatur, **sellerí**rót, jurtaextrakt), bragðefni, glúkósasíróp, gerþykkni, salt, litarefni (karamellusykur), repjuolía, maltódextrín, sykur. | Vatn | Vatn, **sinnep**sfræ, edik, salt, rotvarnarefni (**súlfít**) | Maíssterkja. | Salt (salt, kekkjavarnarefni E535, lyftiefni E500). | Reykt paprika 100% (Capsicum annuum), reykþurrkuð. | Vatn, grænmeti (laukur, hvítlaukur, gulrætur, tómatar, kryddjurtir og krydd), bragðefni, gerþykkni, hoisin-sósa (sykur, rautt misó **soja**baunir, hrísgrjón, salt, vatn, ger, tamari-sojasósa vatn, **soja**baunir, salt, alkóhól, tómatpúrra, vatn, hrísgrjónaedik, stjörnuanís, lakkrís, hvítlauksmauk, chiliduft), salt, sykur, engifermauk, þurrkað glúkósasíróp, maltódextrín, möluð krydd (engifer, chili, kóríander, túrmerik, svartur pipar), repjuolía. | Svartur pipar 100% (Piper nigrum), hitaþurrkað. | Hvítlauksduft 100% | Þurrkað rósmarín (Rosmarinus officinalis) | L7: VANTAR – staðfesta ofnæmisvalda, Sellerí, Sinnep, súlfít, Soja | N7: 56.9 | O7: 2.3 | P7: 0.7 | Q7: 5.4 | R7: 3.3 | S7: 1.7 | T7: 1 | U7: Kælt | V7: Ofn | W7: 140 | X7: 50-60 | Y7: 80 | Z7: Hræra 1-2 sinnum | AC7: Hraunvallaskóli | AD7: Hámarkshlutfall matarkostnaðar | AE7: 0.3 | AF7: =IF($F7="","",IFERROR(IFERROR(INDEX(Réttabanki!$U:$U,MATCH($F7,Réttabanki!$A:$A,0)),INDEX(Vöruskrá!$R:$R,MATCH($F7,Vöruskrá!$B:$B,0)))*$H7/1000,"")) | AG7: =IF($F7="","",IFERROR(IFERROR(INDEX(Réttabanki!$U:$U,MATCH($F7,Réttabanki!$A:$A,0)),INDEX(Vöruskrá!$R:$R,MATCH($F7,Vöruskrá!$B:$B,0)))*IF($I7="",$H7*(1+$AD$2),$I7)/1000,"")) | AH7: =IF(N($AF7)+N($AG7)=0,"",MAX(N($AF7)/$AE$6,N($AG7)/$AE$5)) | AI7: =IF($AH7="","",IF($AH7>$AE$7,"⚠ Yfir "&TEXT($AE$7,"0%"),"OK")) | AJ7: =IF($A7<>"",$A7,AJ6) -> 46258
B8: Mánudagur | C8: 35 | D8: Leikskóli | E8: Aðalréttur | F8: Kartöflumús - Mydibel | G8: Kartöflumús | H8: 80 | J8: =IF($F8="","",IFERROR(IFERROR(INDEX(Réttabanki!$U:$U,MATCH($F8,Réttabanki!$A:$A,0)),INDEX(Vöruskrá!$R:$R,MATCH($F8,Vöruskrá!$B:$B,0)))*($H8+IF($I8="",$H8*(1+$AD$2),$I8))/2/1000,"")) -> 50 | K8: Kartöflur (80%), **nýmjólk**, **smjörfita**, salt, ýruefni (mónó- og díglýseríð fitusýra), krydd | L8: Mjólk | M8: Gæti innihaldið snefil af glúten og eggjum | N8: 103 | O8: 3 | P8: 2.1 | Q8: 16 | R8: 2.2 | S8: 0.7 | T8: 2 | U8: Kælt | V8: Ofn | W8: Steam - 98 | X8: 35-45 | Y8: 75 | Z8: Með loki | AC8: Hvaleyrarskóli | AD8: Hámark Grunnskóli (kr/dag) | AE8: =$AE$5*$AE$7 -> 345 | AF8: =IF($F8="","",IFERROR(IFERROR(INDEX(Réttabanki!$U:$U,MATCH($F8,Réttabanki!$A:$A,0)),INDEX(Vöruskrá!$R:$R,MATCH($F8,Vöruskrá!$B:$B,0)))*$H8/1000,"")) -> 40 | AG8: =IF($F8="","",IFERROR(IFERROR(INDEX(Réttabanki!$U:$U,MATCH($F8,Réttabanki!$A:$A,0)),INDEX(Vöruskrá!$R:$R,MATCH($F8,Vöruskrá!$B:$B,0)))*IF($I8="",$H8*(1+$AD$2),$I8)/1000,"")) -> 60 | AH8: =IF(N($AF8)+N($AG8)=0,"",MAX(N($AF8)/$AE$6,N($AG8)/$AE$5)) -> 0.052173913 | AI8: =IF($AH8="","",IF($AH8>$AE$7,"⚠ Yfir "&TEXT($AE$7,"0%"),"OK")) -> OK | AJ8: =IF($A8<>"",$A8,AJ7) -> 46258
B9: Mánudagur | C9: 35 | D9: Leikskóli | E9: Sérfæði | F9: Forsoðnar kartöflur | G9: Kartöflumús (Mjólkurlaus) | H9: 80 | J9: =IF($F9="","",IFERROR(IFERROR(INDEX(Réttabanki!$U:$U,MATCH($F9,Réttabanki!$A:$A,0)),INDEX(Vöruskrá!$R:$R,MATCH($F9,Vöruskrá!$B:$B,0)))*($H9+IF($I9="",$H9*(1+$AD$2),$I9))/2/1000,"")) -> 43 | K9: Kartöflur | L9: Engir skráðir | N9: 77 | O9: 0.1 | P9: 0 | Q9: 20 | R9: 1.7 | S9: 0 | AC9: Lækjarskóli | AD9: Hámark Leikskóli (kr/dag) | AE9: =$AE$6*$AE$7 -> 405 | AF9: =IF($F9="","",IFERROR(IFERROR(INDEX(Réttabanki!$U:$U,MATCH($F9,Réttabanki!$A:$A,0)),INDEX(Vöruskrá!$R:$R,MATCH($F9,Vöruskrá!$B:$B,0)))*$H9/1000,"")) -> 34.4 | AG9: =IF($F9="","",IFERROR(IFERROR(INDEX(Réttabanki!$U:$U,MATCH($F9,Réttabanki!$A:$A,0)),INDEX(Vöruskrá!$R:$R,MATCH($F9,Vöruskrá!$B:$B,0)))*IF($I9="",$H9*(1+$AD$2),$I9)/1000,"")) -> 51.6 | AH9: =IF(N($AF9)+N($AG9)=0,"",MAX(N($AF9)/$AE$6,N($AG9)/$AE$5)) -> 0.044869565 | AI9: =IF($AH9="","",IF($AH9>$AE$7,"⚠ Yfir "&TEXT($AE$7,"0%"),"OK")) -> OK | AJ9: =IF($A9<>"",$A9,AJ8) -> 46258
